Internal Server Error: /register/8d65680f4e01bfac7aed05218c38adc3cc13fd06/
Traceback (most recent call last):
  File "/Library/Frameworks/Python.framework/Versions/2.7/lib/python2.7/site-packages/django/core/handlers/base.py", line 111, in get_response
    response = callback(request, *callback_args, **callback_kwargs)
  File "/Library/Frameworks/Python.framework/Versions/2.7/lib/python2.7/site-packages/django/views/decorators/csrf.py", line 77, in wrapped_view
    return view_func(*args, **kwargs)
  File "/Users/joshblum/Desktop/Dropbox/code/comm.prod/commProd/views.py", line 43, in register
    user = profile[0].user
TypeError: 'function' object has no attribute '__getitem__'
Internal Server Error: /register/8d65680f4e01bfac7aed05218c38adc3cc13fd06/
Traceback (most recent call last):
  File "/Library/Frameworks/Python.framework/Versions/2.7/lib/python2.7/site-packages/django/core/handlers/base.py", line 111, in get_response
    response = callback(request, *callback_args, **callback_kwargs)
  File "/Library/Frameworks/Python.framework/Versions/2.7/lib/python2.7/site-packages/django/views/decorators/csrf.py", line 77, in wrapped_view
    return view_func(*args, **kwargs)
  File "/Users/joshblum/Desktop/Dropbox/code/comm.prod/commProd/views.py", line 43, in register
    user = profile[0].user
TypeError: 'function' object has no attribute '__getitem__'
Internal Server Error: /register/8d65680f4e01bfac7aed05218c38adc3cc13fd06/
Traceback (most recent call last):
  File "/Library/Frameworks/Python.framework/Versions/2.7/lib/python2.7/site-packages/django/core/handlers/base.py", line 111, in get_response
    response = callback(request, *callback_args, **callback_kwargs)
  File "/Library/Frameworks/Python.framework/Versions/2.7/lib/python2.7/site-packages/django/views/decorators/csrf.py", line 77, in wrapped_view
    return view_func(*args, **kwargs)
  File "/Users/joshblum/Desktop/Dropbox/code/comm.prod/commProd/views.py", line 43, in register
    user = profile[0].user
  File "/Library/Frameworks/Python.framework/Versions/2.7/lib/python2.7/site-packages/django/db/models/query.py", line 207, in __getitem__
    return list(qs)[0]
  File "/Library/Frameworks/Python.framework/Versions/2.7/lib/python2.7/site-packages/django/db/models/query.py", line 87, in __len__
    self._result_cache.extend(self._iter)
  File "/Library/Frameworks/Python.framework/Versions/2.7/lib/python2.7/site-packages/django/db/models/query.py", line 291, in iterator
    for row in compiler.results_iter():
  File "/Library/Frameworks/Python.framework/Versions/2.7/lib/python2.7/site-packages/django/db/models/sql/compiler.py", line 763, in results_iter
    for rows in self.execute_sql(MULTI):
  File "/Library/Frameworks/Python.framework/Versions/2.7/lib/python2.7/site-packages/django/db/models/sql/compiler.py", line 818, in execute_sql
    cursor.execute(sql, params)
  File "/Library/Frameworks/Python.framework/Versions/2.7/lib/python2.7/site-packages/django/db/backends/util.py", line 40, in execute
    return self.cursor.execute(sql, params)
  File "/Library/Frameworks/Python.framework/Versions/2.7/lib/python2.7/site-packages/django/db/backends/mysql/base.py", line 114, in execute
    return self.cursor.execute(query, args)
  File "/Users/joshblum/Library/Python/2.7/lib/python/site-packages/MySQLdb/cursors.py", line 174, in execute
    self.errorhandler(self, exc, value)
  File "/Users/joshblum/Library/Python/2.7/lib/python/site-packages/MySQLdb/connections.py", line 36, in defaulterrorhandler
    raise errorclass, errorvalue
DatabaseError: (1054, "Unknown column 'commProd_userprofile.pic_url' in 'field list'")
Internal Server Error: /register/8d65680f4e01bfac7aed05218c38adc3cc13fd06/
Traceback (most recent call last):
  File "/Library/Frameworks/Python.framework/Versions/2.7/lib/python2.7/site-packages/django/core/handlers/base.py", line 111, in get_response
    response = callback(request, *callback_args, **callback_kwargs)
  File "/Library/Frameworks/Python.framework/Versions/2.7/lib/python2.7/site-packages/django/views/decorators/csrf.py", line 77, in wrapped_view
    return view_func(*args, **kwargs)
  File "/Users/joshblum/Desktop/Dropbox/code/comm.prod/commProd/views.py", line 43, in register
    user = profile[0].user
  File "/Library/Frameworks/Python.framework/Versions/2.7/lib/python2.7/site-packages/django/db/models/query.py", line 207, in __getitem__
    return list(qs)[0]
  File "/Library/Frameworks/Python.framework/Versions/2.7/lib/python2.7/site-packages/django/db/models/query.py", line 87, in __len__
    self._result_cache.extend(self._iter)
  File "/Library/Frameworks/Python.framework/Versions/2.7/lib/python2.7/site-packages/django/db/models/query.py", line 291, in iterator
    for row in compiler.results_iter():
  File "/Library/Frameworks/Python.framework/Versions/2.7/lib/python2.7/site-packages/django/db/models/sql/compiler.py", line 763, in results_iter
    for rows in self.execute_sql(MULTI):
  File "/Library/Frameworks/Python.framework/Versions/2.7/lib/python2.7/site-packages/django/db/models/sql/compiler.py", line 818, in execute_sql
    cursor.execute(sql, params)
  File "/Library/Frameworks/Python.framework/Versions/2.7/lib/python2.7/site-packages/django/db/backends/util.py", line 40, in execute
    return self.cursor.execute(sql, params)
  File "/Library/Frameworks/Python.framework/Versions/2.7/lib/python2.7/site-packages/django/db/backends/mysql/base.py", line 114, in execute
    return self.cursor.execute(query, args)
  File "/Users/joshblum/Library/Python/2.7/lib/python/site-packages/MySQLdb/cursors.py", line 174, in execute
    self.errorhandler(self, exc, value)
  File "/Users/joshblum/Library/Python/2.7/lib/python/site-packages/MySQLdb/connections.py", line 36, in defaulterrorhandler
    raise errorclass, errorvalue
DatabaseError: (1054, "Unknown column 'commProd_userprofile.pic_url' in 'field list'")
Internal Server Error: /register/8d65680f4e01bfac7aed05218c38adc3cc13fd06/
Traceback (most recent call last):
  File "/Library/Frameworks/Python.framework/Versions/2.7/lib/python2.7/site-packages/django/core/handlers/base.py", line 111, in get_response
    response = callback(request, *callback_args, **callback_kwargs)
  File "/Library/Frameworks/Python.framework/Versions/2.7/lib/python2.7/site-packages/django/views/decorators/csrf.py", line 77, in wrapped_view
    return view_func(*args, **kwargs)
  File "/Users/joshblum/Desktop/Dropbox/code/comm.prod/commProd/views.py", line 43, in register
    user = profile[0].user
  File "/Library/Frameworks/Python.framework/Versions/2.7/lib/python2.7/site-packages/django/db/models/query.py", line 207, in __getitem__
    return list(qs)[0]
  File "/Library/Frameworks/Python.framework/Versions/2.7/lib/python2.7/site-packages/django/db/models/query.py", line 87, in __len__
    self._result_cache.extend(self._iter)
  File "/Library/Frameworks/Python.framework/Versions/2.7/lib/python2.7/site-packages/django/db/models/query.py", line 291, in iterator
    for row in compiler.results_iter():
  File "/Library/Frameworks/Python.framework/Versions/2.7/lib/python2.7/site-packages/django/db/models/sql/compiler.py", line 763, in results_iter
    for rows in self.execute_sql(MULTI):
  File "/Library/Frameworks/Python.framework/Versions/2.7/lib/python2.7/site-packages/django/db/models/sql/compiler.py", line 818, in execute_sql
    cursor.execute(sql, params)
  File "/Library/Frameworks/Python.framework/Versions/2.7/lib/python2.7/site-packages/django/db/backends/util.py", line 40, in execute
    return self.cursor.execute(sql, params)
  File "/Library/Frameworks/Python.framework/Versions/2.7/lib/python2.7/site-packages/django/db/backends/mysql/base.py", line 114, in execute
    return self.cursor.execute(query, args)
  File "/Users/joshblum/Library/Python/2.7/lib/python/site-packages/MySQLdb/cursors.py", line 174, in execute
    self.errorhandler(self, exc, value)
  File "/Users/joshblum/Library/Python/2.7/lib/python/site-packages/MySQLdb/connections.py", line 36, in defaulterrorhandler
    raise errorclass, errorvalue
DatabaseError: (1054, "Unknown column 'commProd_userprofile.pic_url' in 'field list'")
