Internal Server Error: /admin
Traceback (most recent call last):
  File "/usr/local/lib/python2.7/dist-packages/django/core/handlers/base.py", line 111, in get_response
    response = callback(request, *callback_args, **callback_kwargs)
  File "/usr/local/lib/python2.7/dist-packages/django/contrib/admin/sites.py", line 213, in wrapper
    return self.admin_view(view, cacheable)(*args, **kwargs)
  File "/usr/local/lib/python2.7/dist-packages/django/utils/decorators.py", line 91, in _wrapped_view
    response = view_func(request, *args, **kwargs)
  File "/usr/local/lib/python2.7/dist-packages/django/views/decorators/cache.py", line 89, in _wrapped_view_func
    response = view_func(request, *args, **kwargs)
  File "/usr/local/lib/python2.7/dist-packages/django/contrib/admin/sites.py", line 196, in inner
    return view(request, *args, **kwargs)
  File "/usr/local/lib/python2.7/dist-packages/django/views/decorators/cache.py", line 89, in _wrapped_view_func
    response = view_func(request, *args, **kwargs)
  File "/usr/local/lib/python2.7/dist-packages/django/contrib/admin/sites.py", line 353, in index
    model_dict['admin_url'] = reverse('admin:%s_%s_changelist' % info, current_app=self.name)
  File "/usr/local/lib/python2.7/dist-packages/django/core/urlresolvers.py", line 447, in reverse
    app_list = resolver.app_dict[ns]
  File "/usr/local/lib/python2.7/dist-packages/django/core/urlresolvers.py", line 290, in app_dict
    self._populate()
  File "/usr/local/lib/python2.7/dist-packages/django/core/urlresolvers.py", line 253, in _populate
    for name in pattern.reverse_dict:
  File "/usr/local/lib/python2.7/dist-packages/django/core/urlresolvers.py", line 276, in reverse_dict
    self._populate()
  File "/usr/local/lib/python2.7/dist-packages/django/core/urlresolvers.py", line 265, in _populate
    lookups.appendlist(pattern.callback, (bits, p_pattern, pattern.default_args))
  File "/usr/local/lib/python2.7/dist-packages/django/core/urlresolvers.py", line 216, in callback
    self._callback = get_callable(self._callback_str)
  File "/usr/local/lib/python2.7/dist-packages/django/utils/functional.py", line 27, in wrapper
    result = func(*args)
  File "/usr/local/lib/python2.7/dist-packages/django/core/urlresolvers.py", line 101, in get_callable
    (lookup_view, mod_name))
ViewDoesNotExist: Could not import commProd.views.register. View does not exist in module commProd.views.
Internal Server Error: /admin
Traceback (most recent call last):
  File "/usr/local/lib/python2.7/dist-packages/django/core/handlers/base.py", line 111, in get_response
    response = callback(request, *callback_args, **callback_kwargs)
  File "/usr/local/lib/python2.7/dist-packages/django/contrib/admin/sites.py", line 213, in wrapper
    return self.admin_view(view, cacheable)(*args, **kwargs)
  File "/usr/local/lib/python2.7/dist-packages/django/utils/decorators.py", line 91, in _wrapped_view
    response = view_func(request, *args, **kwargs)
  File "/usr/local/lib/python2.7/dist-packages/django/views/decorators/cache.py", line 89, in _wrapped_view_func
    response = view_func(request, *args, **kwargs)
  File "/usr/local/lib/python2.7/dist-packages/django/contrib/admin/sites.py", line 196, in inner
    return view(request, *args, **kwargs)
  File "/usr/local/lib/python2.7/dist-packages/django/views/decorators/cache.py", line 89, in _wrapped_view_func
    response = view_func(request, *args, **kwargs)
  File "/usr/local/lib/python2.7/dist-packages/django/contrib/admin/sites.py", line 353, in index
    model_dict['admin_url'] = reverse('admin:%s_%s_changelist' % info, current_app=self.name)
  File "/usr/local/lib/python2.7/dist-packages/django/core/urlresolvers.py", line 447, in reverse
    app_list = resolver.app_dict[ns]
  File "/usr/local/lib/python2.7/dist-packages/django/core/urlresolvers.py", line 290, in app_dict
    self._populate()
  File "/usr/local/lib/python2.7/dist-packages/django/core/urlresolvers.py", line 253, in _populate
    for name in pattern.reverse_dict:
  File "/usr/local/lib/python2.7/dist-packages/django/core/urlresolvers.py", line 276, in reverse_dict
    self._populate()
  File "/usr/local/lib/python2.7/dist-packages/django/core/urlresolvers.py", line 265, in _populate
    lookups.appendlist(pattern.callback, (bits, p_pattern, pattern.default_args))
  File "/usr/local/lib/python2.7/dist-packages/django/core/urlresolvers.py", line 216, in callback
    self._callback = get_callable(self._callback_str)
  File "/usr/local/lib/python2.7/dist-packages/django/utils/functional.py", line 27, in wrapper
    result = func(*args)
  File "/usr/local/lib/python2.7/dist-packages/django/core/urlresolvers.py", line 101, in get_callable
    (lookup_view, mod_name))
ViewDoesNotExist: Could not import commProd.views.register. View does not exist in module commProd.views.
Internal Server Error: /register/123/
Traceback (most recent call last):
  File "/usr/local/lib/python2.7/dist-packages/django/core/handlers/base.py", line 111, in get_response
    response = callback(request, *callback_args, **callback_kwargs)
  File "/home/max/Desktop/comm-prod/commProd/views.py", line 31, in register
    redirect('home',  message = 'No such user')
NameError: global name 'redirect' is not defined
Internal Server Error: /register/123/
Traceback (most recent call last):
  File "/usr/local/lib/python2.7/dist-packages/django/core/handlers/base.py", line 111, in get_response
    response = callback(request, *callback_args, **callback_kwargs)
  File "/home/max/Desktop/comm-prod/commProd/views.py", line 32, in register
    redirect('home',  message = 'No such user')
  File "/usr/local/lib/python2.7/dist-packages/django/shortcuts/__init__.py", line 75, in redirect
    return redirect_class(urlresolvers.reverse(to, args=args, kwargs=kwargs))
  File "/usr/local/lib/python2.7/dist-packages/django/core/urlresolvers.py", line 476, in reverse
    return iri_to_uri(resolver._reverse_with_prefix(view, prefix, *args, **kwargs))
  File "/usr/local/lib/python2.7/dist-packages/django/core/urlresolvers.py", line 396, in _reverse_with_prefix
    "arguments '%s' not found." % (lookup_view_s, args, kwargs))
NoReverseMatch: Reverse for 'home' with arguments '()' and keyword arguments '{'message': 'No such user'}' not found.
Internal Server Error: /register/123/
Traceback (most recent call last):
  File "/usr/local/lib/python2.7/dist-packages/django/core/handlers/base.py", line 101, in get_response
    request.path_info)
  File "/usr/local/lib/python2.7/dist-packages/django/core/urlresolvers.py", line 298, in resolve
    for pattern in self.url_patterns:
  File "/usr/local/lib/python2.7/dist-packages/django/core/urlresolvers.py", line 328, in url_patterns
    patterns = getattr(self.urlconf_module, "urlpatterns", self.urlconf_module)
  File "/usr/local/lib/python2.7/dist-packages/django/core/urlresolvers.py", line 323, in urlconf_module
    self._urlconf_module = import_module(self.urlconf_name)
  File "/usr/local/lib/python2.7/dist-packages/django/utils/importlib.py", line 35, in import_module
    __import__(name)
  File "/home/max/Desktop/comm-prod/commerical_production/urls.py", line 5, in <module>
    admin.autodiscover()
  File "/usr/local/lib/python2.7/dist-packages/django/contrib/admin/__init__.py", line 29, in autodiscover
    import_module('%s.admin' % app)
  File "/usr/local/lib/python2.7/dist-packages/django/utils/importlib.py", line 35, in import_module
    __import__(name)
  File "/home/max/Desktop/comm-prod/commProd/admin.py", line 1, in <module>
    from commProd.models import CommProd, Rating, UserInfo, UserProfile
ImportError: cannot import name UserInfo
Internal Server Error: /favicon.ico
Traceback (most recent call last):
  File "/usr/local/lib/python2.7/dist-packages/django/core/handlers/base.py", line 101, in get_response
    request.path_info)
  File "/usr/local/lib/python2.7/dist-packages/django/core/urlresolvers.py", line 298, in resolve
    for pattern in self.url_patterns:
  File "/usr/local/lib/python2.7/dist-packages/django/core/urlresolvers.py", line 328, in url_patterns
    patterns = getattr(self.urlconf_module, "urlpatterns", self.urlconf_module)
  File "/usr/local/lib/python2.7/dist-packages/django/core/urlresolvers.py", line 323, in urlconf_module
    self._urlconf_module = import_module(self.urlconf_name)
  File "/usr/local/lib/python2.7/dist-packages/django/utils/importlib.py", line 35, in import_module
    __import__(name)
  File "/home/max/Desktop/comm-prod/commerical_production/urls.py", line 5, in <module>
    admin.autodiscover()
  File "/usr/local/lib/python2.7/dist-packages/django/contrib/admin/__init__.py", line 29, in autodiscover
    import_module('%s.admin' % app)
  File "/usr/local/lib/python2.7/dist-packages/django/utils/importlib.py", line 35, in import_module
    __import__(name)
  File "/home/max/Desktop/comm-prod/commProd/admin.py", line 1, in <module>
    from commProd.models import CommProd, Rating, UserInfo, UserProfile
ImportError: cannot import name UserInfo
Internal Server Error: /register/123/
Traceback (most recent call last):
  File "/usr/local/lib/python2.7/dist-packages/django/core/handlers/base.py", line 101, in get_response
    request.path_info)
  File "/usr/local/lib/python2.7/dist-packages/django/core/urlresolvers.py", line 298, in resolve
    for pattern in self.url_patterns:
  File "/usr/local/lib/python2.7/dist-packages/django/core/urlresolvers.py", line 328, in url_patterns
    patterns = getattr(self.urlconf_module, "urlpatterns", self.urlconf_module)
  File "/usr/local/lib/python2.7/dist-packages/django/core/urlresolvers.py", line 323, in urlconf_module
    self._urlconf_module = import_module(self.urlconf_name)
  File "/usr/local/lib/python2.7/dist-packages/django/utils/importlib.py", line 35, in import_module
    __import__(name)
  File "/home/max/Desktop/comm-prod/commerical_production/urls.py", line 5, in <module>
    admin.autodiscover()
  File "/usr/local/lib/python2.7/dist-packages/django/contrib/admin/__init__.py", line 29, in autodiscover
    import_module('%s.admin' % app)
  File "/usr/local/lib/python2.7/dist-packages/django/utils/importlib.py", line 35, in import_module
    __import__(name)
  File "/home/max/Desktop/comm-prod/commProd/admin.py", line 1, in <module>
    from commProd.models import CommProd, Rating, UserInfo, UserProfile
ImportError: cannot import name UserInfo
Internal Server Error: /favicon.ico
Traceback (most recent call last):
  File "/usr/local/lib/python2.7/dist-packages/django/core/handlers/base.py", line 101, in get_response
    request.path_info)
  File "/usr/local/lib/python2.7/dist-packages/django/core/urlresolvers.py", line 298, in resolve
    for pattern in self.url_patterns:
  File "/usr/local/lib/python2.7/dist-packages/django/core/urlresolvers.py", line 328, in url_patterns
    patterns = getattr(self.urlconf_module, "urlpatterns", self.urlconf_module)
  File "/usr/local/lib/python2.7/dist-packages/django/core/urlresolvers.py", line 323, in urlconf_module
    self._urlconf_module = import_module(self.urlconf_name)
  File "/usr/local/lib/python2.7/dist-packages/django/utils/importlib.py", line 35, in import_module
    __import__(name)
  File "/home/max/Desktop/comm-prod/commerical_production/urls.py", line 5, in <module>
    admin.autodiscover()
  File "/usr/local/lib/python2.7/dist-packages/django/contrib/admin/__init__.py", line 29, in autodiscover
    import_module('%s.admin' % app)
  File "/usr/local/lib/python2.7/dist-packages/django/utils/importlib.py", line 35, in import_module
    __import__(name)
  File "/home/max/Desktop/comm-prod/commProd/admin.py", line 1, in <module>
    from commProd.models import CommProd, Rating, UserInfo, UserProfile
ImportError: cannot import name UserInfo
Internal Server Error: /register/123/
Traceback (most recent call last):
  File "/usr/local/lib/python2.7/dist-packages/django/core/handlers/base.py", line 101, in get_response
    request.path_info)
  File "/usr/local/lib/python2.7/dist-packages/django/core/urlresolvers.py", line 298, in resolve
    for pattern in self.url_patterns:
  File "/usr/local/lib/python2.7/dist-packages/django/core/urlresolvers.py", line 328, in url_patterns
    patterns = getattr(self.urlconf_module, "urlpatterns", self.urlconf_module)
  File "/usr/local/lib/python2.7/dist-packages/django/core/urlresolvers.py", line 323, in urlconf_module
    self._urlconf_module = import_module(self.urlconf_name)
  File "/usr/local/lib/python2.7/dist-packages/django/utils/importlib.py", line 35, in import_module
    __import__(name)
  File "/home/max/Desktop/comm-prod/commerical_production/urls.py", line 5, in <module>
    admin.autodiscover()
  File "/usr/local/lib/python2.7/dist-packages/django/contrib/admin/__init__.py", line 29, in autodiscover
    import_module('%s.admin' % app)
  File "/usr/local/lib/python2.7/dist-packages/django/utils/importlib.py", line 35, in import_module
    __import__(name)
  File "/home/max/Desktop/comm-prod/commProd/admin.py", line 1, in <module>
    from commProd.models import CommProd, Rating, UserInfo, UserProfile
ImportError: cannot import name UserInfo
Internal Server Error: /favicon.ico
Traceback (most recent call last):
  File "/usr/local/lib/python2.7/dist-packages/django/core/handlers/base.py", line 101, in get_response
    request.path_info)
  File "/usr/local/lib/python2.7/dist-packages/django/core/urlresolvers.py", line 298, in resolve
    for pattern in self.url_patterns:
  File "/usr/local/lib/python2.7/dist-packages/django/core/urlresolvers.py", line 328, in url_patterns
    patterns = getattr(self.urlconf_module, "urlpatterns", self.urlconf_module)
  File "/usr/local/lib/python2.7/dist-packages/django/core/urlresolvers.py", line 323, in urlconf_module
    self._urlconf_module = import_module(self.urlconf_name)
  File "/usr/local/lib/python2.7/dist-packages/django/utils/importlib.py", line 35, in import_module
    __import__(name)
  File "/home/max/Desktop/comm-prod/commerical_production/urls.py", line 5, in <module>
    admin.autodiscover()
  File "/usr/local/lib/python2.7/dist-packages/django/contrib/admin/__init__.py", line 29, in autodiscover
    import_module('%s.admin' % app)
  File "/usr/local/lib/python2.7/dist-packages/django/utils/importlib.py", line 35, in import_module
    __import__(name)
  File "/home/max/Desktop/comm-prod/commProd/admin.py", line 1, in <module>
    from commProd.models import CommProd, Rating, UserInfo, UserProfile
ImportError: cannot import name UserInfo
Internal Server Error: /register/123/
Traceback (most recent call last):
  File "/usr/local/lib/python2.7/dist-packages/django/core/handlers/base.py", line 101, in get_response
    request.path_info)
  File "/usr/local/lib/python2.7/dist-packages/django/core/urlresolvers.py", line 298, in resolve
    for pattern in self.url_patterns:
  File "/usr/local/lib/python2.7/dist-packages/django/core/urlresolvers.py", line 328, in url_patterns
    patterns = getattr(self.urlconf_module, "urlpatterns", self.urlconf_module)
  File "/usr/local/lib/python2.7/dist-packages/django/core/urlresolvers.py", line 323, in urlconf_module
    self._urlconf_module = import_module(self.urlconf_name)
  File "/usr/local/lib/python2.7/dist-packages/django/utils/importlib.py", line 35, in import_module
    __import__(name)
  File "/home/max/Desktop/comm-prod/commerical_production/urls.py", line 5, in <module>
    admin.autodiscover()
  File "/usr/local/lib/python2.7/dist-packages/django/contrib/admin/__init__.py", line 29, in autodiscover
    import_module('%s.admin' % app)
  File "/usr/local/lib/python2.7/dist-packages/django/utils/importlib.py", line 35, in import_module
    __import__(name)
  File "/home/max/Desktop/comm-prod/commProd/admin.py", line 6, in <module>
    admin.site.register(UserInfo)
NameError: name 'UserInfo' is not defined
Internal Server Error: /favicon.ico
Traceback (most recent call last):
  File "/usr/local/lib/python2.7/dist-packages/django/core/handlers/base.py", line 101, in get_response
    request.path_info)
  File "/usr/local/lib/python2.7/dist-packages/django/core/urlresolvers.py", line 298, in resolve
    for pattern in self.url_patterns:
  File "/usr/local/lib/python2.7/dist-packages/django/core/urlresolvers.py", line 328, in url_patterns
    patterns = getattr(self.urlconf_module, "urlpatterns", self.urlconf_module)
  File "/usr/local/lib/python2.7/dist-packages/django/core/urlresolvers.py", line 323, in urlconf_module
    self._urlconf_module = import_module(self.urlconf_name)
  File "/usr/local/lib/python2.7/dist-packages/django/utils/importlib.py", line 35, in import_module
    __import__(name)
  File "/home/max/Desktop/comm-prod/commerical_production/urls.py", line 5, in <module>
    admin.autodiscover()
  File "/usr/local/lib/python2.7/dist-packages/django/contrib/admin/__init__.py", line 29, in autodiscover
    import_module('%s.admin' % app)
  File "/usr/local/lib/python2.7/dist-packages/django/utils/importlib.py", line 35, in import_module
    __import__(name)
  File "/home/max/Desktop/comm-prod/commProd/admin.py", line 6, in <module>
    admin.site.register(UserInfo)
NameError: name 'UserInfo' is not defined
Internal Server Error: /register/123/
Traceback (most recent call last):
  File "/usr/local/lib/python2.7/dist-packages/django/core/handlers/base.py", line 111, in get_response
    response = callback(request, *callback_args, **callback_kwargs)
  File "/home/max/Desktop/comm-prod/commProd/views.py", line 32, in register
    redirect('home')
  File "/usr/local/lib/python2.7/dist-packages/django/shortcuts/__init__.py", line 75, in redirect
    return redirect_class(urlresolvers.reverse(to, args=args, kwargs=kwargs))
  File "/usr/local/lib/python2.7/dist-packages/django/core/urlresolvers.py", line 476, in reverse
    return iri_to_uri(resolver._reverse_with_prefix(view, prefix, *args, **kwargs))
  File "/usr/local/lib/python2.7/dist-packages/django/core/urlresolvers.py", line 396, in _reverse_with_prefix
    "arguments '%s' not found." % (lookup_view_s, args, kwargs))
NoReverseMatch: Reverse for 'home' with arguments '()' and keyword arguments '{}' not found.
Internal Server Error: /register/123/
Traceback (most recent call last):
  File "/usr/local/lib/python2.7/dist-packages/django/core/handlers/base.py", line 111, in get_response
    response = callback(request, *callback_args, **callback_kwargs)
  File "/home/max/Desktop/comm-prod/commProd/views.py", line 32, in register
    redirect('')
  File "/usr/local/lib/python2.7/dist-packages/django/shortcuts/__init__.py", line 75, in redirect
    return redirect_class(urlresolvers.reverse(to, args=args, kwargs=kwargs))
  File "/usr/local/lib/python2.7/dist-packages/django/core/urlresolvers.py", line 476, in reverse
    return iri_to_uri(resolver._reverse_with_prefix(view, prefix, *args, **kwargs))
  File "/usr/local/lib/python2.7/dist-packages/django/core/urlresolvers.py", line 396, in _reverse_with_prefix
    "arguments '%s' not found." % (lookup_view_s, args, kwargs))
NoReverseMatch: Reverse for '' with arguments '()' and keyword arguments '{}' not found.
Internal Server Error: /register/123/
Traceback (most recent call last):
  File "/usr/local/lib/python2.7/dist-packages/django/core/handlers/base.py", line 111, in get_response
    response = callback(request, *callback_args, **callback_kwargs)
  File "/home/max/Desktop/comm-prod/commProd/views.py", line 32, in register
    return redirect('home')
  File "/usr/local/lib/python2.7/dist-packages/django/shortcuts/__init__.py", line 75, in redirect
    return redirect_class(urlresolvers.reverse(to, args=args, kwargs=kwargs))
  File "/usr/local/lib/python2.7/dist-packages/django/core/urlresolvers.py", line 476, in reverse
    return iri_to_uri(resolver._reverse_with_prefix(view, prefix, *args, **kwargs))
  File "/usr/local/lib/python2.7/dist-packages/django/core/urlresolvers.py", line 396, in _reverse_with_prefix
    "arguments '%s' not found." % (lookup_view_s, args, kwargs))
NoReverseMatch: Reverse for 'home' with arguments '()' and keyword arguments '{}' not found.
Internal Server Error: /admin/
Traceback (most recent call last):
  File "/usr/local/lib/python2.7/dist-packages/django/core/handlers/base.py", line 111, in get_response
    response = callback(request, *callback_args, **callback_kwargs)
  File "/usr/local/lib/python2.7/dist-packages/django/contrib/admin/sites.py", line 213, in wrapper
    return self.admin_view(view, cacheable)(*args, **kwargs)
  File "/usr/local/lib/python2.7/dist-packages/django/utils/decorators.py", line 91, in _wrapped_view
    response = view_func(request, *args, **kwargs)
  File "/usr/local/lib/python2.7/dist-packages/django/views/decorators/cache.py", line 89, in _wrapped_view_func
    response = view_func(request, *args, **kwargs)
  File "/usr/local/lib/python2.7/dist-packages/django/contrib/admin/sites.py", line 196, in inner
    return view(request, *args, **kwargs)
  File "/usr/local/lib/python2.7/dist-packages/django/views/decorators/cache.py", line 89, in _wrapped_view_func
    response = view_func(request, *args, **kwargs)
  File "/usr/local/lib/python2.7/dist-packages/django/contrib/admin/sites.py", line 353, in index
    model_dict['admin_url'] = reverse('admin:%s_%s_changelist' % info, current_app=self.name)
  File "/usr/local/lib/python2.7/dist-packages/django/core/urlresolvers.py", line 447, in reverse
    app_list = resolver.app_dict[ns]
  File "/usr/local/lib/python2.7/dist-packages/django/core/urlresolvers.py", line 290, in app_dict
    self._populate()
  File "/usr/local/lib/python2.7/dist-packages/django/core/urlresolvers.py", line 253, in _populate
    for name in pattern.reverse_dict:
  File "/usr/local/lib/python2.7/dist-packages/django/core/urlresolvers.py", line 276, in reverse_dict
    self._populate()
  File "/usr/local/lib/python2.7/dist-packages/django/core/urlresolvers.py", line 265, in _populate
    lookups.appendlist(pattern.callback, (bits, p_pattern, pattern.default_args))
  File "/usr/local/lib/python2.7/dist-packages/django/core/urlresolvers.py", line 216, in callback
    self._callback = get_callable(self._callback_str)
  File "/usr/local/lib/python2.7/dist-packages/django/utils/functional.py", line 27, in wrapper
    result = func(*args)
  File "/usr/local/lib/python2.7/dist-packages/django/core/urlresolvers.py", line 92, in get_callable
    lookup_view = getattr(import_module(mod_name), func_name)
  File "/usr/local/lib/python2.7/dist-packages/django/utils/importlib.py", line 35, in import_module
    __import__(name)
  File "/home/max/Desktop/comm-prod/commProd/views.py", line 124
    rating_query =  Rating.objects.filter(cp_id__exact=cp_id))
                                                             ^
SyntaxError: invalid syntax
Internal Server Error: /processprod
Traceback (most recent call last):
  File "/Library/Frameworks/Python.framework/Versions/2.7/lib/python2.7/site-packages/django/core/handlers/base.py", line 111, in get_response
    response = callback(request, *callback_args, **callback_kwargs)
  File "/Library/Frameworks/Python.framework/Versions/2.7/lib/python2.7/site-packages/django/views/decorators/csrf.py", line 77, in wrapped_view
    return view_func(*args, **kwargs)
  File "/Users/joshblum/Desktop/Dropbox/code/comm.prod/commProd/views.py", line 100, in processMail
    resp += data
TypeError: cannot concatenate 'str' and 'NoneType' objects
Internal Server Error: /processprod
Traceback (most recent call last):
  File "/Library/Frameworks/Python.framework/Versions/2.7/lib/python2.7/site-packages/django/core/handlers/base.py", line 111, in get_response
    response = callback(request, *callback_args, **callback_kwargs)
  File "/Library/Frameworks/Python.framework/Versions/2.7/lib/python2.7/site-packages/django/views/decorators/csrf.py", line 77, in wrapped_view
    return view_func(*args, **kwargs)
  File "/Users/joshblum/Desktop/Dropbox/code/comm.prod/commProd/views.py", line 119, in processMail
    resp += "User %s found with comm prod(s)\n %s" % (sender, commprods)
NameError: global name 'commprods' is not defined
Internal Server Error: /processprod
Traceback (most recent call last):
  File "/Library/Frameworks/Python.framework/Versions/2.7/lib/python2.7/site-packages/django/core/handlers/base.py", line 101, in get_response
    request.path_info)
  File "/Library/Frameworks/Python.framework/Versions/2.7/lib/python2.7/site-packages/django/core/urlresolvers.py", line 300, in resolve
    sub_match = pattern.resolve(new_path)
  File "/Library/Frameworks/Python.framework/Versions/2.7/lib/python2.7/site-packages/django/core/urlresolvers.py", line 300, in resolve
    sub_match = pattern.resolve(new_path)
  File "/Library/Frameworks/Python.framework/Versions/2.7/lib/python2.7/site-packages/django/core/urlresolvers.py", line 209, in resolve
    return ResolverMatch(self.callback, args, kwargs, self.name)
  File "/Library/Frameworks/Python.framework/Versions/2.7/lib/python2.7/site-packages/django/core/urlresolvers.py", line 216, in callback
    self._callback = get_callable(self._callback_str)
  File "/Library/Frameworks/Python.framework/Versions/2.7/lib/python2.7/site-packages/django/utils/functional.py", line 27, in wrapper
    result = func(*args)
  File "/Library/Frameworks/Python.framework/Versions/2.7/lib/python2.7/site-packages/django/core/urlresolvers.py", line 92, in get_callable
    lookup_view = getattr(import_module(mod_name), func_name)
  File "/Library/Frameworks/Python.framework/Versions/2.7/lib/python2.7/site-packages/django/utils/importlib.py", line 35, in import_module
    __import__(name)
  File "/Users/joshblum/Desktop/Dropbox/code/comm.prod/commProd/views.py", line 103
    if data && str(key) == KEY:
             ^
SyntaxError: invalid syntax
Internal Server Error: /admincommProd/commprod/
Traceback (most recent call last):
  File "/Library/Frameworks/Python.framework/Versions/2.7/lib/python2.7/site-packages/django/core/handlers/base.py", line 136, in get_response
    response = response.render()
  File "/Library/Frameworks/Python.framework/Versions/2.7/lib/python2.7/site-packages/django/template/response.py", line 104, in render
    self._set_content(self.rendered_content)
  File "/Library/Frameworks/Python.framework/Versions/2.7/lib/python2.7/site-packages/django/template/response.py", line 81, in rendered_content
    content = template.render(context)
  File "/Library/Frameworks/Python.framework/Versions/2.7/lib/python2.7/site-packages/django/template/base.py", line 140, in render
    return self._render(context)
  File "/Library/Frameworks/Python.framework/Versions/2.7/lib/python2.7/site-packages/django/template/base.py", line 134, in _render
    return self.nodelist.render(context)
  File "/Library/Frameworks/Python.framework/Versions/2.7/lib/python2.7/site-packages/django/template/base.py", line 823, in render
    bit = self.render_node(node, context)
  File "/Library/Frameworks/Python.framework/Versions/2.7/lib/python2.7/site-packages/django/template/debug.py", line 74, in render_node
    return node.render(context)
  File "/Library/Frameworks/Python.framework/Versions/2.7/lib/python2.7/site-packages/django/template/loader_tags.py", line 123, in render
    return compiled_parent._render(context)
  File "/Library/Frameworks/Python.framework/Versions/2.7/lib/python2.7/site-packages/django/template/base.py", line 134, in _render
    return self.nodelist.render(context)
  File "/Library/Frameworks/Python.framework/Versions/2.7/lib/python2.7/site-packages/django/template/base.py", line 823, in render
    bit = self.render_node(node, context)
  File "/Library/Frameworks/Python.framework/Versions/2.7/lib/python2.7/site-packages/django/template/debug.py", line 74, in render_node
    return node.render(context)
  File "/Library/Frameworks/Python.framework/Versions/2.7/lib/python2.7/site-packages/django/template/loader_tags.py", line 123, in render
    return compiled_parent._render(context)
  File "/Library/Frameworks/Python.framework/Versions/2.7/lib/python2.7/site-packages/django/template/base.py", line 134, in _render
    return self.nodelist.render(context)
  File "/Library/Frameworks/Python.framework/Versions/2.7/lib/python2.7/site-packages/django/template/base.py", line 823, in render
    bit = self.render_node(node, context)
  File "/Library/Frameworks/Python.framework/Versions/2.7/lib/python2.7/site-packages/django/template/debug.py", line 74, in render_node
    return node.render(context)
  File "/Library/Frameworks/Python.framework/Versions/2.7/lib/python2.7/site-packages/django/template/loader_tags.py", line 62, in render
    result = block.nodelist.render(context)
  File "/Library/Frameworks/Python.framework/Versions/2.7/lib/python2.7/site-packages/django/template/base.py", line 823, in render
    bit = self.render_node(node, context)
  File "/Library/Frameworks/Python.framework/Versions/2.7/lib/python2.7/site-packages/django/template/debug.py", line 74, in render_node
    return node.render(context)
  File "/Library/Frameworks/Python.framework/Versions/2.7/lib/python2.7/site-packages/django/template/defaulttags.py", line 281, in render
    return nodelist.render(context)
  File "/Library/Frameworks/Python.framework/Versions/2.7/lib/python2.7/site-packages/django/template/base.py", line 823, in render
    bit = self.render_node(node, context)
  File "/Library/Frameworks/Python.framework/Versions/2.7/lib/python2.7/site-packages/django/template/debug.py", line 74, in render_node
    return node.render(context)
  File "/Library/Frameworks/Python.framework/Versions/2.7/lib/python2.7/site-packages/django/template/defaulttags.py", line 411, in render
    url = reverse(view_name, args=args, kwargs=kwargs, current_app=context.current_app)
  File "/Library/Frameworks/Python.framework/Versions/2.7/lib/python2.7/site-packages/django/core/urlresolvers.py", line 447, in reverse
    app_list = resolver.app_dict[ns]
  File "/Library/Frameworks/Python.framework/Versions/2.7/lib/python2.7/site-packages/django/core/urlresolvers.py", line 290, in app_dict
    self._populate()
  File "/Library/Frameworks/Python.framework/Versions/2.7/lib/python2.7/site-packages/django/core/urlresolvers.py", line 253, in _populate
    for name in pattern.reverse_dict:
  File "/Library/Frameworks/Python.framework/Versions/2.7/lib/python2.7/site-packages/django/core/urlresolvers.py", line 276, in reverse_dict
    self._populate()
  File "/Library/Frameworks/Python.framework/Versions/2.7/lib/python2.7/site-packages/django/core/urlresolvers.py", line 265, in _populate
    lookups.appendlist(pattern.callback, (bits, p_pattern, pattern.default_args))
  File "/Library/Frameworks/Python.framework/Versions/2.7/lib/python2.7/site-packages/django/core/urlresolvers.py", line 216, in callback
    self._callback = get_callable(self._callback_str)
  File "/Library/Frameworks/Python.framework/Versions/2.7/lib/python2.7/site-packages/django/utils/functional.py", line 27, in wrapper
    result = func(*args)
  File "/Library/Frameworks/Python.framework/Versions/2.7/lib/python2.7/site-packages/django/core/urlresolvers.py", line 92, in get_callable
    lookup_view = getattr(import_module(mod_name), func_name)
  File "/Library/Frameworks/Python.framework/Versions/2.7/lib/python2.7/site-packages/django/utils/importlib.py", line 35, in import_module
    __import__(name)
  File "/Users/joshblum/Desktop/Dropbox/code/comm.prod/commProd/views.py", line 103
    if data && str(key) == KEY:
             ^
SyntaxError: invalid syntax
Internal Server Error: /processprod
Traceback (most recent call last):
  File "/Library/Frameworks/Python.framework/Versions/2.7/lib/python2.7/site-packages/django/core/handlers/base.py", line 101, in get_response
    request.path_info)
  File "/Library/Frameworks/Python.framework/Versions/2.7/lib/python2.7/site-packages/django/core/urlresolvers.py", line 300, in resolve
    sub_match = pattern.resolve(new_path)
  File "/Library/Frameworks/Python.framework/Versions/2.7/lib/python2.7/site-packages/django/core/urlresolvers.py", line 300, in resolve
    sub_match = pattern.resolve(new_path)
  File "/Library/Frameworks/Python.framework/Versions/2.7/lib/python2.7/site-packages/django/core/urlresolvers.py", line 209, in resolve
    return ResolverMatch(self.callback, args, kwargs, self.name)
  File "/Library/Frameworks/Python.framework/Versions/2.7/lib/python2.7/site-packages/django/core/urlresolvers.py", line 216, in callback
    self._callback = get_callable(self._callback_str)
  File "/Library/Frameworks/Python.framework/Versions/2.7/lib/python2.7/site-packages/django/utils/functional.py", line 27, in wrapper
    result = func(*args)
  File "/Library/Frameworks/Python.framework/Versions/2.7/lib/python2.7/site-packages/django/core/urlresolvers.py", line 92, in get_callable
    lookup_view = getattr(import_module(mod_name), func_name)
  File "/Library/Frameworks/Python.framework/Versions/2.7/lib/python2.7/site-packages/django/utils/importlib.py", line 35, in import_module
    __import__(name)
  File "/Users/joshblum/Desktop/Dropbox/code/comm.prod/commProd/views.py", line 10, in <module>
    from config import KEY
ImportError: No module named config
Internal Server Error: /admincommProd/commprod/
Traceback (most recent call last):
  File "/Library/Frameworks/Python.framework/Versions/2.7/lib/python2.7/site-packages/django/core/handlers/base.py", line 136, in get_response
    response = response.render()
  File "/Library/Frameworks/Python.framework/Versions/2.7/lib/python2.7/site-packages/django/template/response.py", line 104, in render
    self._set_content(self.rendered_content)
  File "/Library/Frameworks/Python.framework/Versions/2.7/lib/python2.7/site-packages/django/template/response.py", line 81, in rendered_content
    content = template.render(context)
  File "/Library/Frameworks/Python.framework/Versions/2.7/lib/python2.7/site-packages/django/template/base.py", line 140, in render
    return self._render(context)
  File "/Library/Frameworks/Python.framework/Versions/2.7/lib/python2.7/site-packages/django/template/base.py", line 134, in _render
    return self.nodelist.render(context)
  File "/Library/Frameworks/Python.framework/Versions/2.7/lib/python2.7/site-packages/django/template/base.py", line 823, in render
    bit = self.render_node(node, context)
  File "/Library/Frameworks/Python.framework/Versions/2.7/lib/python2.7/site-packages/django/template/debug.py", line 74, in render_node
    return node.render(context)
  File "/Library/Frameworks/Python.framework/Versions/2.7/lib/python2.7/site-packages/django/template/loader_tags.py", line 123, in render
    return compiled_parent._render(context)
  File "/Library/Frameworks/Python.framework/Versions/2.7/lib/python2.7/site-packages/django/template/base.py", line 134, in _render
    return self.nodelist.render(context)
  File "/Library/Frameworks/Python.framework/Versions/2.7/lib/python2.7/site-packages/django/template/base.py", line 823, in render
    bit = self.render_node(node, context)
  File "/Library/Frameworks/Python.framework/Versions/2.7/lib/python2.7/site-packages/django/template/debug.py", line 74, in render_node
    return node.render(context)
  File "/Library/Frameworks/Python.framework/Versions/2.7/lib/python2.7/site-packages/django/template/loader_tags.py", line 123, in render
    return compiled_parent._render(context)
  File "/Library/Frameworks/Python.framework/Versions/2.7/lib/python2.7/site-packages/django/template/base.py", line 134, in _render
    return self.nodelist.render(context)
  File "/Library/Frameworks/Python.framework/Versions/2.7/lib/python2.7/site-packages/django/template/base.py", line 823, in render
    bit = self.render_node(node, context)
  File "/Library/Frameworks/Python.framework/Versions/2.7/lib/python2.7/site-packages/django/template/debug.py", line 74, in render_node
    return node.render(context)
  File "/Library/Frameworks/Python.framework/Versions/2.7/lib/python2.7/site-packages/django/template/loader_tags.py", line 62, in render
    result = block.nodelist.render(context)
  File "/Library/Frameworks/Python.framework/Versions/2.7/lib/python2.7/site-packages/django/template/base.py", line 823, in render
    bit = self.render_node(node, context)
  File "/Library/Frameworks/Python.framework/Versions/2.7/lib/python2.7/site-packages/django/template/debug.py", line 74, in render_node
    return node.render(context)
  File "/Library/Frameworks/Python.framework/Versions/2.7/lib/python2.7/site-packages/django/template/defaulttags.py", line 281, in render
    return nodelist.render(context)
  File "/Library/Frameworks/Python.framework/Versions/2.7/lib/python2.7/site-packages/django/template/base.py", line 823, in render
    bit = self.render_node(node, context)
  File "/Library/Frameworks/Python.framework/Versions/2.7/lib/python2.7/site-packages/django/template/debug.py", line 74, in render_node
    return node.render(context)
  File "/Library/Frameworks/Python.framework/Versions/2.7/lib/python2.7/site-packages/django/template/defaulttags.py", line 411, in render
    url = reverse(view_name, args=args, kwargs=kwargs, current_app=context.current_app)
  File "/Library/Frameworks/Python.framework/Versions/2.7/lib/python2.7/site-packages/django/core/urlresolvers.py", line 447, in reverse
    app_list = resolver.app_dict[ns]
  File "/Library/Frameworks/Python.framework/Versions/2.7/lib/python2.7/site-packages/django/core/urlresolvers.py", line 290, in app_dict
    self._populate()
  File "/Library/Frameworks/Python.framework/Versions/2.7/lib/python2.7/site-packages/django/core/urlresolvers.py", line 253, in _populate
    for name in pattern.reverse_dict:
  File "/Library/Frameworks/Python.framework/Versions/2.7/lib/python2.7/site-packages/django/core/urlresolvers.py", line 276, in reverse_dict
    self._populate()
  File "/Library/Frameworks/Python.framework/Versions/2.7/lib/python2.7/site-packages/django/core/urlresolvers.py", line 265, in _populate
    lookups.appendlist(pattern.callback, (bits, p_pattern, pattern.default_args))
  File "/Library/Frameworks/Python.framework/Versions/2.7/lib/python2.7/site-packages/django/core/urlresolvers.py", line 216, in callback
    self._callback = get_callable(self._callback_str)
  File "/Library/Frameworks/Python.framework/Versions/2.7/lib/python2.7/site-packages/django/utils/functional.py", line 27, in wrapper
    result = func(*args)
  File "/Library/Frameworks/Python.framework/Versions/2.7/lib/python2.7/site-packages/django/core/urlresolvers.py", line 92, in get_callable
    lookup_view = getattr(import_module(mod_name), func_name)
  File "/Library/Frameworks/Python.framework/Versions/2.7/lib/python2.7/site-packages/django/utils/importlib.py", line 35, in import_module
    __import__(name)
  File "/Users/joshblum/Desktop/Dropbox/code/comm.prod/commProd/views.py", line 10, in <module>
    from config import KEY
ImportError: No module named config
