Internal Server Error: /processprod
Traceback (most recent call last):
  File "/Library/Frameworks/Python.framework/Versions/2.7/lib/python2.7/site-packages/django/core/handlers/base.py", line 89, in get_response
    response = middleware_method(request)
  File "/Library/Frameworks/Python.framework/Versions/2.7/lib/python2.7/site-packages/django/middleware/common.py", line 67, in process_request
    if (not urlresolvers.is_valid_path(request.path_info, urlconf) and
  File "/Library/Frameworks/Python.framework/Versions/2.7/lib/python2.7/site-packages/django/core/urlresolvers.py", line 531, in is_valid_path
    resolve(path, urlconf)
  File "/Library/Frameworks/Python.framework/Versions/2.7/lib/python2.7/site-packages/django/core/urlresolvers.py", line 420, in resolve
    return get_resolver(urlconf).resolve(path)
  File "/Library/Frameworks/Python.framework/Versions/2.7/lib/python2.7/site-packages/django/core/urlresolvers.py", line 298, in resolve
    for pattern in self.url_patterns:
  File "/Library/Frameworks/Python.framework/Versions/2.7/lib/python2.7/site-packages/django/core/urlresolvers.py", line 328, in url_patterns
    patterns = getattr(self.urlconf_module, "urlpatterns", self.urlconf_module)
  File "/Library/Frameworks/Python.framework/Versions/2.7/lib/python2.7/site-packages/django/core/urlresolvers.py", line 323, in urlconf_module
    self._urlconf_module = import_module(self.urlconf_name)
  File "/Library/Frameworks/Python.framework/Versions/2.7/lib/python2.7/site-packages/django/utils/importlib.py", line 35, in import_module
    __import__(name)
  File "/Users/joshblum/Desktop/Dropbox/code/comm.prod/commerical_production/urls.py", line 15, in <module>
    url(r'', include('commProd.urls')),
  File "/Library/Frameworks/Python.framework/Versions/2.7/lib/python2.7/site-packages/django/conf/urls/__init__.py", line 24, in include
    urlconf_module = import_module(urlconf_module)
  File "/Library/Frameworks/Python.framework/Versions/2.7/lib/python2.7/site-packages/django/utils/importlib.py", line 35, in import_module
    __import__(name)
  File "/Users/joshblum/Desktop/Dropbox/code/comm.prod/commProd/urls.py", line 10
    url(r'^$', 'home')
      ^
SyntaxError: invalid syntax
Internal Server Error: /processprod
Traceback (most recent call last):
  File "/Library/Frameworks/Python.framework/Versions/2.7/lib/python2.7/site-packages/django/core/handlers/base.py", line 111, in get_response
    response = callback(request, *callback_args, **callback_kwargs)
  File "/Library/Frameworks/Python.framework/Versions/2.7/lib/python2.7/site-packages/django/views/decorators/csrf.py", line 77, in wrapped_view
    return view_func(*args, **kwargs)
  File "/Users/joshblum/Desktop/Dropbox/code/comm.prod/commProd/views.py", line 192, in processProd
    user, created = createUser(sender, sender, False)
  File "/Users/joshblum/Desktop/Dropbox/code/comm.prod/commerical_production/create_users.py", line 45, in createUser
    user, created = User.objects.get_or_create(username=username, email=email)
  File "/Library/Frameworks/Python.framework/Versions/2.7/lib/python2.7/site-packages/django/db/models/manager.py", line 134, in get_or_create
    return self.get_query_set().get_or_create(**kwargs)
  File "/Library/Frameworks/Python.framework/Versions/2.7/lib/python2.7/site-packages/django/db/models/query.py", line 449, in get_or_create
    obj.save(force_insert=True, using=self.db)
  File "/Library/Frameworks/Python.framework/Versions/2.7/lib/python2.7/site-packages/django/db/models/base.py", line 463, in save
    self.save_base(using=using, force_insert=force_insert, force_update=force_update)
  File "/Library/Frameworks/Python.framework/Versions/2.7/lib/python2.7/site-packages/django/db/models/base.py", line 565, in save_base
    created=(not record_exists), raw=raw, using=using)
  File "/Library/Frameworks/Python.framework/Versions/2.7/lib/python2.7/site-packages/django/dispatch/dispatcher.py", line 172, in send
    response = receiver(signal=self, sender=sender, **named)
  File "/Users/joshblum/Desktop/Dropbox/code/comm.prod/commProd/models.py", line 57, in create_user_profile
    profile, created = UserProfile.objects.get_or_create(user=instance)
  File "/Library/Frameworks/Python.framework/Versions/2.7/lib/python2.7/site-packages/django/db/models/manager.py", line 134, in get_or_create
    return self.get_query_set().get_or_create(**kwargs)
  File "/Library/Frameworks/Python.framework/Versions/2.7/lib/python2.7/site-packages/django/db/models/query.py", line 442, in get_or_create
    return self.get(**lookup), False
  File "/Library/Frameworks/Python.framework/Versions/2.7/lib/python2.7/site-packages/django/db/models/query.py", line 361, in get
    num = len(clone)
  File "/Library/Frameworks/Python.framework/Versions/2.7/lib/python2.7/site-packages/django/db/models/query.py", line 85, in __len__
    self._result_cache = list(self.iterator())
  File "/Library/Frameworks/Python.framework/Versions/2.7/lib/python2.7/site-packages/django/db/models/query.py", line 291, in iterator
    for row in compiler.results_iter():
  File "/Library/Frameworks/Python.framework/Versions/2.7/lib/python2.7/site-packages/django/db/models/sql/compiler.py", line 763, in results_iter
    for rows in self.execute_sql(MULTI):
  File "/Library/Frameworks/Python.framework/Versions/2.7/lib/python2.7/site-packages/django/db/models/sql/compiler.py", line 818, in execute_sql
    cursor.execute(sql, params)
  File "/Library/Frameworks/Python.framework/Versions/2.7/lib/python2.7/site-packages/django/db/backends/util.py", line 40, in execute
    return self.cursor.execute(sql, params)
  File "/Library/Frameworks/Python.framework/Versions/2.7/lib/python2.7/site-packages/django/db/backends/mysql/base.py", line 114, in execute
    return self.cursor.execute(query, args)
  File "/Users/joshblum/Library/Python/2.7/lib/python/site-packages/MySQLdb/cursors.py", line 174, in execute
    self.errorhandler(self, exc, value)
  File "/Users/joshblum/Library/Python/2.7/lib/python/site-packages/MySQLdb/connections.py", line 36, in defaulterrorhandler
    raise errorclass, errorvalue
DatabaseError: (1054, "Unknown column 'commProd_userprofile.send_mail' in 'field list'")
Internal Server Error: /
Traceback (most recent call last):
  File "/Library/Frameworks/Python.framework/Versions/2.7/lib/python2.7/site-packages/django/core/handlers/base.py", line 101, in get_response
    request.path_info)
  File "/Library/Frameworks/Python.framework/Versions/2.7/lib/python2.7/site-packages/django/core/urlresolvers.py", line 300, in resolve
    sub_match = pattern.resolve(new_path)
  File "/Library/Frameworks/Python.framework/Versions/2.7/lib/python2.7/site-packages/django/core/urlresolvers.py", line 300, in resolve
    sub_match = pattern.resolve(new_path)
  File "/Library/Frameworks/Python.framework/Versions/2.7/lib/python2.7/site-packages/django/core/urlresolvers.py", line 209, in resolve
    return ResolverMatch(self.callback, args, kwargs, self.name)
  File "/Library/Frameworks/Python.framework/Versions/2.7/lib/python2.7/site-packages/django/core/urlresolvers.py", line 216, in callback
    self._callback = get_callable(self._callback_str)
  File "/Library/Frameworks/Python.framework/Versions/2.7/lib/python2.7/site-packages/django/utils/functional.py", line 27, in wrapper
    result = func(*args)
  File "/Library/Frameworks/Python.framework/Versions/2.7/lib/python2.7/site-packages/django/core/urlresolvers.py", line 92, in get_callable
    lookup_view = getattr(import_module(mod_name), func_name)
  File "/Library/Frameworks/Python.framework/Versions/2.7/lib/python2.7/site-packages/django/utils/importlib.py", line 35, in import_module
    __import__(name)
  File "/Users/joshblum/Desktop/Dropbox/code/comm.prod/commProd/views.py", line 15, in <module>
    from commerical_production.commprod_search import commprod_search
ImportError: No module named commprod_search
Internal Server Error: /
Traceback (most recent call last):
  File "/Library/Frameworks/Python.framework/Versions/2.7/lib/python2.7/site-packages/django/core/handlers/base.py", line 101, in get_response
    request.path_info)
  File "/Library/Frameworks/Python.framework/Versions/2.7/lib/python2.7/site-packages/django/core/urlresolvers.py", line 300, in resolve
    sub_match = pattern.resolve(new_path)
  File "/Library/Frameworks/Python.framework/Versions/2.7/lib/python2.7/site-packages/django/core/urlresolvers.py", line 300, in resolve
    sub_match = pattern.resolve(new_path)
  File "/Library/Frameworks/Python.framework/Versions/2.7/lib/python2.7/site-packages/django/core/urlresolvers.py", line 209, in resolve
    return ResolverMatch(self.callback, args, kwargs, self.name)
  File "/Library/Frameworks/Python.framework/Versions/2.7/lib/python2.7/site-packages/django/core/urlresolvers.py", line 216, in callback
    self._callback = get_callable(self._callback_str)
  File "/Library/Frameworks/Python.framework/Versions/2.7/lib/python2.7/site-packages/django/utils/functional.py", line 27, in wrapper
    result = func(*args)
  File "/Library/Frameworks/Python.framework/Versions/2.7/lib/python2.7/site-packages/django/core/urlresolvers.py", line 92, in get_callable
    lookup_view = getattr(import_module(mod_name), func_name)
  File "/Library/Frameworks/Python.framework/Versions/2.7/lib/python2.7/site-packages/django/utils/importlib.py", line 35, in import_module
    __import__(name)
  File "/Users/joshblum/Desktop/Dropbox/code/comm.prod/commProd/views.py", line 16, in <module>
    from helpers.view_helpers import getRandomUsername, renderErrorMessage
ImportError: No module named helpers.view_helpers
Internal Server Error: /
Traceback (most recent call last):
  File "/Library/Frameworks/Python.framework/Versions/2.7/lib/python2.7/site-packages/django/core/handlers/base.py", line 101, in get_response
    request.path_info)
  File "/Library/Frameworks/Python.framework/Versions/2.7/lib/python2.7/site-packages/django/core/urlresolvers.py", line 300, in resolve
    sub_match = pattern.resolve(new_path)
  File "/Library/Frameworks/Python.framework/Versions/2.7/lib/python2.7/site-packages/django/core/urlresolvers.py", line 300, in resolve
    sub_match = pattern.resolve(new_path)
  File "/Library/Frameworks/Python.framework/Versions/2.7/lib/python2.7/site-packages/django/core/urlresolvers.py", line 209, in resolve
    return ResolverMatch(self.callback, args, kwargs, self.name)
  File "/Library/Frameworks/Python.framework/Versions/2.7/lib/python2.7/site-packages/django/core/urlresolvers.py", line 216, in callback
    self._callback = get_callable(self._callback_str)
  File "/Library/Frameworks/Python.framework/Versions/2.7/lib/python2.7/site-packages/django/utils/functional.py", line 27, in wrapper
    result = func(*args)
  File "/Library/Frameworks/Python.framework/Versions/2.7/lib/python2.7/site-packages/django/core/urlresolvers.py", line 92, in get_callable
    lookup_view = getattr(import_module(mod_name), func_name)
  File "/Library/Frameworks/Python.framework/Versions/2.7/lib/python2.7/site-packages/django/utils/importlib.py", line 35, in import_module
    __import__(name)
  File "/Users/joshblum/Desktop/Dropbox/code/comm.prod/commProd/views.py", line 17, in <module>
    from helpers.commprod_search import commprod_search
ImportError: No module named helpers.commprod_search
Internal Server Error: /
Traceback (most recent call last):
  File "/Library/Frameworks/Python.framework/Versions/2.7/lib/python2.7/site-packages/django/core/handlers/base.py", line 101, in get_response
    request.path_info)
  File "/Library/Frameworks/Python.framework/Versions/2.7/lib/python2.7/site-packages/django/core/urlresolvers.py", line 300, in resolve
    sub_match = pattern.resolve(new_path)
  File "/Library/Frameworks/Python.framework/Versions/2.7/lib/python2.7/site-packages/django/core/urlresolvers.py", line 300, in resolve
    sub_match = pattern.resolve(new_path)
  File "/Library/Frameworks/Python.framework/Versions/2.7/lib/python2.7/site-packages/django/core/urlresolvers.py", line 209, in resolve
    return ResolverMatch(self.callback, args, kwargs, self.name)
  File "/Library/Frameworks/Python.framework/Versions/2.7/lib/python2.7/site-packages/django/core/urlresolvers.py", line 216, in callback
    self._callback = get_callable(self._callback_str)
  File "/Library/Frameworks/Python.framework/Versions/2.7/lib/python2.7/site-packages/django/utils/functional.py", line 27, in wrapper
    result = func(*args)
  File "/Library/Frameworks/Python.framework/Versions/2.7/lib/python2.7/site-packages/django/core/urlresolvers.py", line 92, in get_callable
    lookup_view = getattr(import_module(mod_name), func_name)
  File "/Library/Frameworks/Python.framework/Versions/2.7/lib/python2.7/site-packages/django/utils/importlib.py", line 35, in import_module
    __import__(name)
  File "/Users/joshblum/Desktop/Dropbox/code/comm.prod/commProd/views.py", line 16, in <module>
    from helpers.view_helpers import getRandomUsername, renderErrorMessage
ImportError: No module named helpers.view_helpers
Internal Server Error: /
Traceback (most recent call last):
  File "/Library/Frameworks/Python.framework/Versions/2.7/lib/python2.7/site-packages/django/core/handlers/base.py", line 101, in get_response
    request.path_info)
  File "/Library/Frameworks/Python.framework/Versions/2.7/lib/python2.7/site-packages/django/core/urlresolvers.py", line 300, in resolve
    sub_match = pattern.resolve(new_path)
  File "/Library/Frameworks/Python.framework/Versions/2.7/lib/python2.7/site-packages/django/core/urlresolvers.py", line 300, in resolve
    sub_match = pattern.resolve(new_path)
  File "/Library/Frameworks/Python.framework/Versions/2.7/lib/python2.7/site-packages/django/core/urlresolvers.py", line 209, in resolve
    return ResolverMatch(self.callback, args, kwargs, self.name)
  File "/Library/Frameworks/Python.framework/Versions/2.7/lib/python2.7/site-packages/django/core/urlresolvers.py", line 216, in callback
    self._callback = get_callable(self._callback_str)
  File "/Library/Frameworks/Python.framework/Versions/2.7/lib/python2.7/site-packages/django/utils/functional.py", line 27, in wrapper
    result = func(*args)
  File "/Library/Frameworks/Python.framework/Versions/2.7/lib/python2.7/site-packages/django/core/urlresolvers.py", line 92, in get_callable
    lookup_view = getattr(import_module(mod_name), func_name)
  File "/Library/Frameworks/Python.framework/Versions/2.7/lib/python2.7/site-packages/django/utils/importlib.py", line 35, in import_module
    __import__(name)
  File "/Users/joshblum/Desktop/Dropbox/code/comm.prod/commProd/views.py", line 16, in <module>
    from commerical_production.helpers.view_helpers import getRandomUsername, renderErrorMessage
ImportError: No module named helpers.view_helpers
Internal Server Error: /
Traceback (most recent call last):
  File "/Library/Frameworks/Python.framework/Versions/2.7/lib/python2.7/site-packages/django/core/handlers/base.py", line 101, in get_response
    request.path_info)
  File "/Library/Frameworks/Python.framework/Versions/2.7/lib/python2.7/site-packages/django/core/urlresolvers.py", line 300, in resolve
    sub_match = pattern.resolve(new_path)
  File "/Library/Frameworks/Python.framework/Versions/2.7/lib/python2.7/site-packages/django/core/urlresolvers.py", line 300, in resolve
    sub_match = pattern.resolve(new_path)
  File "/Library/Frameworks/Python.framework/Versions/2.7/lib/python2.7/site-packages/django/core/urlresolvers.py", line 209, in resolve
    return ResolverMatch(self.callback, args, kwargs, self.name)
  File "/Library/Frameworks/Python.framework/Versions/2.7/lib/python2.7/site-packages/django/core/urlresolvers.py", line 216, in callback
    self._callback = get_callable(self._callback_str)
  File "/Library/Frameworks/Python.framework/Versions/2.7/lib/python2.7/site-packages/django/utils/functional.py", line 27, in wrapper
    result = func(*args)
  File "/Library/Frameworks/Python.framework/Versions/2.7/lib/python2.7/site-packages/django/core/urlresolvers.py", line 92, in get_callable
    lookup_view = getattr(import_module(mod_name), func_name)
  File "/Library/Frameworks/Python.framework/Versions/2.7/lib/python2.7/site-packages/django/utils/importlib.py", line 35, in import_module
    __import__(name)
  File "/Users/joshblum/Desktop/Dropbox/code/comm.prod/commProd/views.py", line 16, in <module>
    from commerical_production.helpers.view_helpers import getRandomUsername, renderErrorMessage
ImportError: No module named helpers.view_helpers
Internal Server Error: /
Traceback (most recent call last):
  File "/Library/Frameworks/Python.framework/Versions/2.7/lib/python2.7/site-packages/django/core/handlers/base.py", line 101, in get_response
    request.path_info)
  File "/Library/Frameworks/Python.framework/Versions/2.7/lib/python2.7/site-packages/django/core/urlresolvers.py", line 300, in resolve
    sub_match = pattern.resolve(new_path)
  File "/Library/Frameworks/Python.framework/Versions/2.7/lib/python2.7/site-packages/django/core/urlresolvers.py", line 300, in resolve
    sub_match = pattern.resolve(new_path)
  File "/Library/Frameworks/Python.framework/Versions/2.7/lib/python2.7/site-packages/django/core/urlresolvers.py", line 209, in resolve
    return ResolverMatch(self.callback, args, kwargs, self.name)
  File "/Library/Frameworks/Python.framework/Versions/2.7/lib/python2.7/site-packages/django/core/urlresolvers.py", line 216, in callback
    self._callback = get_callable(self._callback_str)
  File "/Library/Frameworks/Python.framework/Versions/2.7/lib/python2.7/site-packages/django/utils/functional.py", line 27, in wrapper
    result = func(*args)
  File "/Library/Frameworks/Python.framework/Versions/2.7/lib/python2.7/site-packages/django/core/urlresolvers.py", line 92, in get_callable
    lookup_view = getattr(import_module(mod_name), func_name)
  File "/Library/Frameworks/Python.framework/Versions/2.7/lib/python2.7/site-packages/django/utils/importlib.py", line 35, in import_module
    __import__(name)
  File "/Users/joshblum/Desktop/Dropbox/code/comm.prod/commProd/views.py", line 16, in <module>
    from commerical_production.helpers.view_helpers import getRandomUsername, renderErrorMessage
ImportError: No module named helpers.view_helpers
Internal Server Error: /
Traceback (most recent call last):
  File "/Library/Frameworks/Python.framework/Versions/2.7/lib/python2.7/site-packages/django/core/handlers/base.py", line 101, in get_response
    request.path_info)
  File "/Library/Frameworks/Python.framework/Versions/2.7/lib/python2.7/site-packages/django/core/urlresolvers.py", line 300, in resolve
    sub_match = pattern.resolve(new_path)
  File "/Library/Frameworks/Python.framework/Versions/2.7/lib/python2.7/site-packages/django/core/urlresolvers.py", line 300, in resolve
    sub_match = pattern.resolve(new_path)
  File "/Library/Frameworks/Python.framework/Versions/2.7/lib/python2.7/site-packages/django/core/urlresolvers.py", line 209, in resolve
    return ResolverMatch(self.callback, args, kwargs, self.name)
  File "/Library/Frameworks/Python.framework/Versions/2.7/lib/python2.7/site-packages/django/core/urlresolvers.py", line 216, in callback
    self._callback = get_callable(self._callback_str)
  File "/Library/Frameworks/Python.framework/Versions/2.7/lib/python2.7/site-packages/django/utils/functional.py", line 27, in wrapper
    result = func(*args)
  File "/Library/Frameworks/Python.framework/Versions/2.7/lib/python2.7/site-packages/django/core/urlresolvers.py", line 92, in get_callable
    lookup_view = getattr(import_module(mod_name), func_name)
  File "/Library/Frameworks/Python.framework/Versions/2.7/lib/python2.7/site-packages/django/utils/importlib.py", line 35, in import_module
    __import__(name)
  File "/Users/joshblum/Desktop/Dropbox/code/comm.prod/commProd/views.py", line 16, in <module>
    from commerical_production.helpers import * #.view_helpers import getRandomUsername, renderErrorMessage
ImportError: No module named helpers
Internal Server Error: /
Traceback (most recent call last):
  File "/Library/Frameworks/Python.framework/Versions/2.7/lib/python2.7/site-packages/django/core/handlers/base.py", line 101, in get_response
    request.path_info)
  File "/Library/Frameworks/Python.framework/Versions/2.7/lib/python2.7/site-packages/django/core/urlresolvers.py", line 300, in resolve
    sub_match = pattern.resolve(new_path)
  File "/Library/Frameworks/Python.framework/Versions/2.7/lib/python2.7/site-packages/django/core/urlresolvers.py", line 300, in resolve
    sub_match = pattern.resolve(new_path)
  File "/Library/Frameworks/Python.framework/Versions/2.7/lib/python2.7/site-packages/django/core/urlresolvers.py", line 209, in resolve
    return ResolverMatch(self.callback, args, kwargs, self.name)
  File "/Library/Frameworks/Python.framework/Versions/2.7/lib/python2.7/site-packages/django/core/urlresolvers.py", line 216, in callback
    self._callback = get_callable(self._callback_str)
  File "/Library/Frameworks/Python.framework/Versions/2.7/lib/python2.7/site-packages/django/utils/functional.py", line 27, in wrapper
    result = func(*args)
  File "/Library/Frameworks/Python.framework/Versions/2.7/lib/python2.7/site-packages/django/core/urlresolvers.py", line 92, in get_callable
    lookup_view = getattr(import_module(mod_name), func_name)
  File "/Library/Frameworks/Python.framework/Versions/2.7/lib/python2.7/site-packages/django/utils/importlib.py", line 35, in import_module
    __import__(name)
  File "/Users/joshblum/Desktop/Dropbox/code/comm.prod/commProd/views.py", line 16, in <module>
    from helpers import * #.view_helpers import getRandomUsername, renderErrorMessage
ImportError: No module named helpers
Internal Server Error: /
Traceback (most recent call last):
  File "/Library/Frameworks/Python.framework/Versions/2.7/lib/python2.7/site-packages/django/core/handlers/base.py", line 101, in get_response
    request.path_info)
  File "/Library/Frameworks/Python.framework/Versions/2.7/lib/python2.7/site-packages/django/core/urlresolvers.py", line 300, in resolve
    sub_match = pattern.resolve(new_path)
  File "/Library/Frameworks/Python.framework/Versions/2.7/lib/python2.7/site-packages/django/core/urlresolvers.py", line 300, in resolve
    sub_match = pattern.resolve(new_path)
  File "/Library/Frameworks/Python.framework/Versions/2.7/lib/python2.7/site-packages/django/core/urlresolvers.py", line 209, in resolve
    return ResolverMatch(self.callback, args, kwargs, self.name)
  File "/Library/Frameworks/Python.framework/Versions/2.7/lib/python2.7/site-packages/django/core/urlresolvers.py", line 216, in callback
    self._callback = get_callable(self._callback_str)
  File "/Library/Frameworks/Python.framework/Versions/2.7/lib/python2.7/site-packages/django/utils/functional.py", line 27, in wrapper
    result = func(*args)
  File "/Library/Frameworks/Python.framework/Versions/2.7/lib/python2.7/site-packages/django/core/urlresolvers.py", line 92, in get_callable
    lookup_view = getattr(import_module(mod_name), func_name)
  File "/Library/Frameworks/Python.framework/Versions/2.7/lib/python2.7/site-packages/django/utils/importlib.py", line 35, in import_module
    __import__(name)
  File "/Users/joshblum/Desktop/Dropbox/code/comm.prod/commProd/views.py", line 16, in <module>
    from helpers import * #.view_helpers import getRandomUsername, renderErrorMessage
ImportError: No module named helpers
Internal Server Error: /
Traceback (most recent call last):
  File "/Library/Frameworks/Python.framework/Versions/2.7/lib/python2.7/site-packages/django/core/handlers/base.py", line 101, in get_response
    request.path_info)
  File "/Library/Frameworks/Python.framework/Versions/2.7/lib/python2.7/site-packages/django/core/urlresolvers.py", line 300, in resolve
    sub_match = pattern.resolve(new_path)
  File "/Library/Frameworks/Python.framework/Versions/2.7/lib/python2.7/site-packages/django/core/urlresolvers.py", line 300, in resolve
    sub_match = pattern.resolve(new_path)
  File "/Library/Frameworks/Python.framework/Versions/2.7/lib/python2.7/site-packages/django/core/urlresolvers.py", line 209, in resolve
    return ResolverMatch(self.callback, args, kwargs, self.name)
  File "/Library/Frameworks/Python.framework/Versions/2.7/lib/python2.7/site-packages/django/core/urlresolvers.py", line 216, in callback
    self._callback = get_callable(self._callback_str)
  File "/Library/Frameworks/Python.framework/Versions/2.7/lib/python2.7/site-packages/django/utils/functional.py", line 27, in wrapper
    result = func(*args)
  File "/Library/Frameworks/Python.framework/Versions/2.7/lib/python2.7/site-packages/django/core/urlresolvers.py", line 92, in get_callable
    lookup_view = getattr(import_module(mod_name), func_name)
  File "/Library/Frameworks/Python.framework/Versions/2.7/lib/python2.7/site-packages/django/utils/importlib.py", line 35, in import_module
    __import__(name)
  File "/Users/joshblum/Desktop/Dropbox/code/comm.prod/commProd/views.py", line 16, in <module>
    from commProd.helpers import * #.view_helpers import getRandomUsername, renderErrorMessage
ImportError: No module named helpers
Internal Server Error: /
Traceback (most recent call last):
  File "/Library/Frameworks/Python.framework/Versions/2.7/lib/python2.7/site-packages/django/core/handlers/base.py", line 101, in get_response
    request.path_info)
  File "/Library/Frameworks/Python.framework/Versions/2.7/lib/python2.7/site-packages/django/core/urlresolvers.py", line 300, in resolve
    sub_match = pattern.resolve(new_path)
  File "/Library/Frameworks/Python.framework/Versions/2.7/lib/python2.7/site-packages/django/core/urlresolvers.py", line 300, in resolve
    sub_match = pattern.resolve(new_path)
  File "/Library/Frameworks/Python.framework/Versions/2.7/lib/python2.7/site-packages/django/core/urlresolvers.py", line 209, in resolve
    return ResolverMatch(self.callback, args, kwargs, self.name)
  File "/Library/Frameworks/Python.framework/Versions/2.7/lib/python2.7/site-packages/django/core/urlresolvers.py", line 216, in callback
    self._callback = get_callable(self._callback_str)
  File "/Library/Frameworks/Python.framework/Versions/2.7/lib/python2.7/site-packages/django/utils/functional.py", line 27, in wrapper
    result = func(*args)
  File "/Library/Frameworks/Python.framework/Versions/2.7/lib/python2.7/site-packages/django/core/urlresolvers.py", line 92, in get_callable
    lookup_view = getattr(import_module(mod_name), func_name)
  File "/Library/Frameworks/Python.framework/Versions/2.7/lib/python2.7/site-packages/django/utils/importlib.py", line 35, in import_module
    __import__(name)
  File "/Users/joshblum/Desktop/Dropbox/code/comm.prod/commProd/views.py", line 16, in <module>
    from commProd.helpers import * #.view_helpers import getRandomUsername, renderErrorMessage
ImportError: No module named helpers
Internal Server Error: /
Traceback (most recent call last):
  File "/Library/Frameworks/Python.framework/Versions/2.7/lib/python2.7/site-packages/django/core/handlers/base.py", line 101, in get_response
    request.path_info)
  File "/Library/Frameworks/Python.framework/Versions/2.7/lib/python2.7/site-packages/django/core/urlresolvers.py", line 300, in resolve
    sub_match = pattern.resolve(new_path)
  File "/Library/Frameworks/Python.framework/Versions/2.7/lib/python2.7/site-packages/django/core/urlresolvers.py", line 300, in resolve
    sub_match = pattern.resolve(new_path)
  File "/Library/Frameworks/Python.framework/Versions/2.7/lib/python2.7/site-packages/django/core/urlresolvers.py", line 209, in resolve
    return ResolverMatch(self.callback, args, kwargs, self.name)
  File "/Library/Frameworks/Python.framework/Versions/2.7/lib/python2.7/site-packages/django/core/urlresolvers.py", line 216, in callback
    self._callback = get_callable(self._callback_str)
  File "/Library/Frameworks/Python.framework/Versions/2.7/lib/python2.7/site-packages/django/utils/functional.py", line 27, in wrapper
    result = func(*args)
  File "/Library/Frameworks/Python.framework/Versions/2.7/lib/python2.7/site-packages/django/core/urlresolvers.py", line 92, in get_callable
    lookup_view = getattr(import_module(mod_name), func_name)
  File "/Library/Frameworks/Python.framework/Versions/2.7/lib/python2.7/site-packages/django/utils/importlib.py", line 35, in import_module
    __import__(name)
  File "/Users/joshblum/Desktop/Dropbox/code/comm.prod/commProd/views.py", line 17, in <module>
    from commerical_production.helpers.commprod_search import commprod_search
ImportError: No module named helpers.commprod_search
Internal Server Error: /
Traceback (most recent call last):
  File "/Library/Frameworks/Python.framework/Versions/2.7/lib/python2.7/site-packages/django/core/handlers/base.py", line 101, in get_response
    request.path_info)
  File "/Library/Frameworks/Python.framework/Versions/2.7/lib/python2.7/site-packages/django/core/urlresolvers.py", line 300, in resolve
    sub_match = pattern.resolve(new_path)
  File "/Library/Frameworks/Python.framework/Versions/2.7/lib/python2.7/site-packages/django/core/urlresolvers.py", line 300, in resolve
    sub_match = pattern.resolve(new_path)
  File "/Library/Frameworks/Python.framework/Versions/2.7/lib/python2.7/site-packages/django/core/urlresolvers.py", line 209, in resolve
    return ResolverMatch(self.callback, args, kwargs, self.name)
  File "/Library/Frameworks/Python.framework/Versions/2.7/lib/python2.7/site-packages/django/core/urlresolvers.py", line 216, in callback
    self._callback = get_callable(self._callback_str)
  File "/Library/Frameworks/Python.framework/Versions/2.7/lib/python2.7/site-packages/django/utils/functional.py", line 27, in wrapper
    result = func(*args)
  File "/Library/Frameworks/Python.framework/Versions/2.7/lib/python2.7/site-packages/django/core/urlresolvers.py", line 92, in get_callable
    lookup_view = getattr(import_module(mod_name), func_name)
  File "/Library/Frameworks/Python.framework/Versions/2.7/lib/python2.7/site-packages/django/utils/importlib.py", line 35, in import_module
    __import__(name)
  File "/Users/joshblum/Desktop/Dropbox/code/comm.prod/commProd/views.py", line 18, in <module>
    from helpers.admin.utils import createUser
  File "/Users/joshblum/Desktop/Dropbox/code/comm.prod/helpers/admin/utils.py", line 6, in <module>
    from commerical_production.email_templates import registration
ImportError: No module named email_templates
Internal Server Error: /login
Traceback (most recent call last):
  File "/usr/local/lib/python2.7/dist-packages/django/core/handlers/base.py", line 136, in get_response
    response = response.render()
  File "/usr/local/lib/python2.7/dist-packages/django/template/response.py", line 104, in render
    self._set_content(self.rendered_content)
  File "/usr/local/lib/python2.7/dist-packages/django/template/response.py", line 81, in rendered_content
    content = template.render(context)
  File "/usr/local/lib/python2.7/dist-packages/django/template/base.py", line 140, in render
    return self._render(context)
  File "/usr/local/lib/python2.7/dist-packages/django/template/base.py", line 134, in _render
    return self.nodelist.render(context)
  File "/usr/local/lib/python2.7/dist-packages/django/template/base.py", line 823, in render
    bit = self.render_node(node, context)
  File "/usr/local/lib/python2.7/dist-packages/django/template/debug.py", line 74, in render_node
    return node.render(context)
  File "/usr/local/lib/python2.7/dist-packages/django/template/loader_tags.py", line 101, in render
    compiled_parent = self.get_parent(context)
  File "/usr/local/lib/python2.7/dist-packages/django/template/loader_tags.py", line 98, in get_parent
    return get_template(parent)
  File "/usr/local/lib/python2.7/dist-packages/django/template/loader.py", line 145, in get_template
    template, origin = find_template(template_name)
  File "/usr/local/lib/python2.7/dist-packages/django/template/loader.py", line 134, in find_template
    source, display_name = loader(name, dirs)
  File "/usr/local/lib/python2.7/dist-packages/django/template/loader.py", line 42, in __call__
    return self.load_template(template_name, template_dirs)
  File "/usr/local/lib/python2.7/dist-packages/django/template/loader.py", line 48, in load_template
    template = get_template_from_string(source, origin, template_name)
  File "/usr/local/lib/python2.7/dist-packages/django/template/loader.py", line 156, in get_template_from_string
    return Template(source, origin, name)
  File "/usr/local/lib/python2.7/dist-packages/django/template/base.py", line 125, in __init__
    self.nodelist = compile_string(template_string, origin)
  File "/usr/local/lib/python2.7/dist-packages/django/template/base.py", line 153, in compile_string
    return parser.parse()
  File "/usr/local/lib/python2.7/dist-packages/django/template/base.py", line 265, in parse
    self.invalid_block_tag(token, command, parse_until)
  File "/usr/local/lib/python2.7/dist-packages/django/template/base.py", line 321, in invalid_block_tag
    raise self.error(token, "Invalid block tag: '%s'" % command)
TemplateSyntaxError: Invalid block tag: 'elif'
Internal Server Error: /login
Traceback (most recent call last):
  File "/usr/local/lib/python2.7/dist-packages/django/core/handlers/base.py", line 136, in get_response
    response = response.render()
  File "/usr/local/lib/python2.7/dist-packages/django/template/response.py", line 104, in render
    self._set_content(self.rendered_content)
  File "/usr/local/lib/python2.7/dist-packages/django/template/response.py", line 81, in rendered_content
    content = template.render(context)
  File "/usr/local/lib/python2.7/dist-packages/django/template/base.py", line 140, in render
    return self._render(context)
  File "/usr/local/lib/python2.7/dist-packages/django/template/base.py", line 134, in _render
    return self.nodelist.render(context)
  File "/usr/local/lib/python2.7/dist-packages/django/template/base.py", line 823, in render
    bit = self.render_node(node, context)
  File "/usr/local/lib/python2.7/dist-packages/django/template/debug.py", line 74, in render_node
    return node.render(context)
  File "/usr/local/lib/python2.7/dist-packages/django/template/loader_tags.py", line 101, in render
    compiled_parent = self.get_parent(context)
  File "/usr/local/lib/python2.7/dist-packages/django/template/loader_tags.py", line 98, in get_parent
    return get_template(parent)
  File "/usr/local/lib/python2.7/dist-packages/django/template/loader.py", line 145, in get_template
    template, origin = find_template(template_name)
  File "/usr/local/lib/python2.7/dist-packages/django/template/loader.py", line 134, in find_template
    source, display_name = loader(name, dirs)
  File "/usr/local/lib/python2.7/dist-packages/django/template/loader.py", line 42, in __call__
    return self.load_template(template_name, template_dirs)
  File "/usr/local/lib/python2.7/dist-packages/django/template/loader.py", line 48, in load_template
    template = get_template_from_string(source, origin, template_name)
  File "/usr/local/lib/python2.7/dist-packages/django/template/loader.py", line 156, in get_template_from_string
    return Template(source, origin, name)
  File "/usr/local/lib/python2.7/dist-packages/django/template/base.py", line 125, in __init__
    self.nodelist = compile_string(template_string, origin)
  File "/usr/local/lib/python2.7/dist-packages/django/template/base.py", line 153, in compile_string
    return parser.parse()
  File "/usr/local/lib/python2.7/dist-packages/django/template/base.py", line 265, in parse
    self.invalid_block_tag(token, command, parse_until)
  File "/usr/local/lib/python2.7/dist-packages/django/template/base.py", line 321, in invalid_block_tag
    raise self.error(token, "Invalid block tag: '%s'" % command)
TemplateSyntaxError: Invalid block tag: 'endif'
Internal Server Error: /popular
Traceback (most recent call last):
  File "/usr/local/lib/python2.7/dist-packages/django/core/handlers/base.py", line 111, in get_response
    response = callback(request, *callback_args, **callback_kwargs)
  File "/usr/local/lib/python2.7/dist-packages/django/contrib/auth/decorators.py", line 20, in _wrapped_view
    return view_func(request, *args, **kwargs)
  File "/home/max/Documents/projects/comm.prod/commProd/views.py", line 132, in search
    'commprods' : commprod_search(**kwards)
NameError: global name 'kwards' is not defined
Internal Server Error: /recent
Traceback (most recent call last):
  File "/usr/local/lib/python2.7/dist-packages/django/core/handlers/base.py", line 89, in get_response
    response = middleware_method(request)
  File "/usr/local/lib/python2.7/dist-packages/django/middleware/common.py", line 67, in process_request
    if (not urlresolvers.is_valid_path(request.path_info, urlconf) and
  File "/usr/local/lib/python2.7/dist-packages/django/core/urlresolvers.py", line 531, in is_valid_path
    resolve(path, urlconf)
  File "/usr/local/lib/python2.7/dist-packages/django/core/urlresolvers.py", line 420, in resolve
    return get_resolver(urlconf).resolve(path)
  File "/usr/local/lib/python2.7/dist-packages/django/core/urlresolvers.py", line 298, in resolve
    for pattern in self.url_patterns:
  File "/usr/local/lib/python2.7/dist-packages/django/core/urlresolvers.py", line 328, in url_patterns
    patterns = getattr(self.urlconf_module, "urlpatterns", self.urlconf_module)
  File "/usr/local/lib/python2.7/dist-packages/django/core/urlresolvers.py", line 323, in urlconf_module
    self._urlconf_module = import_module(self.urlconf_name)
  File "/usr/local/lib/python2.7/dist-packages/django/utils/importlib.py", line 35, in import_module
    __import__(name)
  File "/home/max/Documents/projects/comm.prod/commerical_production/urls.py", line 15, in <module>
    url(r'', include('commProd.urls')),
  File "/usr/local/lib/python2.7/dist-packages/django/conf/urls/__init__.py", line 24, in include
    urlconf_module = import_module(urlconf_module)
  File "/usr/local/lib/python2.7/dist-packages/django/utils/importlib.py", line 35, in import_module
    __import__(name)
  File "/home/max/Documents/projects/comm.prod/commProd/urls.py", line 10
    url(r'^recent$', 'search', {'title':'Recent comm.prods', 'orderBy': 'date', 'direction'='lh'}),
                                                                                           ^
SyntaxError: invalid syntax
Internal Server Error: /favicon.ico
Traceback (most recent call last):
  File "/usr/local/lib/python2.7/dist-packages/django/core/handlers/base.py", line 89, in get_response
    response = middleware_method(request)
  File "/usr/local/lib/python2.7/dist-packages/django/middleware/common.py", line 67, in process_request
    if (not urlresolvers.is_valid_path(request.path_info, urlconf) and
  File "/usr/local/lib/python2.7/dist-packages/django/core/urlresolvers.py", line 531, in is_valid_path
    resolve(path, urlconf)
  File "/usr/local/lib/python2.7/dist-packages/django/core/urlresolvers.py", line 420, in resolve
    return get_resolver(urlconf).resolve(path)
  File "/usr/local/lib/python2.7/dist-packages/django/core/urlresolvers.py", line 298, in resolve
    for pattern in self.url_patterns:
  File "/usr/local/lib/python2.7/dist-packages/django/core/urlresolvers.py", line 328, in url_patterns
    patterns = getattr(self.urlconf_module, "urlpatterns", self.urlconf_module)
  File "/usr/local/lib/python2.7/dist-packages/django/core/urlresolvers.py", line 323, in urlconf_module
    self._urlconf_module = import_module(self.urlconf_name)
  File "/usr/local/lib/python2.7/dist-packages/django/utils/importlib.py", line 35, in import_module
    __import__(name)
  File "/home/max/Documents/projects/comm.prod/commerical_production/urls.py", line 15, in <module>
    url(r'', include('commProd.urls')),
  File "/usr/local/lib/python2.7/dist-packages/django/conf/urls/__init__.py", line 24, in include
    urlconf_module = import_module(urlconf_module)
  File "/usr/local/lib/python2.7/dist-packages/django/utils/importlib.py", line 35, in import_module
    __import__(name)
  File "/home/max/Documents/projects/comm.prod/commProd/urls.py", line 10
    url(r'^recent$', 'search', {'title':'Recent comm.prods', 'orderBy': 'date', 'direction'='lh'}),
                                                                                           ^
SyntaxError: invalid syntax
Internal Server Error: /popular
Traceback (most recent call last):
  File "/usr/local/lib/python2.7/dist-packages/django/core/handlers/base.py", line 89, in get_response
    response = middleware_method(request)
  File "/usr/local/lib/python2.7/dist-packages/django/middleware/common.py", line 67, in process_request
    if (not urlresolvers.is_valid_path(request.path_info, urlconf) and
  File "/usr/local/lib/python2.7/dist-packages/django/core/urlresolvers.py", line 531, in is_valid_path
    resolve(path, urlconf)
  File "/usr/local/lib/python2.7/dist-packages/django/core/urlresolvers.py", line 420, in resolve
    return get_resolver(urlconf).resolve(path)
  File "/usr/local/lib/python2.7/dist-packages/django/core/urlresolvers.py", line 298, in resolve
    for pattern in self.url_patterns:
  File "/usr/local/lib/python2.7/dist-packages/django/core/urlresolvers.py", line 328, in url_patterns
    patterns = getattr(self.urlconf_module, "urlpatterns", self.urlconf_module)
  File "/usr/local/lib/python2.7/dist-packages/django/core/urlresolvers.py", line 323, in urlconf_module
    self._urlconf_module = import_module(self.urlconf_name)
  File "/usr/local/lib/python2.7/dist-packages/django/utils/importlib.py", line 35, in import_module
    __import__(name)
  File "/home/max/Documents/projects/comm.prod/commerical_production/urls.py", line 15, in <module>
    url(r'', include('commProd.urls')),
  File "/usr/local/lib/python2.7/dist-packages/django/conf/urls/__init__.py", line 24, in include
    urlconf_module = import_module(urlconf_module)
  File "/usr/local/lib/python2.7/dist-packages/django/utils/importlib.py", line 35, in import_module
    __import__(name)
  File "/home/max/Documents/projects/comm.prod/commProd/urls.py", line 9
    url(r'^popular$', 'search', {'title':'Popular comm.prods', 'orderBy': 'avg_score', 'direction'; 'h1'}),
                                                                                                  ^
SyntaxError: invalid syntax
Internal Server Error: /favicon.ico
Traceback (most recent call last):
  File "/usr/local/lib/python2.7/dist-packages/django/core/handlers/base.py", line 89, in get_response
    response = middleware_method(request)
  File "/usr/local/lib/python2.7/dist-packages/django/middleware/common.py", line 67, in process_request
    if (not urlresolvers.is_valid_path(request.path_info, urlconf) and
  File "/usr/local/lib/python2.7/dist-packages/django/core/urlresolvers.py", line 531, in is_valid_path
    resolve(path, urlconf)
  File "/usr/local/lib/python2.7/dist-packages/django/core/urlresolvers.py", line 420, in resolve
    return get_resolver(urlconf).resolve(path)
  File "/usr/local/lib/python2.7/dist-packages/django/core/urlresolvers.py", line 298, in resolve
    for pattern in self.url_patterns:
  File "/usr/local/lib/python2.7/dist-packages/django/core/urlresolvers.py", line 328, in url_patterns
    patterns = getattr(self.urlconf_module, "urlpatterns", self.urlconf_module)
  File "/usr/local/lib/python2.7/dist-packages/django/core/urlresolvers.py", line 323, in urlconf_module
    self._urlconf_module = import_module(self.urlconf_name)
  File "/usr/local/lib/python2.7/dist-packages/django/utils/importlib.py", line 35, in import_module
    __import__(name)
  File "/home/max/Documents/projects/comm.prod/commerical_production/urls.py", line 15, in <module>
    url(r'', include('commProd.urls')),
  File "/usr/local/lib/python2.7/dist-packages/django/conf/urls/__init__.py", line 24, in include
    urlconf_module = import_module(urlconf_module)
  File "/usr/local/lib/python2.7/dist-packages/django/utils/importlib.py", line 35, in import_module
    __import__(name)
  File "/home/max/Documents/projects/comm.prod/commProd/urls.py", line 9
    url(r'^popular$', 'search', {'title':'Popular comm.prods', 'orderBy': 'avg_score', 'direction'; 'h1'}),
                                                                                                  ^
SyntaxError: invalid syntax
