Internal Server Error: /login
Traceback (most recent call last):
  File "/usr/local/lib/python2.7/dist-packages/django/core/handlers/base.py", line 188, in get_response
    response = middleware_method(request, response)
  File "/usr/local/lib/python2.7/dist-packages/django/contrib/sessions/middleware.py", line 34, in process_response
    expires = cookie_date(expires_time)
  File "/usr/local/lib/python2.7/dist-packages/django/utils/http.py", line 88, in cookie_date
    rfcdate = formatdate(epoch_seconds)
  File "/usr/lib/python2.7/email/utils.py", line 161, in formatdate
    now = time.gmtime(timeval)
ValueError: timestamp out of range for platform time_t
Internal Server Error: /login
Traceback (most recent call last):
  File "/usr/local/lib/python2.7/dist-packages/django/core/handlers/base.py", line 188, in get_response
    response = middleware_method(request, response)
  File "/usr/local/lib/python2.7/dist-packages/django/contrib/sessions/middleware.py", line 34, in process_response
    expires = cookie_date(expires_time)
  File "/usr/local/lib/python2.7/dist-packages/django/utils/http.py", line 88, in cookie_date
    rfcdate = formatdate(epoch_seconds)
  File "/usr/lib/python2.7/email/utils.py", line 161, in formatdate
    now = time.gmtime(timeval)
ValueError: timestamp out of range for platform time_t
Internal Server Error: /login
Traceback (most recent call last):
  File "/usr/local/lib/python2.7/dist-packages/django/core/handlers/base.py", line 188, in get_response
    response = middleware_method(request, response)
  File "/usr/local/lib/python2.7/dist-packages/django/contrib/sessions/middleware.py", line 34, in process_response
    expires = cookie_date(expires_time)
  File "/usr/local/lib/python2.7/dist-packages/django/utils/http.py", line 88, in cookie_date
    rfcdate = formatdate(epoch_seconds)
  File "/usr/lib/python2.7/email/utils.py", line 161, in formatdate
    now = time.gmtime(timeval)
ValueError: timestamp out of range for platform time_t
Internal Server Error: /login
Traceback (most recent call last):
  File "/usr/local/lib/python2.7/dist-packages/django/core/handlers/base.py", line 188, in get_response
    response = middleware_method(request, response)
  File "/usr/local/lib/python2.7/dist-packages/django/contrib/sessions/middleware.py", line 34, in process_response
    expires = cookie_date(expires_time)
  File "/usr/local/lib/python2.7/dist-packages/django/utils/http.py", line 88, in cookie_date
    rfcdate = formatdate(epoch_seconds)
  File "/usr/lib/python2.7/email/utils.py", line 161, in formatdate
    now = time.gmtime(timeval)
ValueError: timestamp out of range for platform time_t
Internal Server Error: /login
Traceback (most recent call last):
  File "/usr/local/lib/python2.7/dist-packages/django/core/handlers/base.py", line 188, in get_response
    response = middleware_method(request, response)
  File "/usr/local/lib/python2.7/dist-packages/django/contrib/sessions/middleware.py", line 34, in process_response
    expires = cookie_date(expires_time)
  File "/usr/local/lib/python2.7/dist-packages/django/utils/http.py", line 88, in cookie_date
    rfcdate = formatdate(epoch_seconds)
  File "/usr/lib/python2.7/email/utils.py", line 161, in formatdate
    now = time.gmtime(timeval)
ValueError: timestamp out of range for platform time_t
Internal Server Error: /login
Traceback (most recent call last):
  File "/usr/local/lib/python2.7/dist-packages/django/core/handlers/base.py", line 188, in get_response
    response = middleware_method(request, response)
  File "/usr/local/lib/python2.7/dist-packages/django/contrib/sessions/middleware.py", line 34, in process_response
    expires = cookie_date(expires_time)
  File "/usr/local/lib/python2.7/dist-packages/django/utils/http.py", line 88, in cookie_date
    rfcdate = formatdate(epoch_seconds)
  File "/usr/lib/python2.7/email/utils.py", line 161, in formatdate
    now = time.gmtime(timeval)
ValueError: timestamp out of range for platform time_t
Internal Server Error: /login
Traceback (most recent call last):
  File "/usr/local/lib/python2.7/dist-packages/django/core/handlers/base.py", line 188, in get_response
    response = middleware_method(request, response)
  File "/usr/local/lib/python2.7/dist-packages/django/contrib/sessions/middleware.py", line 34, in process_response
    expires = cookie_date(expires_time)
  File "/usr/local/lib/python2.7/dist-packages/django/utils/http.py", line 88, in cookie_date
    rfcdate = formatdate(epoch_seconds)
  File "/usr/lib/python2.7/email/utils.py", line 161, in formatdate
    now = time.gmtime(timeval)
ValueError: timestamp out of range for platform time_t
Internal Server Error: /login
Traceback (most recent call last):
  File "/usr/local/lib/python2.7/dist-packages/django/core/handlers/base.py", line 188, in get_response
    response = middleware_method(request, response)
  File "/usr/local/lib/python2.7/dist-packages/django/contrib/sessions/middleware.py", line 34, in process_response
    expires = cookie_date(expires_time)
  File "/usr/local/lib/python2.7/dist-packages/django/utils/http.py", line 88, in cookie_date
    rfcdate = formatdate(epoch_seconds)
  File "/usr/lib/python2.7/email/utils.py", line 161, in formatdate
    now = time.gmtime(timeval)
ValueError: timestamp out of range for platform time_t
Internal Server Error: /login
Traceback (most recent call last):
  File "/usr/local/lib/python2.7/dist-packages/django/core/handlers/base.py", line 111, in get_response
    response = callback(request, *callback_args, **callback_kwargs)
  File "/usr/local/lib/python2.7/dist-packages/django/views/decorators/debug.py", line 69, in wrapper
    return view(request, *args, **kwargs)
  File "/usr/local/lib/python2.7/dist-packages/django/utils/decorators.py", line 91, in _wrapped_view
    response = view_func(request, *args, **kwargs)
  File "/usr/local/lib/python2.7/dist-packages/django/views/decorators/cache.py", line 89, in _wrapped_view_func
    response = view_func(request, *args, **kwargs)
  File "/usr/local/lib/python2.7/dist-packages/django/contrib/auth/views.py", line 58, in login
    request.session.set_test_cookie()
  File "/usr/local/lib/python2.7/dist-packages/django/contrib/sessions/backends/base.py", line 65, in set_test_cookie
    self[self.TEST_COOKIE_NAME] = self.TEST_COOKIE_VALUE
  File "/usr/local/lib/python2.7/dist-packages/django/contrib/sessions/backends/base.py", line 42, in __setitem__
    self._session[key] = value
  File "/usr/local/lib/python2.7/dist-packages/django/contrib/sessions/backends/base.py", line 165, in _get_session
    self._session_cache = self.load()
  File "/usr/local/lib/python2.7/dist-packages/django/contrib/sessions/backends/db.py", line 19, in load
    expire_date__gt=timezone.now()
  File "/usr/local/lib/python2.7/dist-packages/django/db/models/manager.py", line 131, in get
    return self.get_query_set().get(*args, **kwargs)
  File "/usr/local/lib/python2.7/dist-packages/django/db/models/query.py", line 361, in get
    num = len(clone)
  File "/usr/local/lib/python2.7/dist-packages/django/db/models/query.py", line 85, in __len__
    self._result_cache = list(self.iterator())
  File "/usr/local/lib/python2.7/dist-packages/django/db/models/query.py", line 291, in iterator
    for row in compiler.results_iter():
  File "/usr/local/lib/python2.7/dist-packages/django/db/models/sql/compiler.py", line 763, in results_iter
    for rows in self.execute_sql(MULTI):
  File "/usr/local/lib/python2.7/dist-packages/django/db/models/sql/compiler.py", line 817, in execute_sql
    cursor = self.connection.cursor()
  File "/usr/local/lib/python2.7/dist-packages/django/db/backends/__init__.py", line 306, in cursor
    cursor = self.make_debug_cursor(self._cursor())
  File "/usr/local/lib/python2.7/dist-packages/django/db/backends/mysql/base.py", line 387, in _cursor
    self.connection = Database.connect(**kwargs)
  File "/usr/local/lib/python2.7/dist-packages/MySQLdb/__init__.py", line 81, in Connect
    return Connection(*args, **kwargs)
  File "/usr/local/lib/python2.7/dist-packages/MySQLdb/connections.py", line 187, in __init__
    super(Connection, self).__init__(*args, **kwargs2)
OperationalError: (2003, "Can't connect to MySQL server on 'sql.mit.edu' (110)")
Internal Server Error: /
Traceback (most recent call last):
  File "/usr/local/lib/python2.7/dist-packages/django/core/handlers/base.py", line 111, in get_response
    response = callback(request, *callback_args, **callback_kwargs)
  File "/usr/local/lib/python2.7/dist-packages/django/contrib/auth/decorators.py", line 19, in _wrapped_view
    if test_func(request.user):
  File "/usr/local/lib/python2.7/dist-packages/django/contrib/auth/decorators.py", line 42, in <lambda>
    lambda u: u.is_authenticated(),
  File "/usr/local/lib/python2.7/dist-packages/django/utils/functional.py", line 184, in inner
    self._setup()
  File "/usr/local/lib/python2.7/dist-packages/django/utils/functional.py", line 248, in _setup
    self._wrapped = self._setupfunc()
  File "/usr/local/lib/python2.7/dist-packages/django/contrib/auth/middleware.py", line 16, in <lambda>
    request.user = SimpleLazyObject(lambda: get_user(request))
  File "/usr/local/lib/python2.7/dist-packages/django/contrib/auth/middleware.py", line 8, in get_user
    request._cached_user = auth.get_user(request)
  File "/usr/local/lib/python2.7/dist-packages/django/contrib/auth/__init__.py", line 98, in get_user
    user_id = request.session[SESSION_KEY]
  File "/usr/local/lib/python2.7/dist-packages/django/contrib/sessions/backends/base.py", line 39, in __getitem__
    return self._session[key]
  File "/usr/local/lib/python2.7/dist-packages/django/contrib/sessions/backends/base.py", line 165, in _get_session
    self._session_cache = self.load()
  File "/usr/local/lib/python2.7/dist-packages/django/contrib/sessions/backends/db.py", line 19, in load
    expire_date__gt=timezone.now()
  File "/usr/local/lib/python2.7/dist-packages/django/db/models/manager.py", line 131, in get
    return self.get_query_set().get(*args, **kwargs)
  File "/usr/local/lib/python2.7/dist-packages/django/db/models/query.py", line 361, in get
    num = len(clone)
  File "/usr/local/lib/python2.7/dist-packages/django/db/models/query.py", line 85, in __len__
    self._result_cache = list(self.iterator())
  File "/usr/local/lib/python2.7/dist-packages/django/db/models/query.py", line 291, in iterator
    for row in compiler.results_iter():
  File "/usr/local/lib/python2.7/dist-packages/django/db/models/sql/compiler.py", line 763, in results_iter
    for rows in self.execute_sql(MULTI):
  File "/usr/local/lib/python2.7/dist-packages/django/db/models/sql/compiler.py", line 817, in execute_sql
    cursor = self.connection.cursor()
  File "/usr/local/lib/python2.7/dist-packages/django/db/backends/__init__.py", line 306, in cursor
    cursor = self.make_debug_cursor(self._cursor())
  File "/usr/local/lib/python2.7/dist-packages/django/db/backends/mysql/base.py", line 387, in _cursor
    self.connection = Database.connect(**kwargs)
  File "/usr/local/lib/python2.7/dist-packages/MySQLdb/__init__.py", line 81, in Connect
    return Connection(*args, **kwargs)
  File "/usr/local/lib/python2.7/dist-packages/MySQLdb/connections.py", line 187, in __init__
    super(Connection, self).__init__(*args, **kwargs2)
OperationalError: (2003, "Can't connect to MySQL server on 'sql.mit.edu' (110)")
Internal Server Error: /
Traceback (most recent call last):
  File "/usr/local/lib/python2.7/dist-packages/django/core/handlers/base.py", line 111, in get_response
    response = callback(request, *callback_args, **callback_kwargs)
  File "/usr/local/lib/python2.7/dist-packages/django/contrib/auth/decorators.py", line 19, in _wrapped_view
    if test_func(request.user):
  File "/usr/local/lib/python2.7/dist-packages/django/contrib/auth/decorators.py", line 42, in <lambda>
    lambda u: u.is_authenticated(),
  File "/usr/local/lib/python2.7/dist-packages/django/utils/functional.py", line 184, in inner
    self._setup()
  File "/usr/local/lib/python2.7/dist-packages/django/utils/functional.py", line 248, in _setup
    self._wrapped = self._setupfunc()
  File "/usr/local/lib/python2.7/dist-packages/django/contrib/auth/middleware.py", line 16, in <lambda>
    request.user = SimpleLazyObject(lambda: get_user(request))
  File "/usr/local/lib/python2.7/dist-packages/django/contrib/auth/middleware.py", line 8, in get_user
    request._cached_user = auth.get_user(request)
  File "/usr/local/lib/python2.7/dist-packages/django/contrib/auth/__init__.py", line 98, in get_user
    user_id = request.session[SESSION_KEY]
  File "/usr/local/lib/python2.7/dist-packages/django/contrib/sessions/backends/base.py", line 39, in __getitem__
    return self._session[key]
  File "/usr/local/lib/python2.7/dist-packages/django/contrib/sessions/backends/base.py", line 165, in _get_session
    self._session_cache = self.load()
  File "/usr/local/lib/python2.7/dist-packages/django/contrib/sessions/backends/db.py", line 19, in load
    expire_date__gt=timezone.now()
  File "/usr/local/lib/python2.7/dist-packages/django/db/models/manager.py", line 131, in get
    return self.get_query_set().get(*args, **kwargs)
  File "/usr/local/lib/python2.7/dist-packages/django/db/models/query.py", line 361, in get
    num = len(clone)
  File "/usr/local/lib/python2.7/dist-packages/django/db/models/query.py", line 85, in __len__
    self._result_cache = list(self.iterator())
  File "/usr/local/lib/python2.7/dist-packages/django/db/models/query.py", line 291, in iterator
    for row in compiler.results_iter():
  File "/usr/local/lib/python2.7/dist-packages/django/db/models/sql/compiler.py", line 763, in results_iter
    for rows in self.execute_sql(MULTI):
  File "/usr/local/lib/python2.7/dist-packages/django/db/models/sql/compiler.py", line 817, in execute_sql
    cursor = self.connection.cursor()
  File "/usr/local/lib/python2.7/dist-packages/django/db/backends/__init__.py", line 306, in cursor
    cursor = self.make_debug_cursor(self._cursor())
  File "/usr/local/lib/python2.7/dist-packages/django/db/backends/mysql/base.py", line 387, in _cursor
    self.connection = Database.connect(**kwargs)
  File "/usr/local/lib/python2.7/dist-packages/MySQLdb/__init__.py", line 81, in Connect
    return Connection(*args, **kwargs)
  File "/usr/local/lib/python2.7/dist-packages/MySQLdb/connections.py", line 187, in __init__
    super(Connection, self).__init__(*args, **kwargs2)
OperationalError: (2005, "Unknown MySQL server host 'sql.mit.edu' (2)")
Internal Server Error: /admin
Traceback (most recent call last):
  File "/usr/local/lib/python2.7/dist-packages/django/core/handlers/base.py", line 111, in get_response
    response = callback(request, *callback_args, **callback_kwargs)
  File "/usr/local/lib/python2.7/dist-packages/django/contrib/admin/sites.py", line 213, in wrapper
    return self.admin_view(view, cacheable)(*args, **kwargs)
  File "/usr/local/lib/python2.7/dist-packages/django/utils/decorators.py", line 91, in _wrapped_view
    response = view_func(request, *args, **kwargs)
  File "/usr/local/lib/python2.7/dist-packages/django/views/decorators/cache.py", line 89, in _wrapped_view_func
    response = view_func(request, *args, **kwargs)
  File "/usr/local/lib/python2.7/dist-packages/django/contrib/admin/sites.py", line 190, in inner
    if not self.has_permission(request):
  File "/usr/local/lib/python2.7/dist-packages/django/contrib/admin/sites.py", line 143, in has_permission
    return request.user.is_active and request.user.is_staff
  File "/usr/local/lib/python2.7/dist-packages/django/utils/functional.py", line 184, in inner
    self._setup()
  File "/usr/local/lib/python2.7/dist-packages/django/utils/functional.py", line 248, in _setup
    self._wrapped = self._setupfunc()
  File "/usr/local/lib/python2.7/dist-packages/django/contrib/auth/middleware.py", line 16, in <lambda>
    request.user = SimpleLazyObject(lambda: get_user(request))
  File "/usr/local/lib/python2.7/dist-packages/django/contrib/auth/middleware.py", line 8, in get_user
    request._cached_user = auth.get_user(request)
  File "/usr/local/lib/python2.7/dist-packages/django/contrib/auth/__init__.py", line 98, in get_user
    user_id = request.session[SESSION_KEY]
  File "/usr/local/lib/python2.7/dist-packages/django/contrib/sessions/backends/base.py", line 39, in __getitem__
    return self._session[key]
  File "/usr/local/lib/python2.7/dist-packages/django/contrib/sessions/backends/base.py", line 165, in _get_session
    self._session_cache = self.load()
  File "/usr/local/lib/python2.7/dist-packages/django/contrib/sessions/backends/db.py", line 19, in load
    expire_date__gt=timezone.now()
  File "/usr/local/lib/python2.7/dist-packages/django/db/models/manager.py", line 131, in get
    return self.get_query_set().get(*args, **kwargs)
  File "/usr/local/lib/python2.7/dist-packages/django/db/models/query.py", line 361, in get
    num = len(clone)
  File "/usr/local/lib/python2.7/dist-packages/django/db/models/query.py", line 85, in __len__
    self._result_cache = list(self.iterator())
  File "/usr/local/lib/python2.7/dist-packages/django/db/models/query.py", line 291, in iterator
    for row in compiler.results_iter():
  File "/usr/local/lib/python2.7/dist-packages/django/db/models/sql/compiler.py", line 763, in results_iter
    for rows in self.execute_sql(MULTI):
  File "/usr/local/lib/python2.7/dist-packages/django/db/models/sql/compiler.py", line 817, in execute_sql
    cursor = self.connection.cursor()
  File "/usr/local/lib/python2.7/dist-packages/django/db/backends/__init__.py", line 306, in cursor
    cursor = self.make_debug_cursor(self._cursor())
  File "/usr/local/lib/python2.7/dist-packages/django/db/backends/mysql/base.py", line 387, in _cursor
    self.connection = Database.connect(**kwargs)
  File "/usr/local/lib/python2.7/dist-packages/MySQLdb/__init__.py", line 81, in Connect
    return Connection(*args, **kwargs)
  File "/usr/local/lib/python2.7/dist-packages/MySQLdb/connections.py", line 187, in __init__
    super(Connection, self).__init__(*args, **kwargs2)
OperationalError: (2003, "Can't connect to MySQL server on 'sql.mit.edu' (110)")
Internal Server Error: /
Traceback (most recent call last):
  File "/usr/local/lib/python2.7/dist-packages/django/core/handlers/base.py", line 111, in get_response
    response = callback(request, *callback_args, **callback_kwargs)
  File "/usr/local/lib/python2.7/dist-packages/django/contrib/auth/decorators.py", line 19, in _wrapped_view
    if test_func(request.user):
  File "/usr/local/lib/python2.7/dist-packages/django/contrib/auth/decorators.py", line 42, in <lambda>
    lambda u: u.is_authenticated(),
  File "/usr/local/lib/python2.7/dist-packages/django/utils/functional.py", line 184, in inner
    self._setup()
  File "/usr/local/lib/python2.7/dist-packages/django/utils/functional.py", line 248, in _setup
    self._wrapped = self._setupfunc()
  File "/usr/local/lib/python2.7/dist-packages/django/contrib/auth/middleware.py", line 16, in <lambda>
    request.user = SimpleLazyObject(lambda: get_user(request))
  File "/usr/local/lib/python2.7/dist-packages/django/contrib/auth/middleware.py", line 8, in get_user
    request._cached_user = auth.get_user(request)
  File "/usr/local/lib/python2.7/dist-packages/django/contrib/auth/__init__.py", line 98, in get_user
    user_id = request.session[SESSION_KEY]
  File "/usr/local/lib/python2.7/dist-packages/django/contrib/sessions/backends/base.py", line 39, in __getitem__
    return self._session[key]
  File "/usr/local/lib/python2.7/dist-packages/django/contrib/sessions/backends/base.py", line 165, in _get_session
    self._session_cache = self.load()
  File "/usr/local/lib/python2.7/dist-packages/django/contrib/sessions/backends/db.py", line 19, in load
    expire_date__gt=timezone.now()
  File "/usr/local/lib/python2.7/dist-packages/django/db/models/manager.py", line 131, in get
    return self.get_query_set().get(*args, **kwargs)
  File "/usr/local/lib/python2.7/dist-packages/django/db/models/query.py", line 361, in get
    num = len(clone)
  File "/usr/local/lib/python2.7/dist-packages/django/db/models/query.py", line 85, in __len__
    self._result_cache = list(self.iterator())
  File "/usr/local/lib/python2.7/dist-packages/django/db/models/query.py", line 291, in iterator
    for row in compiler.results_iter():
  File "/usr/local/lib/python2.7/dist-packages/django/db/models/sql/compiler.py", line 763, in results_iter
    for rows in self.execute_sql(MULTI):
  File "/usr/local/lib/python2.7/dist-packages/django/db/models/sql/compiler.py", line 817, in execute_sql
    cursor = self.connection.cursor()
  File "/usr/local/lib/python2.7/dist-packages/django/db/backends/__init__.py", line 306, in cursor
    cursor = self.make_debug_cursor(self._cursor())
  File "/usr/local/lib/python2.7/dist-packages/django/db/backends/mysql/base.py", line 387, in _cursor
    self.connection = Database.connect(**kwargs)
  File "/usr/local/lib/python2.7/dist-packages/MySQLdb/__init__.py", line 81, in Connect
    return Connection(*args, **kwargs)
  File "/usr/local/lib/python2.7/dist-packages/MySQLdb/connections.py", line 187, in __init__
    super(Connection, self).__init__(*args, **kwargs2)
OperationalError: (2003, "Can't connect to MySQL server on 'sql.mit.edu' (110)")
Internal Server Error: /
Traceback (most recent call last):
  File "/usr/local/lib/python2.7/dist-packages/django/core/handlers/base.py", line 101, in get_response
    request.path_info)
  File "/usr/local/lib/python2.7/dist-packages/django/core/urlresolvers.py", line 300, in resolve
    sub_match = pattern.resolve(new_path)
  File "/usr/local/lib/python2.7/dist-packages/django/core/urlresolvers.py", line 300, in resolve
    sub_match = pattern.resolve(new_path)
  File "/usr/local/lib/python2.7/dist-packages/django/core/urlresolvers.py", line 209, in resolve
    return ResolverMatch(self.callback, args, kwargs, self.name)
  File "/usr/local/lib/python2.7/dist-packages/django/core/urlresolvers.py", line 216, in callback
    self._callback = get_callable(self._callback_str)
  File "/usr/local/lib/python2.7/dist-packages/django/utils/functional.py", line 27, in wrapper
    result = func(*args)
  File "/usr/local/lib/python2.7/dist-packages/django/core/urlresolvers.py", line 92, in get_callable
    lookup_view = getattr(import_module(mod_name), func_name)
  File "/usr/local/lib/python2.7/dist-packages/django/utils/importlib.py", line 35, in import_module
    __import__(name)
  File "/home/max/Documents/projects/comm.prod/commProd/views.py", line 165
    return return HttpResponse(json.dumps({'success':False}), mimetype='application/json')
                ^
SyntaxError: invalid syntax
Internal Server Error: /
Traceback (most recent call last):
  File "/usr/local/lib/python2.7/dist-packages/django/core/handlers/base.py", line 101, in get_response
    request.path_info)
  File "/usr/local/lib/python2.7/dist-packages/django/core/urlresolvers.py", line 300, in resolve
    sub_match = pattern.resolve(new_path)
  File "/usr/local/lib/python2.7/dist-packages/django/core/urlresolvers.py", line 300, in resolve
    sub_match = pattern.resolve(new_path)
  File "/usr/local/lib/python2.7/dist-packages/django/core/urlresolvers.py", line 209, in resolve
    return ResolverMatch(self.callback, args, kwargs, self.name)
  File "/usr/local/lib/python2.7/dist-packages/django/core/urlresolvers.py", line 216, in callback
    self._callback = get_callable(self._callback_str)
  File "/usr/local/lib/python2.7/dist-packages/django/utils/functional.py", line 27, in wrapper
    result = func(*args)
  File "/usr/local/lib/python2.7/dist-packages/django/core/urlresolvers.py", line 92, in get_callable
    lookup_view = getattr(import_module(mod_name), func_name)
  File "/usr/local/lib/python2.7/dist-packages/django/utils/importlib.py", line 35, in import_module
    __import__(name)
  File "/home/max/Documents/projects/comm.prod/commProd/views.py", line 15, in <module>
    from commerical_production.commprod_search import commprod_search
  File "/home/max/Documents/projects/comm.prod/commerical_production/commprod_search.py", line 3
    def commprod_search(cp_id=None, query=None, orderBy='date', direction='hl' username=None, startDate=None, endDate=None ):
                                                                                      ^
SyntaxError: invalid syntax
Internal Server Error: /
Traceback (most recent call last):
  File "/usr/local/lib/python2.7/dist-packages/django/core/handlers/base.py", line 101, in get_response
    request.path_info)
  File "/usr/local/lib/python2.7/dist-packages/django/core/urlresolvers.py", line 300, in resolve
    sub_match = pattern.resolve(new_path)
  File "/usr/local/lib/python2.7/dist-packages/django/core/urlresolvers.py", line 300, in resolve
    sub_match = pattern.resolve(new_path)
  File "/usr/local/lib/python2.7/dist-packages/django/core/urlresolvers.py", line 209, in resolve
    return ResolverMatch(self.callback, args, kwargs, self.name)
  File "/usr/local/lib/python2.7/dist-packages/django/core/urlresolvers.py", line 216, in callback
    self._callback = get_callable(self._callback_str)
  File "/usr/local/lib/python2.7/dist-packages/django/utils/functional.py", line 27, in wrapper
    result = func(*args)
  File "/usr/local/lib/python2.7/dist-packages/django/core/urlresolvers.py", line 92, in get_callable
    lookup_view = getattr(import_module(mod_name), func_name)
  File "/usr/local/lib/python2.7/dist-packages/django/utils/importlib.py", line 35, in import_module
    __import__(name)
  File "/home/max/Documents/projects/comm.prod/commProd/views.py", line 15, in <module>
    from commerical_production.commprod_search import commprod_search
  File "/home/max/Documents/projects/comm.prod/commerical_production/commprod_search.py", line 14
    if direction = 'lh':
                 ^
SyntaxError: invalid syntax
Internal Server Error: /login
Traceback (most recent call last):
  File "/usr/local/lib/python2.7/dist-packages/django/core/handlers/base.py", line 111, in get_response
    response = callback(request, *callback_args, **callback_kwargs)
  File "/usr/local/lib/python2.7/dist-packages/django/views/decorators/debug.py", line 69, in wrapper
    return view(request, *args, **kwargs)
  File "/usr/local/lib/python2.7/dist-packages/django/utils/decorators.py", line 91, in _wrapped_view
    response = view_func(request, *args, **kwargs)
  File "/usr/local/lib/python2.7/dist-packages/django/views/decorators/cache.py", line 89, in _wrapped_view_func
    response = view_func(request, *args, **kwargs)
  File "/usr/local/lib/python2.7/dist-packages/django/contrib/auth/views.py", line 60, in login
    current_site = get_current_site(request)
  File "/usr/local/lib/python2.7/dist-packages/django/contrib/sites/models.py", line 92, in get_current_site
    current_site = Site.objects.get_current()
  File "/usr/local/lib/python2.7/dist-packages/django/contrib/sites/models.py", line 25, in get_current
    current_site = self.get(pk=sid)
  File "/usr/local/lib/python2.7/dist-packages/django/db/models/manager.py", line 131, in get
    return self.get_query_set().get(*args, **kwargs)
  File "/usr/local/lib/python2.7/dist-packages/django/db/models/query.py", line 366, in get
    % self.model._meta.object_name)
DoesNotExist: Site matching query does not exist.
Internal Server Error: /login
Traceback (most recent call last):
  File "/usr/local/lib/python2.7/dist-packages/django/core/handlers/base.py", line 111, in get_response
    response = callback(request, *callback_args, **callback_kwargs)
  File "/usr/local/lib/python2.7/dist-packages/django/views/decorators/debug.py", line 69, in wrapper
    return view(request, *args, **kwargs)
  File "/usr/local/lib/python2.7/dist-packages/django/utils/decorators.py", line 91, in _wrapped_view
    response = view_func(request, *args, **kwargs)
  File "/usr/local/lib/python2.7/dist-packages/django/views/decorators/cache.py", line 89, in _wrapped_view_func
    response = view_func(request, *args, **kwargs)
  File "/usr/local/lib/python2.7/dist-packages/django/contrib/auth/views.py", line 60, in login
    current_site = get_current_site(request)
  File "/usr/local/lib/python2.7/dist-packages/django/contrib/sites/models.py", line 92, in get_current_site
    current_site = Site.objects.get_current()
  File "/usr/local/lib/python2.7/dist-packages/django/contrib/sites/models.py", line 25, in get_current
    current_site = self.get(pk=sid)
  File "/usr/local/lib/python2.7/dist-packages/django/db/models/manager.py", line 131, in get
    return self.get_query_set().get(*args, **kwargs)
  File "/usr/local/lib/python2.7/dist-packages/django/db/models/query.py", line 366, in get
    % self.model._meta.object_name)
DoesNotExist: Site matching query does not exist.
Internal Server Error: /login
Traceback (most recent call last):
  File "/usr/local/lib/python2.7/dist-packages/django/core/handlers/base.py", line 111, in get_response
    response = callback(request, *callback_args, **callback_kwargs)
  File "/usr/local/lib/python2.7/dist-packages/django/views/decorators/debug.py", line 69, in wrapper
    return view(request, *args, **kwargs)
  File "/usr/local/lib/python2.7/dist-packages/django/utils/decorators.py", line 91, in _wrapped_view
    response = view_func(request, *args, **kwargs)
  File "/usr/local/lib/python2.7/dist-packages/django/views/decorators/cache.py", line 89, in _wrapped_view_func
    response = view_func(request, *args, **kwargs)
  File "/usr/local/lib/python2.7/dist-packages/django/contrib/auth/views.py", line 60, in login
    current_site = get_current_site(request)
  File "/usr/local/lib/python2.7/dist-packages/django/contrib/sites/models.py", line 92, in get_current_site
    current_site = Site.objects.get_current()
  File "/usr/local/lib/python2.7/dist-packages/django/contrib/sites/models.py", line 25, in get_current
    current_site = self.get(pk=sid)
  File "/usr/local/lib/python2.7/dist-packages/django/db/models/manager.py", line 131, in get
    return self.get_query_set().get(*args, **kwargs)
  File "/usr/local/lib/python2.7/dist-packages/django/db/models/query.py", line 366, in get
    % self.model._meta.object_name)
DoesNotExist: Site matching query does not exist.
Internal Server Error: /login
Traceback (most recent call last):
  File "/usr/local/lib/python2.7/dist-packages/django/core/handlers/base.py", line 111, in get_response
    response = callback(request, *callback_args, **callback_kwargs)
  File "/usr/local/lib/python2.7/dist-packages/django/views/decorators/debug.py", line 69, in wrapper
    return view(request, *args, **kwargs)
  File "/usr/local/lib/python2.7/dist-packages/django/utils/decorators.py", line 91, in _wrapped_view
    response = view_func(request, *args, **kwargs)
  File "/usr/local/lib/python2.7/dist-packages/django/views/decorators/cache.py", line 89, in _wrapped_view_func
    response = view_func(request, *args, **kwargs)
  File "/usr/local/lib/python2.7/dist-packages/django/contrib/auth/views.py", line 60, in login
    current_site = get_current_site(request)
  File "/usr/local/lib/python2.7/dist-packages/django/contrib/sites/models.py", line 92, in get_current_site
    current_site = Site.objects.get_current()
  File "/usr/local/lib/python2.7/dist-packages/django/contrib/sites/models.py", line 25, in get_current
    current_site = self.get(pk=sid)
  File "/usr/local/lib/python2.7/dist-packages/django/db/models/manager.py", line 131, in get
    return self.get_query_set().get(*args, **kwargs)
  File "/usr/local/lib/python2.7/dist-packages/django/db/models/query.py", line 366, in get
    % self.model._meta.object_name)
DoesNotExist: Site matching query does not exist.
Internal Server Error: /login
Traceback (most recent call last):
  File "/usr/local/lib/python2.7/dist-packages/django/core/handlers/base.py", line 111, in get_response
    response = callback(request, *callback_args, **callback_kwargs)
  File "/usr/local/lib/python2.7/dist-packages/django/views/decorators/debug.py", line 69, in wrapper
    return view(request, *args, **kwargs)
  File "/usr/local/lib/python2.7/dist-packages/django/utils/decorators.py", line 91, in _wrapped_view
    response = view_func(request, *args, **kwargs)
  File "/usr/local/lib/python2.7/dist-packages/django/views/decorators/cache.py", line 89, in _wrapped_view_func
    response = view_func(request, *args, **kwargs)
  File "/usr/local/lib/python2.7/dist-packages/django/contrib/auth/views.py", line 60, in login
    current_site = get_current_site(request)
  File "/usr/local/lib/python2.7/dist-packages/django/contrib/sites/models.py", line 92, in get_current_site
    current_site = Site.objects.get_current()
  File "/usr/local/lib/python2.7/dist-packages/django/contrib/sites/models.py", line 25, in get_current
    current_site = self.get(pk=sid)
  File "/usr/local/lib/python2.7/dist-packages/django/db/models/manager.py", line 131, in get
    return self.get_query_set().get(*args, **kwargs)
  File "/usr/local/lib/python2.7/dist-packages/django/db/models/query.py", line 366, in get
    % self.model._meta.object_name)
DoesNotExist: Site matching query does not exist.
Internal Server Error: /admin
Traceback (most recent call last):
  File "/usr/local/lib/python2.7/dist-packages/django/core/handlers/base.py", line 111, in get_response
    response = callback(request, *callback_args, **callback_kwargs)
  File "/usr/local/lib/python2.7/dist-packages/django/contrib/admin/sites.py", line 213, in wrapper
    return self.admin_view(view, cacheable)(*args, **kwargs)
  File "/usr/local/lib/python2.7/dist-packages/django/utils/decorators.py", line 91, in _wrapped_view
    response = view_func(request, *args, **kwargs)
  File "/usr/local/lib/python2.7/dist-packages/django/views/decorators/cache.py", line 89, in _wrapped_view_func
    response = view_func(request, *args, **kwargs)
  File "/usr/local/lib/python2.7/dist-packages/django/contrib/admin/sites.py", line 195, in inner
    return self.login(request)
  File "/usr/local/lib/python2.7/dist-packages/django/views/decorators/cache.py", line 89, in _wrapped_view_func
    response = view_func(request, *args, **kwargs)
  File "/usr/local/lib/python2.7/dist-packages/django/contrib/admin/sites.py", line 326, in login
    return login(request, **defaults)
  File "/usr/local/lib/python2.7/dist-packages/django/views/decorators/debug.py", line 69, in wrapper
    return view(request, *args, **kwargs)
  File "/usr/local/lib/python2.7/dist-packages/django/utils/decorators.py", line 91, in _wrapped_view
    response = view_func(request, *args, **kwargs)
  File "/usr/local/lib/python2.7/dist-packages/django/views/decorators/cache.py", line 89, in _wrapped_view_func
    response = view_func(request, *args, **kwargs)
  File "/usr/local/lib/python2.7/dist-packages/django/contrib/auth/views.py", line 60, in login
    current_site = get_current_site(request)
  File "/usr/local/lib/python2.7/dist-packages/django/contrib/sites/models.py", line 92, in get_current_site
    current_site = Site.objects.get_current()
  File "/usr/local/lib/python2.7/dist-packages/django/contrib/sites/models.py", line 25, in get_current
    current_site = self.get(pk=sid)
  File "/usr/local/lib/python2.7/dist-packages/django/db/models/manager.py", line 131, in get
    return self.get_query_set().get(*args, **kwargs)
  File "/usr/local/lib/python2.7/dist-packages/django/db/models/query.py", line 366, in get
    % self.model._meta.object_name)
DoesNotExist: Site matching query does not exist.
