Internal Server Error: /processprod
Traceback (most recent call last):
  File "/Library/Frameworks/Python.framework/Versions/2.7/lib/python2.7/site-packages/django/core/handlers/base.py", line 89, in get_response
    response = middleware_method(request)
  File "/Library/Frameworks/Python.framework/Versions/2.7/lib/python2.7/site-packages/django/middleware/common.py", line 67, in process_request
    if (not urlresolvers.is_valid_path(request.path_info, urlconf) and
  File "/Library/Frameworks/Python.framework/Versions/2.7/lib/python2.7/site-packages/django/core/urlresolvers.py", line 531, in is_valid_path
    resolve(path, urlconf)
  File "/Library/Frameworks/Python.framework/Versions/2.7/lib/python2.7/site-packages/django/core/urlresolvers.py", line 420, in resolve
    return get_resolver(urlconf).resolve(path)
  File "/Library/Frameworks/Python.framework/Versions/2.7/lib/python2.7/site-packages/django/core/urlresolvers.py", line 298, in resolve
    for pattern in self.url_patterns:
  File "/Library/Frameworks/Python.framework/Versions/2.7/lib/python2.7/site-packages/django/core/urlresolvers.py", line 328, in url_patterns
    patterns = getattr(self.urlconf_module, "urlpatterns", self.urlconf_module)
  File "/Library/Frameworks/Python.framework/Versions/2.7/lib/python2.7/site-packages/django/core/urlresolvers.py", line 323, in urlconf_module
    self._urlconf_module = import_module(self.urlconf_name)
  File "/Library/Frameworks/Python.framework/Versions/2.7/lib/python2.7/site-packages/django/utils/importlib.py", line 35, in import_module
    __import__(name)
  File "/Users/joshblum/Desktop/Dropbox/code/comm.prod/commerical_production/urls.py", line 15, in <module>
    url(r'', include('commProd.urls')),
  File "/Library/Frameworks/Python.framework/Versions/2.7/lib/python2.7/site-packages/django/conf/urls/__init__.py", line 24, in include
    urlconf_module = import_module(urlconf_module)
  File "/Library/Frameworks/Python.framework/Versions/2.7/lib/python2.7/site-packages/django/utils/importlib.py", line 35, in import_module
    __import__(name)
  File "/Users/joshblum/Desktop/Dropbox/code/comm.prod/commProd/urls.py", line 10
    url(r'^$', 'home')
      ^
SyntaxError: invalid syntax
Internal Server Error: /processprod
Traceback (most recent call last):
  File "/Library/Frameworks/Python.framework/Versions/2.7/lib/python2.7/site-packages/django/core/handlers/base.py", line 111, in get_response
    response = callback(request, *callback_args, **callback_kwargs)
  File "/Library/Frameworks/Python.framework/Versions/2.7/lib/python2.7/site-packages/django/views/decorators/csrf.py", line 77, in wrapped_view
    return view_func(*args, **kwargs)
  File "/Users/joshblum/Desktop/Dropbox/code/comm.prod/commProd/views.py", line 192, in processProd
    user, created = createUser(sender, sender, False)
  File "/Users/joshblum/Desktop/Dropbox/code/comm.prod/commerical_production/create_users.py", line 45, in createUser
    user, created = User.objects.get_or_create(username=username, email=email)
  File "/Library/Frameworks/Python.framework/Versions/2.7/lib/python2.7/site-packages/django/db/models/manager.py", line 134, in get_or_create
    return self.get_query_set().get_or_create(**kwargs)
  File "/Library/Frameworks/Python.framework/Versions/2.7/lib/python2.7/site-packages/django/db/models/query.py", line 449, in get_or_create
    obj.save(force_insert=True, using=self.db)
  File "/Library/Frameworks/Python.framework/Versions/2.7/lib/python2.7/site-packages/django/db/models/base.py", line 463, in save
    self.save_base(using=using, force_insert=force_insert, force_update=force_update)
  File "/Library/Frameworks/Python.framework/Versions/2.7/lib/python2.7/site-packages/django/db/models/base.py", line 565, in save_base
    created=(not record_exists), raw=raw, using=using)
  File "/Library/Frameworks/Python.framework/Versions/2.7/lib/python2.7/site-packages/django/dispatch/dispatcher.py", line 172, in send
    response = receiver(signal=self, sender=sender, **named)
  File "/Users/joshblum/Desktop/Dropbox/code/comm.prod/commProd/models.py", line 57, in create_user_profile
    profile, created = UserProfile.objects.get_or_create(user=instance)
  File "/Library/Frameworks/Python.framework/Versions/2.7/lib/python2.7/site-packages/django/db/models/manager.py", line 134, in get_or_create
    return self.get_query_set().get_or_create(**kwargs)
  File "/Library/Frameworks/Python.framework/Versions/2.7/lib/python2.7/site-packages/django/db/models/query.py", line 442, in get_or_create
    return self.get(**lookup), False
  File "/Library/Frameworks/Python.framework/Versions/2.7/lib/python2.7/site-packages/django/db/models/query.py", line 361, in get
    num = len(clone)
  File "/Library/Frameworks/Python.framework/Versions/2.7/lib/python2.7/site-packages/django/db/models/query.py", line 85, in __len__
    self._result_cache = list(self.iterator())
  File "/Library/Frameworks/Python.framework/Versions/2.7/lib/python2.7/site-packages/django/db/models/query.py", line 291, in iterator
    for row in compiler.results_iter():
  File "/Library/Frameworks/Python.framework/Versions/2.7/lib/python2.7/site-packages/django/db/models/sql/compiler.py", line 763, in results_iter
    for rows in self.execute_sql(MULTI):
  File "/Library/Frameworks/Python.framework/Versions/2.7/lib/python2.7/site-packages/django/db/models/sql/compiler.py", line 818, in execute_sql
    cursor.execute(sql, params)
  File "/Library/Frameworks/Python.framework/Versions/2.7/lib/python2.7/site-packages/django/db/backends/util.py", line 40, in execute
    return self.cursor.execute(sql, params)
  File "/Library/Frameworks/Python.framework/Versions/2.7/lib/python2.7/site-packages/django/db/backends/mysql/base.py", line 114, in execute
    return self.cursor.execute(query, args)
  File "/Users/joshblum/Library/Python/2.7/lib/python/site-packages/MySQLdb/cursors.py", line 174, in execute
    self.errorhandler(self, exc, value)
  File "/Users/joshblum/Library/Python/2.7/lib/python/site-packages/MySQLdb/connections.py", line 36, in defaulterrorhandler
    raise errorclass, errorvalue
DatabaseError: (1054, "Unknown column 'commProd_userprofile.send_mail' in 'field list'")
Internal Server Error: /
Traceback (most recent call last):
  File "/Library/Frameworks/Python.framework/Versions/2.7/lib/python2.7/site-packages/django/core/handlers/base.py", line 101, in get_response
    request.path_info)
  File "/Library/Frameworks/Python.framework/Versions/2.7/lib/python2.7/site-packages/django/core/urlresolvers.py", line 300, in resolve
    sub_match = pattern.resolve(new_path)
  File "/Library/Frameworks/Python.framework/Versions/2.7/lib/python2.7/site-packages/django/core/urlresolvers.py", line 300, in resolve
    sub_match = pattern.resolve(new_path)
  File "/Library/Frameworks/Python.framework/Versions/2.7/lib/python2.7/site-packages/django/core/urlresolvers.py", line 209, in resolve
    return ResolverMatch(self.callback, args, kwargs, self.name)
  File "/Library/Frameworks/Python.framework/Versions/2.7/lib/python2.7/site-packages/django/core/urlresolvers.py", line 216, in callback
    self._callback = get_callable(self._callback_str)
  File "/Library/Frameworks/Python.framework/Versions/2.7/lib/python2.7/site-packages/django/utils/functional.py", line 27, in wrapper
    result = func(*args)
  File "/Library/Frameworks/Python.framework/Versions/2.7/lib/python2.7/site-packages/django/core/urlresolvers.py", line 92, in get_callable
    lookup_view = getattr(import_module(mod_name), func_name)
  File "/Library/Frameworks/Python.framework/Versions/2.7/lib/python2.7/site-packages/django/utils/importlib.py", line 35, in import_module
    __import__(name)
  File "/Users/joshblum/Desktop/Dropbox/code/comm.prod/commProd/views.py", line 15, in <module>
    from commerical_production.commprod_search import commprod_search
ImportError: No module named commprod_search
Internal Server Error: /
Traceback (most recent call last):
  File "/Library/Frameworks/Python.framework/Versions/2.7/lib/python2.7/site-packages/django/core/handlers/base.py", line 101, in get_response
    request.path_info)
  File "/Library/Frameworks/Python.framework/Versions/2.7/lib/python2.7/site-packages/django/core/urlresolvers.py", line 300, in resolve
    sub_match = pattern.resolve(new_path)
  File "/Library/Frameworks/Python.framework/Versions/2.7/lib/python2.7/site-packages/django/core/urlresolvers.py", line 300, in resolve
    sub_match = pattern.resolve(new_path)
  File "/Library/Frameworks/Python.framework/Versions/2.7/lib/python2.7/site-packages/django/core/urlresolvers.py", line 209, in resolve
    return ResolverMatch(self.callback, args, kwargs, self.name)
  File "/Library/Frameworks/Python.framework/Versions/2.7/lib/python2.7/site-packages/django/core/urlresolvers.py", line 216, in callback
    self._callback = get_callable(self._callback_str)
  File "/Library/Frameworks/Python.framework/Versions/2.7/lib/python2.7/site-packages/django/utils/functional.py", line 27, in wrapper
    result = func(*args)
  File "/Library/Frameworks/Python.framework/Versions/2.7/lib/python2.7/site-packages/django/core/urlresolvers.py", line 92, in get_callable
    lookup_view = getattr(import_module(mod_name), func_name)
  File "/Library/Frameworks/Python.framework/Versions/2.7/lib/python2.7/site-packages/django/utils/importlib.py", line 35, in import_module
    __import__(name)
  File "/Users/joshblum/Desktop/Dropbox/code/comm.prod/commProd/views.py", line 16, in <module>
    from helpers.view_helpers import getRandomUsername, renderErrorMessage
ImportError: No module named helpers.view_helpers
Internal Server Error: /
Traceback (most recent call last):
  File "/Library/Frameworks/Python.framework/Versions/2.7/lib/python2.7/site-packages/django/core/handlers/base.py", line 101, in get_response
    request.path_info)
  File "/Library/Frameworks/Python.framework/Versions/2.7/lib/python2.7/site-packages/django/core/urlresolvers.py", line 300, in resolve
    sub_match = pattern.resolve(new_path)
  File "/Library/Frameworks/Python.framework/Versions/2.7/lib/python2.7/site-packages/django/core/urlresolvers.py", line 300, in resolve
    sub_match = pattern.resolve(new_path)
  File "/Library/Frameworks/Python.framework/Versions/2.7/lib/python2.7/site-packages/django/core/urlresolvers.py", line 209, in resolve
    return ResolverMatch(self.callback, args, kwargs, self.name)
  File "/Library/Frameworks/Python.framework/Versions/2.7/lib/python2.7/site-packages/django/core/urlresolvers.py", line 216, in callback
    self._callback = get_callable(self._callback_str)
  File "/Library/Frameworks/Python.framework/Versions/2.7/lib/python2.7/site-packages/django/utils/functional.py", line 27, in wrapper
    result = func(*args)
  File "/Library/Frameworks/Python.framework/Versions/2.7/lib/python2.7/site-packages/django/core/urlresolvers.py", line 92, in get_callable
    lookup_view = getattr(import_module(mod_name), func_name)
  File "/Library/Frameworks/Python.framework/Versions/2.7/lib/python2.7/site-packages/django/utils/importlib.py", line 35, in import_module
    __import__(name)
  File "/Users/joshblum/Desktop/Dropbox/code/comm.prod/commProd/views.py", line 17, in <module>
    from helpers.commprod_search import commprod_search
ImportError: No module named helpers.commprod_search
Internal Server Error: /
Traceback (most recent call last):
  File "/Library/Frameworks/Python.framework/Versions/2.7/lib/python2.7/site-packages/django/core/handlers/base.py", line 101, in get_response
    request.path_info)
  File "/Library/Frameworks/Python.framework/Versions/2.7/lib/python2.7/site-packages/django/core/urlresolvers.py", line 300, in resolve
    sub_match = pattern.resolve(new_path)
  File "/Library/Frameworks/Python.framework/Versions/2.7/lib/python2.7/site-packages/django/core/urlresolvers.py", line 300, in resolve
    sub_match = pattern.resolve(new_path)
  File "/Library/Frameworks/Python.framework/Versions/2.7/lib/python2.7/site-packages/django/core/urlresolvers.py", line 209, in resolve
    return ResolverMatch(self.callback, args, kwargs, self.name)
  File "/Library/Frameworks/Python.framework/Versions/2.7/lib/python2.7/site-packages/django/core/urlresolvers.py", line 216, in callback
    self._callback = get_callable(self._callback_str)
  File "/Library/Frameworks/Python.framework/Versions/2.7/lib/python2.7/site-packages/django/utils/functional.py", line 27, in wrapper
    result = func(*args)
  File "/Library/Frameworks/Python.framework/Versions/2.7/lib/python2.7/site-packages/django/core/urlresolvers.py", line 92, in get_callable
    lookup_view = getattr(import_module(mod_name), func_name)
  File "/Library/Frameworks/Python.framework/Versions/2.7/lib/python2.7/site-packages/django/utils/importlib.py", line 35, in import_module
    __import__(name)
  File "/Users/joshblum/Desktop/Dropbox/code/comm.prod/commProd/views.py", line 16, in <module>
    from helpers.view_helpers import getRandomUsername, renderErrorMessage
ImportError: No module named helpers.view_helpers
Internal Server Error: /
Traceback (most recent call last):
  File "/Library/Frameworks/Python.framework/Versions/2.7/lib/python2.7/site-packages/django/core/handlers/base.py", line 101, in get_response
    request.path_info)
  File "/Library/Frameworks/Python.framework/Versions/2.7/lib/python2.7/site-packages/django/core/urlresolvers.py", line 300, in resolve
    sub_match = pattern.resolve(new_path)
  File "/Library/Frameworks/Python.framework/Versions/2.7/lib/python2.7/site-packages/django/core/urlresolvers.py", line 300, in resolve
    sub_match = pattern.resolve(new_path)
  File "/Library/Frameworks/Python.framework/Versions/2.7/lib/python2.7/site-packages/django/core/urlresolvers.py", line 209, in resolve
    return ResolverMatch(self.callback, args, kwargs, self.name)
  File "/Library/Frameworks/Python.framework/Versions/2.7/lib/python2.7/site-packages/django/core/urlresolvers.py", line 216, in callback
    self._callback = get_callable(self._callback_str)
  File "/Library/Frameworks/Python.framework/Versions/2.7/lib/python2.7/site-packages/django/utils/functional.py", line 27, in wrapper
    result = func(*args)
  File "/Library/Frameworks/Python.framework/Versions/2.7/lib/python2.7/site-packages/django/core/urlresolvers.py", line 92, in get_callable
    lookup_view = getattr(import_module(mod_name), func_name)
  File "/Library/Frameworks/Python.framework/Versions/2.7/lib/python2.7/site-packages/django/utils/importlib.py", line 35, in import_module
    __import__(name)
  File "/Users/joshblum/Desktop/Dropbox/code/comm.prod/commProd/views.py", line 16, in <module>
    from commerical_production.helpers.view_helpers import getRandomUsername, renderErrorMessage
ImportError: No module named helpers.view_helpers
Internal Server Error: /
Traceback (most recent call last):
  File "/Library/Frameworks/Python.framework/Versions/2.7/lib/python2.7/site-packages/django/core/handlers/base.py", line 101, in get_response
    request.path_info)
  File "/Library/Frameworks/Python.framework/Versions/2.7/lib/python2.7/site-packages/django/core/urlresolvers.py", line 300, in resolve
    sub_match = pattern.resolve(new_path)
  File "/Library/Frameworks/Python.framework/Versions/2.7/lib/python2.7/site-packages/django/core/urlresolvers.py", line 300, in resolve
    sub_match = pattern.resolve(new_path)
  File "/Library/Frameworks/Python.framework/Versions/2.7/lib/python2.7/site-packages/django/core/urlresolvers.py", line 209, in resolve
    return ResolverMatch(self.callback, args, kwargs, self.name)
  File "/Library/Frameworks/Python.framework/Versions/2.7/lib/python2.7/site-packages/django/core/urlresolvers.py", line 216, in callback
    self._callback = get_callable(self._callback_str)
  File "/Library/Frameworks/Python.framework/Versions/2.7/lib/python2.7/site-packages/django/utils/functional.py", line 27, in wrapper
    result = func(*args)
  File "/Library/Frameworks/Python.framework/Versions/2.7/lib/python2.7/site-packages/django/core/urlresolvers.py", line 92, in get_callable
    lookup_view = getattr(import_module(mod_name), func_name)
  File "/Library/Frameworks/Python.framework/Versions/2.7/lib/python2.7/site-packages/django/utils/importlib.py", line 35, in import_module
    __import__(name)
  File "/Users/joshblum/Desktop/Dropbox/code/comm.prod/commProd/views.py", line 16, in <module>
    from commerical_production.helpers.view_helpers import getRandomUsername, renderErrorMessage
ImportError: No module named helpers.view_helpers
Internal Server Error: /
Traceback (most recent call last):
  File "/Library/Frameworks/Python.framework/Versions/2.7/lib/python2.7/site-packages/django/core/handlers/base.py", line 101, in get_response
    request.path_info)
  File "/Library/Frameworks/Python.framework/Versions/2.7/lib/python2.7/site-packages/django/core/urlresolvers.py", line 300, in resolve
    sub_match = pattern.resolve(new_path)
  File "/Library/Frameworks/Python.framework/Versions/2.7/lib/python2.7/site-packages/django/core/urlresolvers.py", line 300, in resolve
    sub_match = pattern.resolve(new_path)
  File "/Library/Frameworks/Python.framework/Versions/2.7/lib/python2.7/site-packages/django/core/urlresolvers.py", line 209, in resolve
    return ResolverMatch(self.callback, args, kwargs, self.name)
  File "/Library/Frameworks/Python.framework/Versions/2.7/lib/python2.7/site-packages/django/core/urlresolvers.py", line 216, in callback
    self._callback = get_callable(self._callback_str)
  File "/Library/Frameworks/Python.framework/Versions/2.7/lib/python2.7/site-packages/django/utils/functional.py", line 27, in wrapper
    result = func(*args)
  File "/Library/Frameworks/Python.framework/Versions/2.7/lib/python2.7/site-packages/django/core/urlresolvers.py", line 92, in get_callable
    lookup_view = getattr(import_module(mod_name), func_name)
  File "/Library/Frameworks/Python.framework/Versions/2.7/lib/python2.7/site-packages/django/utils/importlib.py", line 35, in import_module
    __import__(name)
  File "/Users/joshblum/Desktop/Dropbox/code/comm.prod/commProd/views.py", line 16, in <module>
    from commerical_production.helpers.view_helpers import getRandomUsername, renderErrorMessage
ImportError: No module named helpers.view_helpers
Internal Server Error: /
Traceback (most recent call last):
  File "/Library/Frameworks/Python.framework/Versions/2.7/lib/python2.7/site-packages/django/core/handlers/base.py", line 101, in get_response
    request.path_info)
  File "/Library/Frameworks/Python.framework/Versions/2.7/lib/python2.7/site-packages/django/core/urlresolvers.py", line 300, in resolve
    sub_match = pattern.resolve(new_path)
  File "/Library/Frameworks/Python.framework/Versions/2.7/lib/python2.7/site-packages/django/core/urlresolvers.py", line 300, in resolve
    sub_match = pattern.resolve(new_path)
  File "/Library/Frameworks/Python.framework/Versions/2.7/lib/python2.7/site-packages/django/core/urlresolvers.py", line 209, in resolve
    return ResolverMatch(self.callback, args, kwargs, self.name)
  File "/Library/Frameworks/Python.framework/Versions/2.7/lib/python2.7/site-packages/django/core/urlresolvers.py", line 216, in callback
    self._callback = get_callable(self._callback_str)
  File "/Library/Frameworks/Python.framework/Versions/2.7/lib/python2.7/site-packages/django/utils/functional.py", line 27, in wrapper
    result = func(*args)
  File "/Library/Frameworks/Python.framework/Versions/2.7/lib/python2.7/site-packages/django/core/urlresolvers.py", line 92, in get_callable
    lookup_view = getattr(import_module(mod_name), func_name)
  File "/Library/Frameworks/Python.framework/Versions/2.7/lib/python2.7/site-packages/django/utils/importlib.py", line 35, in import_module
    __import__(name)
  File "/Users/joshblum/Desktop/Dropbox/code/comm.prod/commProd/views.py", line 16, in <module>
    from commerical_production.helpers import * #.view_helpers import getRandomUsername, renderErrorMessage
ImportError: No module named helpers
Internal Server Error: /
Traceback (most recent call last):
  File "/Library/Frameworks/Python.framework/Versions/2.7/lib/python2.7/site-packages/django/core/handlers/base.py", line 101, in get_response
    request.path_info)
  File "/Library/Frameworks/Python.framework/Versions/2.7/lib/python2.7/site-packages/django/core/urlresolvers.py", line 300, in resolve
    sub_match = pattern.resolve(new_path)
  File "/Library/Frameworks/Python.framework/Versions/2.7/lib/python2.7/site-packages/django/core/urlresolvers.py", line 300, in resolve
    sub_match = pattern.resolve(new_path)
  File "/Library/Frameworks/Python.framework/Versions/2.7/lib/python2.7/site-packages/django/core/urlresolvers.py", line 209, in resolve
    return ResolverMatch(self.callback, args, kwargs, self.name)
  File "/Library/Frameworks/Python.framework/Versions/2.7/lib/python2.7/site-packages/django/core/urlresolvers.py", line 216, in callback
    self._callback = get_callable(self._callback_str)
  File "/Library/Frameworks/Python.framework/Versions/2.7/lib/python2.7/site-packages/django/utils/functional.py", line 27, in wrapper
    result = func(*args)
  File "/Library/Frameworks/Python.framework/Versions/2.7/lib/python2.7/site-packages/django/core/urlresolvers.py", line 92, in get_callable
    lookup_view = getattr(import_module(mod_name), func_name)
  File "/Library/Frameworks/Python.framework/Versions/2.7/lib/python2.7/site-packages/django/utils/importlib.py", line 35, in import_module
    __import__(name)
  File "/Users/joshblum/Desktop/Dropbox/code/comm.prod/commProd/views.py", line 16, in <module>
    from helpers import * #.view_helpers import getRandomUsername, renderErrorMessage
ImportError: No module named helpers
Internal Server Error: /
Traceback (most recent call last):
  File "/Library/Frameworks/Python.framework/Versions/2.7/lib/python2.7/site-packages/django/core/handlers/base.py", line 101, in get_response
    request.path_info)
  File "/Library/Frameworks/Python.framework/Versions/2.7/lib/python2.7/site-packages/django/core/urlresolvers.py", line 300, in resolve
    sub_match = pattern.resolve(new_path)
  File "/Library/Frameworks/Python.framework/Versions/2.7/lib/python2.7/site-packages/django/core/urlresolvers.py", line 300, in resolve
    sub_match = pattern.resolve(new_path)
  File "/Library/Frameworks/Python.framework/Versions/2.7/lib/python2.7/site-packages/django/core/urlresolvers.py", line 209, in resolve
    return ResolverMatch(self.callback, args, kwargs, self.name)
  File "/Library/Frameworks/Python.framework/Versions/2.7/lib/python2.7/site-packages/django/core/urlresolvers.py", line 216, in callback
    self._callback = get_callable(self._callback_str)
  File "/Library/Frameworks/Python.framework/Versions/2.7/lib/python2.7/site-packages/django/utils/functional.py", line 27, in wrapper
    result = func(*args)
  File "/Library/Frameworks/Python.framework/Versions/2.7/lib/python2.7/site-packages/django/core/urlresolvers.py", line 92, in get_callable
    lookup_view = getattr(import_module(mod_name), func_name)
  File "/Library/Frameworks/Python.framework/Versions/2.7/lib/python2.7/site-packages/django/utils/importlib.py", line 35, in import_module
    __import__(name)
  File "/Users/joshblum/Desktop/Dropbox/code/comm.prod/commProd/views.py", line 16, in <module>
    from helpers import * #.view_helpers import getRandomUsername, renderErrorMessage
ImportError: No module named helpers
Internal Server Error: /
Traceback (most recent call last):
  File "/Library/Frameworks/Python.framework/Versions/2.7/lib/python2.7/site-packages/django/core/handlers/base.py", line 101, in get_response
    request.path_info)
  File "/Library/Frameworks/Python.framework/Versions/2.7/lib/python2.7/site-packages/django/core/urlresolvers.py", line 300, in resolve
    sub_match = pattern.resolve(new_path)
  File "/Library/Frameworks/Python.framework/Versions/2.7/lib/python2.7/site-packages/django/core/urlresolvers.py", line 300, in resolve
    sub_match = pattern.resolve(new_path)
  File "/Library/Frameworks/Python.framework/Versions/2.7/lib/python2.7/site-packages/django/core/urlresolvers.py", line 209, in resolve
    return ResolverMatch(self.callback, args, kwargs, self.name)
  File "/Library/Frameworks/Python.framework/Versions/2.7/lib/python2.7/site-packages/django/core/urlresolvers.py", line 216, in callback
    self._callback = get_callable(self._callback_str)
  File "/Library/Frameworks/Python.framework/Versions/2.7/lib/python2.7/site-packages/django/utils/functional.py", line 27, in wrapper
    result = func(*args)
  File "/Library/Frameworks/Python.framework/Versions/2.7/lib/python2.7/site-packages/django/core/urlresolvers.py", line 92, in get_callable
    lookup_view = getattr(import_module(mod_name), func_name)
  File "/Library/Frameworks/Python.framework/Versions/2.7/lib/python2.7/site-packages/django/utils/importlib.py", line 35, in import_module
    __import__(name)
  File "/Users/joshblum/Desktop/Dropbox/code/comm.prod/commProd/views.py", line 16, in <module>
    from commProd.helpers import * #.view_helpers import getRandomUsername, renderErrorMessage
ImportError: No module named helpers
Internal Server Error: /
Traceback (most recent call last):
  File "/Library/Frameworks/Python.framework/Versions/2.7/lib/python2.7/site-packages/django/core/handlers/base.py", line 101, in get_response
    request.path_info)
  File "/Library/Frameworks/Python.framework/Versions/2.7/lib/python2.7/site-packages/django/core/urlresolvers.py", line 300, in resolve
    sub_match = pattern.resolve(new_path)
  File "/Library/Frameworks/Python.framework/Versions/2.7/lib/python2.7/site-packages/django/core/urlresolvers.py", line 300, in resolve
    sub_match = pattern.resolve(new_path)
  File "/Library/Frameworks/Python.framework/Versions/2.7/lib/python2.7/site-packages/django/core/urlresolvers.py", line 209, in resolve
    return ResolverMatch(self.callback, args, kwargs, self.name)
  File "/Library/Frameworks/Python.framework/Versions/2.7/lib/python2.7/site-packages/django/core/urlresolvers.py", line 216, in callback
    self._callback = get_callable(self._callback_str)
  File "/Library/Frameworks/Python.framework/Versions/2.7/lib/python2.7/site-packages/django/utils/functional.py", line 27, in wrapper
    result = func(*args)
  File "/Library/Frameworks/Python.framework/Versions/2.7/lib/python2.7/site-packages/django/core/urlresolvers.py", line 92, in get_callable
    lookup_view = getattr(import_module(mod_name), func_name)
  File "/Library/Frameworks/Python.framework/Versions/2.7/lib/python2.7/site-packages/django/utils/importlib.py", line 35, in import_module
    __import__(name)
  File "/Users/joshblum/Desktop/Dropbox/code/comm.prod/commProd/views.py", line 16, in <module>
    from commProd.helpers import * #.view_helpers import getRandomUsername, renderErrorMessage
ImportError: No module named helpers
Internal Server Error: /
Traceback (most recent call last):
  File "/Library/Frameworks/Python.framework/Versions/2.7/lib/python2.7/site-packages/django/core/handlers/base.py", line 101, in get_response
    request.path_info)
  File "/Library/Frameworks/Python.framework/Versions/2.7/lib/python2.7/site-packages/django/core/urlresolvers.py", line 300, in resolve
    sub_match = pattern.resolve(new_path)
  File "/Library/Frameworks/Python.framework/Versions/2.7/lib/python2.7/site-packages/django/core/urlresolvers.py", line 300, in resolve
    sub_match = pattern.resolve(new_path)
  File "/Library/Frameworks/Python.framework/Versions/2.7/lib/python2.7/site-packages/django/core/urlresolvers.py", line 209, in resolve
    return ResolverMatch(self.callback, args, kwargs, self.name)
  File "/Library/Frameworks/Python.framework/Versions/2.7/lib/python2.7/site-packages/django/core/urlresolvers.py", line 216, in callback
    self._callback = get_callable(self._callback_str)
  File "/Library/Frameworks/Python.framework/Versions/2.7/lib/python2.7/site-packages/django/utils/functional.py", line 27, in wrapper
    result = func(*args)
  File "/Library/Frameworks/Python.framework/Versions/2.7/lib/python2.7/site-packages/django/core/urlresolvers.py", line 92, in get_callable
    lookup_view = getattr(import_module(mod_name), func_name)
  File "/Library/Frameworks/Python.framework/Versions/2.7/lib/python2.7/site-packages/django/utils/importlib.py", line 35, in import_module
    __import__(name)
  File "/Users/joshblum/Desktop/Dropbox/code/comm.prod/commProd/views.py", line 17, in <module>
    from commerical_production.helpers.commprod_search import commprod_search
ImportError: No module named helpers.commprod_search
Internal Server Error: /
Traceback (most recent call last):
  File "/Library/Frameworks/Python.framework/Versions/2.7/lib/python2.7/site-packages/django/core/handlers/base.py", line 101, in get_response
    request.path_info)
  File "/Library/Frameworks/Python.framework/Versions/2.7/lib/python2.7/site-packages/django/core/urlresolvers.py", line 300, in resolve
    sub_match = pattern.resolve(new_path)
  File "/Library/Frameworks/Python.framework/Versions/2.7/lib/python2.7/site-packages/django/core/urlresolvers.py", line 300, in resolve
    sub_match = pattern.resolve(new_path)
  File "/Library/Frameworks/Python.framework/Versions/2.7/lib/python2.7/site-packages/django/core/urlresolvers.py", line 209, in resolve
    return ResolverMatch(self.callback, args, kwargs, self.name)
  File "/Library/Frameworks/Python.framework/Versions/2.7/lib/python2.7/site-packages/django/core/urlresolvers.py", line 216, in callback
    self._callback = get_callable(self._callback_str)
  File "/Library/Frameworks/Python.framework/Versions/2.7/lib/python2.7/site-packages/django/utils/functional.py", line 27, in wrapper
    result = func(*args)
  File "/Library/Frameworks/Python.framework/Versions/2.7/lib/python2.7/site-packages/django/core/urlresolvers.py", line 92, in get_callable
    lookup_view = getattr(import_module(mod_name), func_name)
  File "/Library/Frameworks/Python.framework/Versions/2.7/lib/python2.7/site-packages/django/utils/importlib.py", line 35, in import_module
    __import__(name)
  File "/Users/joshblum/Desktop/Dropbox/code/comm.prod/commProd/views.py", line 18, in <module>
    from helpers.admin.utils import createUser
  File "/Users/joshblum/Desktop/Dropbox/code/comm.prod/helpers/admin/utils.py", line 6, in <module>
    from commerical_production.email_templates import registration
ImportError: No module named email_templates
Internal Server Error: /admincommProd/rating/add/
Traceback (most recent call last):
  File "/Library/Frameworks/Python.framework/Versions/2.7/lib/python2.7/site-packages/django/core/handlers/base.py", line 111, in get_response
    response = callback(request, *callback_args, **callback_kwargs)
  File "/Library/Frameworks/Python.framework/Versions/2.7/lib/python2.7/site-packages/django/contrib/admin/options.py", line 366, in wrapper
    return self.admin_site.admin_view(view)(*args, **kwargs)
  File "/Library/Frameworks/Python.framework/Versions/2.7/lib/python2.7/site-packages/django/utils/decorators.py", line 91, in _wrapped_view
    response = view_func(request, *args, **kwargs)
  File "/Library/Frameworks/Python.framework/Versions/2.7/lib/python2.7/site-packages/django/views/decorators/cache.py", line 89, in _wrapped_view_func
    response = view_func(request, *args, **kwargs)
  File "/Library/Frameworks/Python.framework/Versions/2.7/lib/python2.7/site-packages/django/contrib/admin/sites.py", line 196, in inner
    return view(request, *args, **kwargs)
  File "/Library/Frameworks/Python.framework/Versions/2.7/lib/python2.7/site-packages/django/utils/decorators.py", line 25, in _wrapper
    return bound_func(*args, **kwargs)
  File "/Library/Frameworks/Python.framework/Versions/2.7/lib/python2.7/site-packages/django/utils/decorators.py", line 91, in _wrapped_view
    response = view_func(request, *args, **kwargs)
  File "/Library/Frameworks/Python.framework/Versions/2.7/lib/python2.7/site-packages/django/utils/decorators.py", line 21, in bound_func
    return func(self, *args2, **kwargs2)
  File "/Library/Frameworks/Python.framework/Versions/2.7/lib/python2.7/site-packages/django/db/transaction.py", line 209, in inner
    return func(*args, **kwargs)
  File "/Library/Frameworks/Python.framework/Versions/2.7/lib/python2.7/site-packages/django/contrib/admin/options.py", line 955, in add_view
    self.save_model(request, new_object, form, False)
  File "/Library/Frameworks/Python.framework/Versions/2.7/lib/python2.7/site-packages/django/contrib/admin/options.py", line 709, in save_model
    obj.save()
  File "/Library/Frameworks/Python.framework/Versions/2.7/lib/python2.7/site-packages/django/db/models/base.py", line 463, in save
    self.save_base(using=using, force_insert=force_insert, force_update=force_update)
  File "/Library/Frameworks/Python.framework/Versions/2.7/lib/python2.7/site-packages/django/db/models/base.py", line 565, in save_base
    created=(not record_exists), raw=raw, using=using)
  File "/Library/Frameworks/Python.framework/Versions/2.7/lib/python2.7/site-packages/django/dispatch/dispatcher.py", line 172, in send
    response = receiver(signal=self, sender=sender, **named)
  File "/Users/joshblum/Desktop/Dropbox/code/comm.prod/commProd/signals.py", line 11, in post_save_ratings
    instance.commprod.update_avg()
  File "/Users/joshblum/Desktop/Dropbox/code/comm.prod/commProd/models.py", line 55, in update_avg
    self.avg_score = Rating.objects.get(commprod=self).aggregate(Avg('score'))
AttributeError: 'Rating' object has no attribute 'aggregate'
Internal Server Error: /admincommProd/rating/add/
Traceback (most recent call last):
  File "/Library/Frameworks/Python.framework/Versions/2.7/lib/python2.7/site-packages/django/core/handlers/base.py", line 111, in get_response
    response = callback(request, *callback_args, **callback_kwargs)
  File "/Library/Frameworks/Python.framework/Versions/2.7/lib/python2.7/site-packages/django/contrib/admin/options.py", line 366, in wrapper
    return self.admin_site.admin_view(view)(*args, **kwargs)
  File "/Library/Frameworks/Python.framework/Versions/2.7/lib/python2.7/site-packages/django/utils/decorators.py", line 91, in _wrapped_view
    response = view_func(request, *args, **kwargs)
  File "/Library/Frameworks/Python.framework/Versions/2.7/lib/python2.7/site-packages/django/views/decorators/cache.py", line 89, in _wrapped_view_func
    response = view_func(request, *args, **kwargs)
  File "/Library/Frameworks/Python.framework/Versions/2.7/lib/python2.7/site-packages/django/contrib/admin/sites.py", line 196, in inner
    return view(request, *args, **kwargs)
  File "/Library/Frameworks/Python.framework/Versions/2.7/lib/python2.7/site-packages/django/utils/decorators.py", line 25, in _wrapper
    return bound_func(*args, **kwargs)
  File "/Library/Frameworks/Python.framework/Versions/2.7/lib/python2.7/site-packages/django/utils/decorators.py", line 91, in _wrapped_view
    response = view_func(request, *args, **kwargs)
  File "/Library/Frameworks/Python.framework/Versions/2.7/lib/python2.7/site-packages/django/utils/decorators.py", line 21, in bound_func
    return func(self, *args2, **kwargs2)
  File "/Library/Frameworks/Python.framework/Versions/2.7/lib/python2.7/site-packages/django/db/transaction.py", line 209, in inner
    return func(*args, **kwargs)
  File "/Library/Frameworks/Python.framework/Versions/2.7/lib/python2.7/site-packages/django/contrib/admin/options.py", line 955, in add_view
    self.save_model(request, new_object, form, False)
  File "/Library/Frameworks/Python.framework/Versions/2.7/lib/python2.7/site-packages/django/contrib/admin/options.py", line 709, in save_model
    obj.save()
  File "/Library/Frameworks/Python.framework/Versions/2.7/lib/python2.7/site-packages/django/db/models/base.py", line 463, in save
    self.save_base(using=using, force_insert=force_insert, force_update=force_update)
  File "/Library/Frameworks/Python.framework/Versions/2.7/lib/python2.7/site-packages/django/db/models/base.py", line 565, in save_base
    created=(not record_exists), raw=raw, using=using)
  File "/Library/Frameworks/Python.framework/Versions/2.7/lib/python2.7/site-packages/django/dispatch/dispatcher.py", line 172, in send
    response = receiver(signal=self, sender=sender, **named)
  File "/Users/joshblum/Desktop/Dropbox/code/comm.prod/commProd/signals.py", line 11, in post_save_ratings
    instance.commprod.update_avg()
  File "/Users/joshblum/Desktop/Dropbox/code/comm.prod/commProd/models.py", line 56, in update_avg
    self.save()
  File "/Library/Frameworks/Python.framework/Versions/2.7/lib/python2.7/site-packages/django/db/models/base.py", line 463, in save
    self.save_base(using=using, force_insert=force_insert, force_update=force_update)
  File "/Library/Frameworks/Python.framework/Versions/2.7/lib/python2.7/site-packages/django/db/models/base.py", line 529, in save_base
    rows = manager.using(using).filter(pk=pk_val)._update(values)
  File "/Library/Frameworks/Python.framework/Versions/2.7/lib/python2.7/site-packages/django/db/models/query.py", line 557, in _update
    return query.get_compiler(self.db).execute_sql(None)
  File "/Library/Frameworks/Python.framework/Versions/2.7/lib/python2.7/site-packages/django/db/models/sql/compiler.py", line 986, in execute_sql
    cursor = super(SQLUpdateCompiler, self).execute_sql(result_type)
  File "/Library/Frameworks/Python.framework/Versions/2.7/lib/python2.7/site-packages/django/db/models/sql/compiler.py", line 808, in execute_sql
    sql, params = self.as_sql()
  File "/Library/Frameworks/Python.framework/Versions/2.7/lib/python2.7/site-packages/django/db/models/sql/compiler.py", line 951, in as_sql
    val = field.get_db_prep_save(val, connection=self.connection)
  File "/Library/Frameworks/Python.framework/Versions/2.7/lib/python2.7/site-packages/django/db/models/fields/__init__.py", line 292, in get_db_prep_save
    prepared=False)
  File "/Library/Frameworks/Python.framework/Versions/2.7/lib/python2.7/site-packages/django/db/models/fields/__init__.py", line 284, in get_db_prep_value
    value = self.get_prep_value(value)
  File "/Library/Frameworks/Python.framework/Versions/2.7/lib/python2.7/site-packages/django/db/models/fields/__init__.py", line 937, in get_prep_value
    return float(value)
TypeError: float() argument must be a string or a number
Internal Server Error: /admincommProd/rating/add/
Traceback (most recent call last):
  File "/Library/Frameworks/Python.framework/Versions/2.7/lib/python2.7/site-packages/django/core/handlers/base.py", line 111, in get_response
    response = callback(request, *callback_args, **callback_kwargs)
  File "/Library/Frameworks/Python.framework/Versions/2.7/lib/python2.7/site-packages/django/contrib/admin/options.py", line 366, in wrapper
    return self.admin_site.admin_view(view)(*args, **kwargs)
  File "/Library/Frameworks/Python.framework/Versions/2.7/lib/python2.7/site-packages/django/utils/decorators.py", line 91, in _wrapped_view
    response = view_func(request, *args, **kwargs)
  File "/Library/Frameworks/Python.framework/Versions/2.7/lib/python2.7/site-packages/django/views/decorators/cache.py", line 89, in _wrapped_view_func
    response = view_func(request, *args, **kwargs)
  File "/Library/Frameworks/Python.framework/Versions/2.7/lib/python2.7/site-packages/django/contrib/admin/sites.py", line 196, in inner
    return view(request, *args, **kwargs)
  File "/Library/Frameworks/Python.framework/Versions/2.7/lib/python2.7/site-packages/django/utils/decorators.py", line 25, in _wrapper
    return bound_func(*args, **kwargs)
  File "/Library/Frameworks/Python.framework/Versions/2.7/lib/python2.7/site-packages/django/utils/decorators.py", line 91, in _wrapped_view
    response = view_func(request, *args, **kwargs)
  File "/Library/Frameworks/Python.framework/Versions/2.7/lib/python2.7/site-packages/django/utils/decorators.py", line 21, in bound_func
    return func(self, *args2, **kwargs2)
  File "/Library/Frameworks/Python.framework/Versions/2.7/lib/python2.7/site-packages/django/db/transaction.py", line 209, in inner
    return func(*args, **kwargs)
  File "/Library/Frameworks/Python.framework/Versions/2.7/lib/python2.7/site-packages/django/contrib/admin/options.py", line 955, in add_view
    self.save_model(request, new_object, form, False)
  File "/Library/Frameworks/Python.framework/Versions/2.7/lib/python2.7/site-packages/django/contrib/admin/options.py", line 709, in save_model
    obj.save()
  File "/Library/Frameworks/Python.framework/Versions/2.7/lib/python2.7/site-packages/django/db/models/base.py", line 463, in save
    self.save_base(using=using, force_insert=force_insert, force_update=force_update)
  File "/Library/Frameworks/Python.framework/Versions/2.7/lib/python2.7/site-packages/django/db/models/base.py", line 565, in save_base
    created=(not record_exists), raw=raw, using=using)
  File "/Library/Frameworks/Python.framework/Versions/2.7/lib/python2.7/site-packages/django/dispatch/dispatcher.py", line 172, in send
    response = receiver(signal=self, sender=sender, **named)
  File "/Users/joshblum/Desktop/Dropbox/code/comm.prod/commProd/signals.py", line 11, in post_save_ratings
    instance.commprod.update_avg()
  File "/Users/joshblum/Desktop/Dropbox/code/comm.prod/commProd/models.py", line 55, in update_avg
    self.avg_score = Rating.objects.filter(commprod=self).aggregate(Avg('score'))['score']
KeyError: 'score'
Internal Server Error: /admincommProd/rating/5/
Traceback (most recent call last):
  File "/Library/Frameworks/Python.framework/Versions/2.7/lib/python2.7/site-packages/django/core/handlers/base.py", line 111, in get_response
    response = callback(request, *callback_args, **callback_kwargs)
  File "/Library/Frameworks/Python.framework/Versions/2.7/lib/python2.7/site-packages/django/contrib/admin/options.py", line 366, in wrapper
    return self.admin_site.admin_view(view)(*args, **kwargs)
  File "/Library/Frameworks/Python.framework/Versions/2.7/lib/python2.7/site-packages/django/utils/decorators.py", line 91, in _wrapped_view
    response = view_func(request, *args, **kwargs)
  File "/Library/Frameworks/Python.framework/Versions/2.7/lib/python2.7/site-packages/django/views/decorators/cache.py", line 89, in _wrapped_view_func
    response = view_func(request, *args, **kwargs)
  File "/Library/Frameworks/Python.framework/Versions/2.7/lib/python2.7/site-packages/django/contrib/admin/sites.py", line 196, in inner
    return view(request, *args, **kwargs)
  File "/Library/Frameworks/Python.framework/Versions/2.7/lib/python2.7/site-packages/django/utils/decorators.py", line 25, in _wrapper
    return bound_func(*args, **kwargs)
  File "/Library/Frameworks/Python.framework/Versions/2.7/lib/python2.7/site-packages/django/utils/decorators.py", line 91, in _wrapped_view
    response = view_func(request, *args, **kwargs)
  File "/Library/Frameworks/Python.framework/Versions/2.7/lib/python2.7/site-packages/django/utils/decorators.py", line 21, in bound_func
    return func(self, *args2, **kwargs2)
  File "/Library/Frameworks/Python.framework/Versions/2.7/lib/python2.7/site-packages/django/db/transaction.py", line 209, in inner
    return func(*args, **kwargs)
  File "/Library/Frameworks/Python.framework/Versions/2.7/lib/python2.7/site-packages/django/contrib/admin/options.py", line 1054, in change_view
    self.save_model(request, new_object, form, True)
  File "/Library/Frameworks/Python.framework/Versions/2.7/lib/python2.7/site-packages/django/contrib/admin/options.py", line 709, in save_model
    obj.save()
  File "/Library/Frameworks/Python.framework/Versions/2.7/lib/python2.7/site-packages/django/db/models/base.py", line 463, in save
    self.save_base(using=using, force_insert=force_insert, force_update=force_update)
  File "/Library/Frameworks/Python.framework/Versions/2.7/lib/python2.7/site-packages/django/db/models/base.py", line 565, in save_base
    created=(not record_exists), raw=raw, using=using)
  File "/Library/Frameworks/Python.framework/Versions/2.7/lib/python2.7/site-packages/django/dispatch/dispatcher.py", line 172, in send
    response = receiver(signal=self, sender=sender, **named)
  File "/Users/joshblum/Desktop/Dropbox/code/comm.prod/commProd/signals.py", line 12, in post_save_ratings
    instance.user.profile.update_avg()
  File "/Users/joshblum/Desktop/Dropbox/code/comm.prod/commProd/models.py", line 20, in update_avg
    self.save()
  File "/Library/Frameworks/Python.framework/Versions/2.7/lib/python2.7/site-packages/django/db/models/base.py", line 463, in save
    self.save_base(using=using, force_insert=force_insert, force_update=force_update)
  File "/Library/Frameworks/Python.framework/Versions/2.7/lib/python2.7/site-packages/django/db/models/base.py", line 529, in save_base
    rows = manager.using(using).filter(pk=pk_val)._update(values)
  File "/Library/Frameworks/Python.framework/Versions/2.7/lib/python2.7/site-packages/django/db/models/query.py", line 557, in _update
    return query.get_compiler(self.db).execute_sql(None)
  File "/Library/Frameworks/Python.framework/Versions/2.7/lib/python2.7/site-packages/django/db/models/sql/compiler.py", line 986, in execute_sql
    cursor = super(SQLUpdateCompiler, self).execute_sql(result_type)
  File "/Library/Frameworks/Python.framework/Versions/2.7/lib/python2.7/site-packages/django/db/models/sql/compiler.py", line 818, in execute_sql
    cursor.execute(sql, params)
  File "/Library/Frameworks/Python.framework/Versions/2.7/lib/python2.7/site-packages/django/db/backends/util.py", line 40, in execute
    return self.cursor.execute(sql, params)
  File "/Library/Frameworks/Python.framework/Versions/2.7/lib/python2.7/site-packages/django/db/backends/mysql/base.py", line 114, in execute
    return self.cursor.execute(query, args)
  File "/Users/joshblum/Library/Python/2.7/lib/python/site-packages/MySQLdb/cursors.py", line 176, in execute
    if not self._defer_warnings: self._warning_check()
  File "/Users/joshblum/Library/Python/2.7/lib/python/site-packages/MySQLdb/cursors.py", line 92, in _warning_check
    warn(w[-1], self.Warning, 3)
Warning: Column 'avg_score' cannot be null
