<<<<<<< HEAD
Internal Server Error: /login
Traceback (most recent call last):
  File "/usr/local/lib/python2.7/dist-packages/django/core/handlers/base.py", line 188, in get_response
    response = middleware_method(request, response)
  File "/usr/local/lib/python2.7/dist-packages/django/contrib/sessions/middleware.py", line 34, in process_response
    expires = cookie_date(expires_time)
  File "/usr/local/lib/python2.7/dist-packages/django/utils/http.py", line 88, in cookie_date
    rfcdate = formatdate(epoch_seconds)
  File "/usr/lib/python2.7/email/utils.py", line 161, in formatdate
    now = time.gmtime(timeval)
ValueError: timestamp out of range for platform time_t
Internal Server Error: /login
Traceback (most recent call last):
  File "/usr/local/lib/python2.7/dist-packages/django/core/handlers/base.py", line 188, in get_response
    response = middleware_method(request, response)
  File "/usr/local/lib/python2.7/dist-packages/django/contrib/sessions/middleware.py", line 34, in process_response
    expires = cookie_date(expires_time)
  File "/usr/local/lib/python2.7/dist-packages/django/utils/http.py", line 88, in cookie_date
    rfcdate = formatdate(epoch_seconds)
  File "/usr/lib/python2.7/email/utils.py", line 161, in formatdate
    now = time.gmtime(timeval)
ValueError: timestamp out of range for platform time_t
Internal Server Error: /login
Traceback (most recent call last):
  File "/usr/local/lib/python2.7/dist-packages/django/core/handlers/base.py", line 188, in get_response
    response = middleware_method(request, response)
  File "/usr/local/lib/python2.7/dist-packages/django/contrib/sessions/middleware.py", line 34, in process_response
    expires = cookie_date(expires_time)
  File "/usr/local/lib/python2.7/dist-packages/django/utils/http.py", line 88, in cookie_date
    rfcdate = formatdate(epoch_seconds)
  File "/usr/lib/python2.7/email/utils.py", line 161, in formatdate
    now = time.gmtime(timeval)
ValueError: timestamp out of range for platform time_t
Internal Server Error: /login
Traceback (most recent call last):
  File "/usr/local/lib/python2.7/dist-packages/django/core/handlers/base.py", line 188, in get_response
    response = middleware_method(request, response)
  File "/usr/local/lib/python2.7/dist-packages/django/contrib/sessions/middleware.py", line 34, in process_response
    expires = cookie_date(expires_time)
  File "/usr/local/lib/python2.7/dist-packages/django/utils/http.py", line 88, in cookie_date
    rfcdate = formatdate(epoch_seconds)
  File "/usr/lib/python2.7/email/utils.py", line 161, in formatdate
    now = time.gmtime(timeval)
ValueError: timestamp out of range for platform time_t
Internal Server Error: /login
Traceback (most recent call last):
  File "/usr/local/lib/python2.7/dist-packages/django/core/handlers/base.py", line 188, in get_response
    response = middleware_method(request, response)
  File "/usr/local/lib/python2.7/dist-packages/django/contrib/sessions/middleware.py", line 34, in process_response
    expires = cookie_date(expires_time)
  File "/usr/local/lib/python2.7/dist-packages/django/utils/http.py", line 88, in cookie_date
    rfcdate = formatdate(epoch_seconds)
  File "/usr/lib/python2.7/email/utils.py", line 161, in formatdate
    now = time.gmtime(timeval)
ValueError: timestamp out of range for platform time_t
Internal Server Error: /login
Traceback (most recent call last):
  File "/usr/local/lib/python2.7/dist-packages/django/core/handlers/base.py", line 188, in get_response
    response = middleware_method(request, response)
  File "/usr/local/lib/python2.7/dist-packages/django/contrib/sessions/middleware.py", line 34, in process_response
    expires = cookie_date(expires_time)
  File "/usr/local/lib/python2.7/dist-packages/django/utils/http.py", line 88, in cookie_date
    rfcdate = formatdate(epoch_seconds)
  File "/usr/lib/python2.7/email/utils.py", line 161, in formatdate
    now = time.gmtime(timeval)
ValueError: timestamp out of range for platform time_t
Internal Server Error: /login
Traceback (most recent call last):
  File "/usr/local/lib/python2.7/dist-packages/django/core/handlers/base.py", line 188, in get_response
    response = middleware_method(request, response)
  File "/usr/local/lib/python2.7/dist-packages/django/contrib/sessions/middleware.py", line 34, in process_response
    expires = cookie_date(expires_time)
  File "/usr/local/lib/python2.7/dist-packages/django/utils/http.py", line 88, in cookie_date
    rfcdate = formatdate(epoch_seconds)
  File "/usr/lib/python2.7/email/utils.py", line 161, in formatdate
    now = time.gmtime(timeval)
ValueError: timestamp out of range for platform time_t
Internal Server Error: /login
Traceback (most recent call last):
  File "/usr/local/lib/python2.7/dist-packages/django/core/handlers/base.py", line 188, in get_response
    response = middleware_method(request, response)
  File "/usr/local/lib/python2.7/dist-packages/django/contrib/sessions/middleware.py", line 34, in process_response
    expires = cookie_date(expires_time)
  File "/usr/local/lib/python2.7/dist-packages/django/utils/http.py", line 88, in cookie_date
    rfcdate = formatdate(epoch_seconds)
  File "/usr/lib/python2.7/email/utils.py", line 161, in formatdate
    now = time.gmtime(timeval)
ValueError: timestamp out of range for platform time_t
Internal Server Error: /login
Traceback (most recent call last):
  File "/usr/local/lib/python2.7/dist-packages/django/core/handlers/base.py", line 111, in get_response
    response = callback(request, *callback_args, **callback_kwargs)
  File "/usr/local/lib/python2.7/dist-packages/django/views/decorators/debug.py", line 69, in wrapper
    return view(request, *args, **kwargs)
  File "/usr/local/lib/python2.7/dist-packages/django/utils/decorators.py", line 91, in _wrapped_view
    response = view_func(request, *args, **kwargs)
  File "/usr/local/lib/python2.7/dist-packages/django/views/decorators/cache.py", line 89, in _wrapped_view_func
    response = view_func(request, *args, **kwargs)
  File "/usr/local/lib/python2.7/dist-packages/django/contrib/auth/views.py", line 58, in login
    request.session.set_test_cookie()
  File "/usr/local/lib/python2.7/dist-packages/django/contrib/sessions/backends/base.py", line 65, in set_test_cookie
    self[self.TEST_COOKIE_NAME] = self.TEST_COOKIE_VALUE
  File "/usr/local/lib/python2.7/dist-packages/django/contrib/sessions/backends/base.py", line 42, in __setitem__
    self._session[key] = value
  File "/usr/local/lib/python2.7/dist-packages/django/contrib/sessions/backends/base.py", line 165, in _get_session
    self._session_cache = self.load()
  File "/usr/local/lib/python2.7/dist-packages/django/contrib/sessions/backends/db.py", line 19, in load
    expire_date__gt=timezone.now()
  File "/usr/local/lib/python2.7/dist-packages/django/db/models/manager.py", line 131, in get
    return self.get_query_set().get(*args, **kwargs)
  File "/usr/local/lib/python2.7/dist-packages/django/db/models/query.py", line 361, in get
    num = len(clone)
  File "/usr/local/lib/python2.7/dist-packages/django/db/models/query.py", line 85, in __len__
    self._result_cache = list(self.iterator())
  File "/usr/local/lib/python2.7/dist-packages/django/db/models/query.py", line 291, in iterator
    for row in compiler.results_iter():
  File "/usr/local/lib/python2.7/dist-packages/django/db/models/sql/compiler.py", line 763, in results_iter
    for rows in self.execute_sql(MULTI):
  File "/usr/local/lib/python2.7/dist-packages/django/db/models/sql/compiler.py", line 817, in execute_sql
    cursor = self.connection.cursor()
  File "/usr/local/lib/python2.7/dist-packages/django/db/backends/__init__.py", line 306, in cursor
    cursor = self.make_debug_cursor(self._cursor())
  File "/usr/local/lib/python2.7/dist-packages/django/db/backends/mysql/base.py", line 387, in _cursor
    self.connection = Database.connect(**kwargs)
  File "/usr/local/lib/python2.7/dist-packages/MySQLdb/__init__.py", line 81, in Connect
    return Connection(*args, **kwargs)
  File "/usr/local/lib/python2.7/dist-packages/MySQLdb/connections.py", line 187, in __init__
    super(Connection, self).__init__(*args, **kwargs2)
OperationalError: (2003, "Can't connect to MySQL server on 'sql.mit.edu' (110)")
Internal Server Error: /
Traceback (most recent call last):
  File "/usr/local/lib/python2.7/dist-packages/django/core/handlers/base.py", line 111, in get_response
    response = callback(request, *callback_args, **callback_kwargs)
  File "/usr/local/lib/python2.7/dist-packages/django/contrib/auth/decorators.py", line 19, in _wrapped_view
    if test_func(request.user):
  File "/usr/local/lib/python2.7/dist-packages/django/contrib/auth/decorators.py", line 42, in <lambda>
    lambda u: u.is_authenticated(),
  File "/usr/local/lib/python2.7/dist-packages/django/utils/functional.py", line 184, in inner
    self._setup()
  File "/usr/local/lib/python2.7/dist-packages/django/utils/functional.py", line 248, in _setup
    self._wrapped = self._setupfunc()
  File "/usr/local/lib/python2.7/dist-packages/django/contrib/auth/middleware.py", line 16, in <lambda>
    request.user = SimpleLazyObject(lambda: get_user(request))
  File "/usr/local/lib/python2.7/dist-packages/django/contrib/auth/middleware.py", line 8, in get_user
    request._cached_user = auth.get_user(request)
  File "/usr/local/lib/python2.7/dist-packages/django/contrib/auth/__init__.py", line 98, in get_user
    user_id = request.session[SESSION_KEY]
  File "/usr/local/lib/python2.7/dist-packages/django/contrib/sessions/backends/base.py", line 39, in __getitem__
    return self._session[key]
  File "/usr/local/lib/python2.7/dist-packages/django/contrib/sessions/backends/base.py", line 165, in _get_session
    self._session_cache = self.load()
  File "/usr/local/lib/python2.7/dist-packages/django/contrib/sessions/backends/db.py", line 19, in load
    expire_date__gt=timezone.now()
  File "/usr/local/lib/python2.7/dist-packages/django/db/models/manager.py", line 131, in get
    return self.get_query_set().get(*args, **kwargs)
  File "/usr/local/lib/python2.7/dist-packages/django/db/models/query.py", line 361, in get
    num = len(clone)
  File "/usr/local/lib/python2.7/dist-packages/django/db/models/query.py", line 85, in __len__
    self._result_cache = list(self.iterator())
  File "/usr/local/lib/python2.7/dist-packages/django/db/models/query.py", line 291, in iterator
    for row in compiler.results_iter():
  File "/usr/local/lib/python2.7/dist-packages/django/db/models/sql/compiler.py", line 763, in results_iter
    for rows in self.execute_sql(MULTI):
  File "/usr/local/lib/python2.7/dist-packages/django/db/models/sql/compiler.py", line 817, in execute_sql
    cursor = self.connection.cursor()
  File "/usr/local/lib/python2.7/dist-packages/django/db/backends/__init__.py", line 306, in cursor
    cursor = self.make_debug_cursor(self._cursor())
  File "/usr/local/lib/python2.7/dist-packages/django/db/backends/mysql/base.py", line 387, in _cursor
    self.connection = Database.connect(**kwargs)
  File "/usr/local/lib/python2.7/dist-packages/MySQLdb/__init__.py", line 81, in Connect
    return Connection(*args, **kwargs)
  File "/usr/local/lib/python2.7/dist-packages/MySQLdb/connections.py", line 187, in __init__
    super(Connection, self).__init__(*args, **kwargs2)
OperationalError: (2003, "Can't connect to MySQL server on 'sql.mit.edu' (110)")
Internal Server Error: /
Traceback (most recent call last):
  File "/usr/local/lib/python2.7/dist-packages/django/core/handlers/base.py", line 111, in get_response
    response = callback(request, *callback_args, **callback_kwargs)
  File "/usr/local/lib/python2.7/dist-packages/django/contrib/auth/decorators.py", line 19, in _wrapped_view
    if test_func(request.user):
  File "/usr/local/lib/python2.7/dist-packages/django/contrib/auth/decorators.py", line 42, in <lambda>
    lambda u: u.is_authenticated(),
  File "/usr/local/lib/python2.7/dist-packages/django/utils/functional.py", line 184, in inner
    self._setup()
  File "/usr/local/lib/python2.7/dist-packages/django/utils/functional.py", line 248, in _setup
    self._wrapped = self._setupfunc()
  File "/usr/local/lib/python2.7/dist-packages/django/contrib/auth/middleware.py", line 16, in <lambda>
    request.user = SimpleLazyObject(lambda: get_user(request))
  File "/usr/local/lib/python2.7/dist-packages/django/contrib/auth/middleware.py", line 8, in get_user
    request._cached_user = auth.get_user(request)
  File "/usr/local/lib/python2.7/dist-packages/django/contrib/auth/__init__.py", line 98, in get_user
    user_id = request.session[SESSION_KEY]
  File "/usr/local/lib/python2.7/dist-packages/django/contrib/sessions/backends/base.py", line 39, in __getitem__
    return self._session[key]
  File "/usr/local/lib/python2.7/dist-packages/django/contrib/sessions/backends/base.py", line 165, in _get_session
    self._session_cache = self.load()
  File "/usr/local/lib/python2.7/dist-packages/django/contrib/sessions/backends/db.py", line 19, in load
    expire_date__gt=timezone.now()
  File "/usr/local/lib/python2.7/dist-packages/django/db/models/manager.py", line 131, in get
    return self.get_query_set().get(*args, **kwargs)
  File "/usr/local/lib/python2.7/dist-packages/django/db/models/query.py", line 361, in get
    num = len(clone)
  File "/usr/local/lib/python2.7/dist-packages/django/db/models/query.py", line 85, in __len__
    self._result_cache = list(self.iterator())
  File "/usr/local/lib/python2.7/dist-packages/django/db/models/query.py", line 291, in iterator
    for row in compiler.results_iter():
  File "/usr/local/lib/python2.7/dist-packages/django/db/models/sql/compiler.py", line 763, in results_iter
    for rows in self.execute_sql(MULTI):
  File "/usr/local/lib/python2.7/dist-packages/django/db/models/sql/compiler.py", line 817, in execute_sql
    cursor = self.connection.cursor()
  File "/usr/local/lib/python2.7/dist-packages/django/db/backends/__init__.py", line 306, in cursor
    cursor = self.make_debug_cursor(self._cursor())
  File "/usr/local/lib/python2.7/dist-packages/django/db/backends/mysql/base.py", line 387, in _cursor
    self.connection = Database.connect(**kwargs)
  File "/usr/local/lib/python2.7/dist-packages/MySQLdb/__init__.py", line 81, in Connect
    return Connection(*args, **kwargs)
  File "/usr/local/lib/python2.7/dist-packages/MySQLdb/connections.py", line 187, in __init__
    super(Connection, self).__init__(*args, **kwargs2)
OperationalError: (2005, "Unknown MySQL server host 'sql.mit.edu' (2)")
Internal Server Error: /admin
Traceback (most recent call last):
  File "/usr/local/lib/python2.7/dist-packages/django/core/handlers/base.py", line 111, in get_response
    response = callback(request, *callback_args, **callback_kwargs)
  File "/usr/local/lib/python2.7/dist-packages/django/contrib/admin/sites.py", line 213, in wrapper
    return self.admin_view(view, cacheable)(*args, **kwargs)
  File "/usr/local/lib/python2.7/dist-packages/django/utils/decorators.py", line 91, in _wrapped_view
    response = view_func(request, *args, **kwargs)
  File "/usr/local/lib/python2.7/dist-packages/django/views/decorators/cache.py", line 89, in _wrapped_view_func
    response = view_func(request, *args, **kwargs)
  File "/usr/local/lib/python2.7/dist-packages/django/contrib/admin/sites.py", line 190, in inner
    if not self.has_permission(request):
  File "/usr/local/lib/python2.7/dist-packages/django/contrib/admin/sites.py", line 143, in has_permission
    return request.user.is_active and request.user.is_staff
  File "/usr/local/lib/python2.7/dist-packages/django/utils/functional.py", line 184, in inner
    self._setup()
  File "/usr/local/lib/python2.7/dist-packages/django/utils/functional.py", line 248, in _setup
    self._wrapped = self._setupfunc()
  File "/usr/local/lib/python2.7/dist-packages/django/contrib/auth/middleware.py", line 16, in <lambda>
    request.user = SimpleLazyObject(lambda: get_user(request))
  File "/usr/local/lib/python2.7/dist-packages/django/contrib/auth/middleware.py", line 8, in get_user
    request._cached_user = auth.get_user(request)
  File "/usr/local/lib/python2.7/dist-packages/django/contrib/auth/__init__.py", line 98, in get_user
    user_id = request.session[SESSION_KEY]
  File "/usr/local/lib/python2.7/dist-packages/django/contrib/sessions/backends/base.py", line 39, in __getitem__
    return self._session[key]
  File "/usr/local/lib/python2.7/dist-packages/django/contrib/sessions/backends/base.py", line 165, in _get_session
    self._session_cache = self.load()
  File "/usr/local/lib/python2.7/dist-packages/django/contrib/sessions/backends/db.py", line 19, in load
    expire_date__gt=timezone.now()
  File "/usr/local/lib/python2.7/dist-packages/django/db/models/manager.py", line 131, in get
    return self.get_query_set().get(*args, **kwargs)
  File "/usr/local/lib/python2.7/dist-packages/django/db/models/query.py", line 361, in get
    num = len(clone)
  File "/usr/local/lib/python2.7/dist-packages/django/db/models/query.py", line 85, in __len__
    self._result_cache = list(self.iterator())
  File "/usr/local/lib/python2.7/dist-packages/django/db/models/query.py", line 291, in iterator
    for row in compiler.results_iter():
  File "/usr/local/lib/python2.7/dist-packages/django/db/models/sql/compiler.py", line 763, in results_iter
    for rows in self.execute_sql(MULTI):
  File "/usr/local/lib/python2.7/dist-packages/django/db/models/sql/compiler.py", line 817, in execute_sql
    cursor = self.connection.cursor()
  File "/usr/local/lib/python2.7/dist-packages/django/db/backends/__init__.py", line 306, in cursor
    cursor = self.make_debug_cursor(self._cursor())
  File "/usr/local/lib/python2.7/dist-packages/django/db/backends/mysql/base.py", line 387, in _cursor
    self.connection = Database.connect(**kwargs)
  File "/usr/local/lib/python2.7/dist-packages/MySQLdb/__init__.py", line 81, in Connect
    return Connection(*args, **kwargs)
  File "/usr/local/lib/python2.7/dist-packages/MySQLdb/connections.py", line 187, in __init__
    super(Connection, self).__init__(*args, **kwargs2)
OperationalError: (2003, "Can't connect to MySQL server on 'sql.mit.edu' (110)")
Internal Server Error: /
Traceback (most recent call last):
  File "/usr/local/lib/python2.7/dist-packages/django/core/handlers/base.py", line 111, in get_response
    response = callback(request, *callback_args, **callback_kwargs)
  File "/usr/local/lib/python2.7/dist-packages/django/contrib/auth/decorators.py", line 19, in _wrapped_view
    if test_func(request.user):
  File "/usr/local/lib/python2.7/dist-packages/django/contrib/auth/decorators.py", line 42, in <lambda>
    lambda u: u.is_authenticated(),
  File "/usr/local/lib/python2.7/dist-packages/django/utils/functional.py", line 184, in inner
    self._setup()
  File "/usr/local/lib/python2.7/dist-packages/django/utils/functional.py", line 248, in _setup
    self._wrapped = self._setupfunc()
  File "/usr/local/lib/python2.7/dist-packages/django/contrib/auth/middleware.py", line 16, in <lambda>
    request.user = SimpleLazyObject(lambda: get_user(request))
  File "/usr/local/lib/python2.7/dist-packages/django/contrib/auth/middleware.py", line 8, in get_user
    request._cached_user = auth.get_user(request)
  File "/usr/local/lib/python2.7/dist-packages/django/contrib/auth/__init__.py", line 98, in get_user
    user_id = request.session[SESSION_KEY]
  File "/usr/local/lib/python2.7/dist-packages/django/contrib/sessions/backends/base.py", line 39, in __getitem__
    return self._session[key]
  File "/usr/local/lib/python2.7/dist-packages/django/contrib/sessions/backends/base.py", line 165, in _get_session
    self._session_cache = self.load()
  File "/usr/local/lib/python2.7/dist-packages/django/contrib/sessions/backends/db.py", line 19, in load
    expire_date__gt=timezone.now()
  File "/usr/local/lib/python2.7/dist-packages/django/db/models/manager.py", line 131, in get
    return self.get_query_set().get(*args, **kwargs)
  File "/usr/local/lib/python2.7/dist-packages/django/db/models/query.py", line 361, in get
    num = len(clone)
  File "/usr/local/lib/python2.7/dist-packages/django/db/models/query.py", line 85, in __len__
    self._result_cache = list(self.iterator())
  File "/usr/local/lib/python2.7/dist-packages/django/db/models/query.py", line 291, in iterator
    for row in compiler.results_iter():
  File "/usr/local/lib/python2.7/dist-packages/django/db/models/sql/compiler.py", line 763, in results_iter
    for rows in self.execute_sql(MULTI):
  File "/usr/local/lib/python2.7/dist-packages/django/db/models/sql/compiler.py", line 817, in execute_sql
    cursor = self.connection.cursor()
  File "/usr/local/lib/python2.7/dist-packages/django/db/backends/__init__.py", line 306, in cursor
    cursor = self.make_debug_cursor(self._cursor())
  File "/usr/local/lib/python2.7/dist-packages/django/db/backends/mysql/base.py", line 387, in _cursor
    self.connection = Database.connect(**kwargs)
  File "/usr/local/lib/python2.7/dist-packages/MySQLdb/__init__.py", line 81, in Connect
    return Connection(*args, **kwargs)
  File "/usr/local/lib/python2.7/dist-packages/MySQLdb/connections.py", line 187, in __init__
    super(Connection, self).__init__(*args, **kwargs2)
OperationalError: (2003, "Can't connect to MySQL server on 'sql.mit.edu' (110)")
Internal Server Error: /
Traceback (most recent call last):
  File "/usr/local/lib/python2.7/dist-packages/django/core/handlers/base.py", line 101, in get_response
    request.path_info)
  File "/usr/local/lib/python2.7/dist-packages/django/core/urlresolvers.py", line 300, in resolve
    sub_match = pattern.resolve(new_path)
  File "/usr/local/lib/python2.7/dist-packages/django/core/urlresolvers.py", line 300, in resolve
    sub_match = pattern.resolve(new_path)
  File "/usr/local/lib/python2.7/dist-packages/django/core/urlresolvers.py", line 209, in resolve
    return ResolverMatch(self.callback, args, kwargs, self.name)
  File "/usr/local/lib/python2.7/dist-packages/django/core/urlresolvers.py", line 216, in callback
    self._callback = get_callable(self._callback_str)
  File "/usr/local/lib/python2.7/dist-packages/django/utils/functional.py", line 27, in wrapper
    result = func(*args)
  File "/usr/local/lib/python2.7/dist-packages/django/core/urlresolvers.py", line 92, in get_callable
    lookup_view = getattr(import_module(mod_name), func_name)
  File "/usr/local/lib/python2.7/dist-packages/django/utils/importlib.py", line 35, in import_module
    __import__(name)
  File "/home/max/Documents/projects/comm.prod/commProd/views.py", line 165
    return return HttpResponse(json.dumps({'success':False}), mimetype='application/json')
                ^
SyntaxError: invalid syntax
Internal Server Error: /
Traceback (most recent call last):
  File "/usr/local/lib/python2.7/dist-packages/django/core/handlers/base.py", line 101, in get_response
    request.path_info)
  File "/usr/local/lib/python2.7/dist-packages/django/core/urlresolvers.py", line 300, in resolve
    sub_match = pattern.resolve(new_path)
  File "/usr/local/lib/python2.7/dist-packages/django/core/urlresolvers.py", line 300, in resolve
    sub_match = pattern.resolve(new_path)
  File "/usr/local/lib/python2.7/dist-packages/django/core/urlresolvers.py", line 209, in resolve
    return ResolverMatch(self.callback, args, kwargs, self.name)
  File "/usr/local/lib/python2.7/dist-packages/django/core/urlresolvers.py", line 216, in callback
    self._callback = get_callable(self._callback_str)
  File "/usr/local/lib/python2.7/dist-packages/django/utils/functional.py", line 27, in wrapper
    result = func(*args)
  File "/usr/local/lib/python2.7/dist-packages/django/core/urlresolvers.py", line 92, in get_callable
    lookup_view = getattr(import_module(mod_name), func_name)
  File "/usr/local/lib/python2.7/dist-packages/django/utils/importlib.py", line 35, in import_module
    __import__(name)
  File "/home/max/Documents/projects/comm.prod/commProd/views.py", line 15, in <module>
    from commerical_production.commprod_search import commprod_search
  File "/home/max/Documents/projects/comm.prod/commerical_production/commprod_search.py", line 3
    def commprod_search(cp_id=None, query=None, orderBy='date', direction='hl' username=None, startDate=None, endDate=None ):
                                                                                      ^
SyntaxError: invalid syntax
Internal Server Error: /
Traceback (most recent call last):
  File "/usr/local/lib/python2.7/dist-packages/django/core/handlers/base.py", line 101, in get_response
    request.path_info)
  File "/usr/local/lib/python2.7/dist-packages/django/core/urlresolvers.py", line 300, in resolve
    sub_match = pattern.resolve(new_path)
  File "/usr/local/lib/python2.7/dist-packages/django/core/urlresolvers.py", line 300, in resolve
    sub_match = pattern.resolve(new_path)
  File "/usr/local/lib/python2.7/dist-packages/django/core/urlresolvers.py", line 209, in resolve
    return ResolverMatch(self.callback, args, kwargs, self.name)
  File "/usr/local/lib/python2.7/dist-packages/django/core/urlresolvers.py", line 216, in callback
    self._callback = get_callable(self._callback_str)
  File "/usr/local/lib/python2.7/dist-packages/django/utils/functional.py", line 27, in wrapper
    result = func(*args)
  File "/usr/local/lib/python2.7/dist-packages/django/core/urlresolvers.py", line 92, in get_callable
    lookup_view = getattr(import_module(mod_name), func_name)
  File "/usr/local/lib/python2.7/dist-packages/django/utils/importlib.py", line 35, in import_module
    __import__(name)
  File "/home/max/Documents/projects/comm.prod/commProd/views.py", line 15, in <module>
    from commerical_production.commprod_search import commprod_search
  File "/home/max/Documents/projects/comm.prod/commerical_production/commprod_search.py", line 14
    if direction = 'lh':
                 ^
SyntaxError: invalid syntax
Internal Server Error: /login
Traceback (most recent call last):
  File "/usr/local/lib/python2.7/dist-packages/django/core/handlers/base.py", line 111, in get_response
    response = callback(request, *callback_args, **callback_kwargs)
  File "/usr/local/lib/python2.7/dist-packages/django/views/decorators/debug.py", line 69, in wrapper
    return view(request, *args, **kwargs)
  File "/usr/local/lib/python2.7/dist-packages/django/utils/decorators.py", line 91, in _wrapped_view
    response = view_func(request, *args, **kwargs)
  File "/usr/local/lib/python2.7/dist-packages/django/views/decorators/cache.py", line 89, in _wrapped_view_func
    response = view_func(request, *args, **kwargs)
  File "/usr/local/lib/python2.7/dist-packages/django/contrib/auth/views.py", line 60, in login
    current_site = get_current_site(request)
  File "/usr/local/lib/python2.7/dist-packages/django/contrib/sites/models.py", line 92, in get_current_site
    current_site = Site.objects.get_current()
  File "/usr/local/lib/python2.7/dist-packages/django/contrib/sites/models.py", line 25, in get_current
    current_site = self.get(pk=sid)
  File "/usr/local/lib/python2.7/dist-packages/django/db/models/manager.py", line 131, in get
    return self.get_query_set().get(*args, **kwargs)
  File "/usr/local/lib/python2.7/dist-packages/django/db/models/query.py", line 366, in get
    % self.model._meta.object_name)
DoesNotExist: Site matching query does not exist.
Internal Server Error: /login
Traceback (most recent call last):
  File "/usr/local/lib/python2.7/dist-packages/django/core/handlers/base.py", line 111, in get_response
    response = callback(request, *callback_args, **callback_kwargs)
  File "/usr/local/lib/python2.7/dist-packages/django/views/decorators/debug.py", line 69, in wrapper
    return view(request, *args, **kwargs)
  File "/usr/local/lib/python2.7/dist-packages/django/utils/decorators.py", line 91, in _wrapped_view
    response = view_func(request, *args, **kwargs)
  File "/usr/local/lib/python2.7/dist-packages/django/views/decorators/cache.py", line 89, in _wrapped_view_func
    response = view_func(request, *args, **kwargs)
  File "/usr/local/lib/python2.7/dist-packages/django/contrib/auth/views.py", line 60, in login
    current_site = get_current_site(request)
  File "/usr/local/lib/python2.7/dist-packages/django/contrib/sites/models.py", line 92, in get_current_site
    current_site = Site.objects.get_current()
  File "/usr/local/lib/python2.7/dist-packages/django/contrib/sites/models.py", line 25, in get_current
    current_site = self.get(pk=sid)
  File "/usr/local/lib/python2.7/dist-packages/django/db/models/manager.py", line 131, in get
    return self.get_query_set().get(*args, **kwargs)
  File "/usr/local/lib/python2.7/dist-packages/django/db/models/query.py", line 366, in get
    % self.model._meta.object_name)
DoesNotExist: Site matching query does not exist.
Internal Server Error: /login
Traceback (most recent call last):
  File "/usr/local/lib/python2.7/dist-packages/django/core/handlers/base.py", line 111, in get_response
    response = callback(request, *callback_args, **callback_kwargs)
  File "/usr/local/lib/python2.7/dist-packages/django/views/decorators/debug.py", line 69, in wrapper
    return view(request, *args, **kwargs)
  File "/usr/local/lib/python2.7/dist-packages/django/utils/decorators.py", line 91, in _wrapped_view
    response = view_func(request, *args, **kwargs)
  File "/usr/local/lib/python2.7/dist-packages/django/views/decorators/cache.py", line 89, in _wrapped_view_func
    response = view_func(request, *args, **kwargs)
  File "/usr/local/lib/python2.7/dist-packages/django/contrib/auth/views.py", line 60, in login
    current_site = get_current_site(request)
  File "/usr/local/lib/python2.7/dist-packages/django/contrib/sites/models.py", line 92, in get_current_site
    current_site = Site.objects.get_current()
  File "/usr/local/lib/python2.7/dist-packages/django/contrib/sites/models.py", line 25, in get_current
    current_site = self.get(pk=sid)
  File "/usr/local/lib/python2.7/dist-packages/django/db/models/manager.py", line 131, in get
    return self.get_query_set().get(*args, **kwargs)
  File "/usr/local/lib/python2.7/dist-packages/django/db/models/query.py", line 366, in get
    % self.model._meta.object_name)
DoesNotExist: Site matching query does not exist.
Internal Server Error: /login
Traceback (most recent call last):
  File "/usr/local/lib/python2.7/dist-packages/django/core/handlers/base.py", line 111, in get_response
    response = callback(request, *callback_args, **callback_kwargs)
  File "/usr/local/lib/python2.7/dist-packages/django/views/decorators/debug.py", line 69, in wrapper
    return view(request, *args, **kwargs)
  File "/usr/local/lib/python2.7/dist-packages/django/utils/decorators.py", line 91, in _wrapped_view
    response = view_func(request, *args, **kwargs)
  File "/usr/local/lib/python2.7/dist-packages/django/views/decorators/cache.py", line 89, in _wrapped_view_func
    response = view_func(request, *args, **kwargs)
  File "/usr/local/lib/python2.7/dist-packages/django/contrib/auth/views.py", line 60, in login
    current_site = get_current_site(request)
  File "/usr/local/lib/python2.7/dist-packages/django/contrib/sites/models.py", line 92, in get_current_site
    current_site = Site.objects.get_current()
  File "/usr/local/lib/python2.7/dist-packages/django/contrib/sites/models.py", line 25, in get_current
    current_site = self.get(pk=sid)
  File "/usr/local/lib/python2.7/dist-packages/django/db/models/manager.py", line 131, in get
    return self.get_query_set().get(*args, **kwargs)
  File "/usr/local/lib/python2.7/dist-packages/django/db/models/query.py", line 366, in get
    % self.model._meta.object_name)
DoesNotExist: Site matching query does not exist.
Internal Server Error: /login
Traceback (most recent call last):
  File "/usr/local/lib/python2.7/dist-packages/django/core/handlers/base.py", line 111, in get_response
    response = callback(request, *callback_args, **callback_kwargs)
  File "/usr/local/lib/python2.7/dist-packages/django/views/decorators/debug.py", line 69, in wrapper
    return view(request, *args, **kwargs)
  File "/usr/local/lib/python2.7/dist-packages/django/utils/decorators.py", line 91, in _wrapped_view
    response = view_func(request, *args, **kwargs)
  File "/usr/local/lib/python2.7/dist-packages/django/views/decorators/cache.py", line 89, in _wrapped_view_func
    response = view_func(request, *args, **kwargs)
  File "/usr/local/lib/python2.7/dist-packages/django/contrib/auth/views.py", line 60, in login
    current_site = get_current_site(request)
  File "/usr/local/lib/python2.7/dist-packages/django/contrib/sites/models.py", line 92, in get_current_site
    current_site = Site.objects.get_current()
  File "/usr/local/lib/python2.7/dist-packages/django/contrib/sites/models.py", line 25, in get_current
    current_site = self.get(pk=sid)
  File "/usr/local/lib/python2.7/dist-packages/django/db/models/manager.py", line 131, in get
    return self.get_query_set().get(*args, **kwargs)
  File "/usr/local/lib/python2.7/dist-packages/django/db/models/query.py", line 366, in get
    % self.model._meta.object_name)
DoesNotExist: Site matching query does not exist.
Internal Server Error: /admin
Traceback (most recent call last):
  File "/usr/local/lib/python2.7/dist-packages/django/core/handlers/base.py", line 111, in get_response
    response = callback(request, *callback_args, **callback_kwargs)
  File "/usr/local/lib/python2.7/dist-packages/django/contrib/admin/sites.py", line 213, in wrapper
    return self.admin_view(view, cacheable)(*args, **kwargs)
  File "/usr/local/lib/python2.7/dist-packages/django/utils/decorators.py", line 91, in _wrapped_view
    response = view_func(request, *args, **kwargs)
  File "/usr/local/lib/python2.7/dist-packages/django/views/decorators/cache.py", line 89, in _wrapped_view_func
    response = view_func(request, *args, **kwargs)
  File "/usr/local/lib/python2.7/dist-packages/django/contrib/admin/sites.py", line 195, in inner
    return self.login(request)
  File "/usr/local/lib/python2.7/dist-packages/django/views/decorators/cache.py", line 89, in _wrapped_view_func
    response = view_func(request, *args, **kwargs)
  File "/usr/local/lib/python2.7/dist-packages/django/contrib/admin/sites.py", line 326, in login
    return login(request, **defaults)
  File "/usr/local/lib/python2.7/dist-packages/django/views/decorators/debug.py", line 69, in wrapper
    return view(request, *args, **kwargs)
  File "/usr/local/lib/python2.7/dist-packages/django/utils/decorators.py", line 91, in _wrapped_view
    response = view_func(request, *args, **kwargs)
  File "/usr/local/lib/python2.7/dist-packages/django/views/decorators/cache.py", line 89, in _wrapped_view_func
    response = view_func(request, *args, **kwargs)
  File "/usr/local/lib/python2.7/dist-packages/django/contrib/auth/views.py", line 60, in login
    current_site = get_current_site(request)
  File "/usr/local/lib/python2.7/dist-packages/django/contrib/sites/models.py", line 92, in get_current_site
    current_site = Site.objects.get_current()
  File "/usr/local/lib/python2.7/dist-packages/django/contrib/sites/models.py", line 25, in get_current
    current_site = self.get(pk=sid)
  File "/usr/local/lib/python2.7/dist-packages/django/db/models/manager.py", line 131, in get
    return self.get_query_set().get(*args, **kwargs)
  File "/usr/local/lib/python2.7/dist-packages/django/db/models/query.py", line 366, in get
    % self.model._meta.object_name)
DoesNotExist: Site matching query does not exist.
=======
Internal Server Error: /users/joshblum/
Traceback (most recent call last):
  File "/Library/Frameworks/Python.framework/Versions/2.7/lib/python2.7/site-packages/django/core/handlers/base.py", line 111, in get_response
    response = callback(request, *callback_args, **callback_kwargs)
  File "/Library/Frameworks/Python.framework/Versions/2.7/lib/python2.7/site-packages/django/contrib/auth/decorators.py", line 20, in _wrapped_view
    return view_func(request, *args, **kwargs)
  File "/Users/joshblum/Desktop/Dropbox/code/comm.prod/commProd/views.py", line 113, in profile
    page_username = getUsername(user)
  File "/Users/joshblum/Desktop/Dropbox/code/comm.prod/commProd/views.py", line 208, in getUsername
    potentials = json.loads(user.shirt_names)
AttributeError: 'User' object has no attribute 'shirt_names'
Internal Server Error: /users/50/
Traceback (most recent call last):
  File "/Library/Frameworks/Python.framework/Versions/2.7/lib/python2.7/site-packages/django/core/handlers/base.py", line 111, in get_response
    response = callback(request, *callback_args, **callback_kwargs)
  File "/Library/Frameworks/Python.framework/Versions/2.7/lib/python2.7/site-packages/django/contrib/auth/decorators.py", line 19, in _wrapped_view
    if test_func(request.user):
  File "/Library/Frameworks/Python.framework/Versions/2.7/lib/python2.7/site-packages/django/contrib/auth/decorators.py", line 42, in <lambda>
    lambda u: u.is_authenticated(),
  File "/Library/Frameworks/Python.framework/Versions/2.7/lib/python2.7/site-packages/django/utils/functional.py", line 184, in inner
    self._setup()
  File "/Library/Frameworks/Python.framework/Versions/2.7/lib/python2.7/site-packages/django/utils/functional.py", line 248, in _setup
    self._wrapped = self._setupfunc()
  File "/Library/Frameworks/Python.framework/Versions/2.7/lib/python2.7/site-packages/django/contrib/auth/middleware.py", line 16, in <lambda>
    request.user = SimpleLazyObject(lambda: get_user(request))
  File "/Library/Frameworks/Python.framework/Versions/2.7/lib/python2.7/site-packages/django/contrib/auth/middleware.py", line 8, in get_user
    request._cached_user = auth.get_user(request)
  File "/Library/Frameworks/Python.framework/Versions/2.7/lib/python2.7/site-packages/django/contrib/auth/__init__.py", line 98, in get_user
    user_id = request.session[SESSION_KEY]
  File "/Library/Frameworks/Python.framework/Versions/2.7/lib/python2.7/site-packages/django/contrib/sessions/backends/base.py", line 39, in __getitem__
    return self._session[key]
  File "/Library/Frameworks/Python.framework/Versions/2.7/lib/python2.7/site-packages/django/contrib/sessions/backends/base.py", line 165, in _get_session
    self._session_cache = self.load()
  File "/Library/Frameworks/Python.framework/Versions/2.7/lib/python2.7/site-packages/django/contrib/sessions/backends/db.py", line 19, in load
    expire_date__gt=timezone.now()
  File "/Library/Frameworks/Python.framework/Versions/2.7/lib/python2.7/site-packages/django/db/models/manager.py", line 131, in get
    return self.get_query_set().get(*args, **kwargs)
  File "/Library/Frameworks/Python.framework/Versions/2.7/lib/python2.7/site-packages/django/db/models/query.py", line 361, in get
    num = len(clone)
  File "/Library/Frameworks/Python.framework/Versions/2.7/lib/python2.7/site-packages/django/db/models/query.py", line 85, in __len__
    self._result_cache = list(self.iterator())
  File "/Library/Frameworks/Python.framework/Versions/2.7/lib/python2.7/site-packages/django/db/models/query.py", line 291, in iterator
    for row in compiler.results_iter():
  File "/Library/Frameworks/Python.framework/Versions/2.7/lib/python2.7/site-packages/django/db/models/sql/compiler.py", line 763, in results_iter
    for rows in self.execute_sql(MULTI):
  File "/Library/Frameworks/Python.framework/Versions/2.7/lib/python2.7/site-packages/django/db/models/sql/compiler.py", line 817, in execute_sql
    cursor = self.connection.cursor()
  File "/Library/Frameworks/Python.framework/Versions/2.7/lib/python2.7/site-packages/django/db/backends/__init__.py", line 306, in cursor
    cursor = self.make_debug_cursor(self._cursor())
  File "/Library/Frameworks/Python.framework/Versions/2.7/lib/python2.7/site-packages/django/db/backends/mysql/base.py", line 387, in _cursor
    self.connection = Database.connect(**kwargs)
  File "/Users/joshblum/Library/Python/2.7/lib/python/site-packages/MySQLdb/__init__.py", line 81, in Connect
    return Connection(*args, **kwargs)
  File "/Users/joshblum/Library/Python/2.7/lib/python/site-packages/MySQLdb/connections.py", line 187, in __init__
    super(Connection, self).__init__(*args, **kwargs2)
OperationalError: (2013, "Lost connection to MySQL server at 'reading initial communication packet', system error: 54")
Internal Server Error: /users/kanter/
Traceback (most recent call last):
  File "/Library/Frameworks/Python.framework/Versions/2.7/lib/python2.7/site-packages/django/core/handlers/base.py", line 111, in get_response
    response = callback(request, *callback_args, **callback_kwargs)
  File "/Library/Frameworks/Python.framework/Versions/2.7/lib/python2.7/site-packages/django/contrib/auth/decorators.py", line 20, in _wrapped_view
    return view_func(request, *args, **kwargs)
  File "/Users/joshblum/Desktop/Dropbox/code/comm.prod/commProd/views.py", line 113, in profile
    page_username = getUsername(user)
  File "/Users/joshblum/Desktop/Dropbox/code/comm.prod/commProd/views.py", line 208, in getUsername
    potentials = json.loads(user.profile.shirt_names)
  File "/Library/Frameworks/Python.framework/Versions/2.7/lib/python2.7/site-packages/simplejson/__init__.py", line 451, in loads
    return _default_decoder.decode(s)
  File "/Library/Frameworks/Python.framework/Versions/2.7/lib/python2.7/site-packages/simplejson/decoder.py", line 402, in decode
    obj, end = self.raw_decode(s, idx=_w(s, 0).end())
  File "/Library/Frameworks/Python.framework/Versions/2.7/lib/python2.7/site-packages/simplejson/decoder.py", line 420, in raw_decode
    raise JSONDecodeError("No JSON object could be decoded", s, idx)
JSONDecodeError: No JSON object could be decoded: line 1 column 0 (char 0)
Internal Server Error: /
Traceback (most recent call last):
  File "/Library/Frameworks/Python.framework/Versions/2.7/lib/python2.7/site-packages/django/core/handlers/base.py", line 101, in get_response
    request.path_info)
  File "/Library/Frameworks/Python.framework/Versions/2.7/lib/python2.7/site-packages/django/core/urlresolvers.py", line 300, in resolve
    sub_match = pattern.resolve(new_path)
  File "/Library/Frameworks/Python.framework/Versions/2.7/lib/python2.7/site-packages/django/core/urlresolvers.py", line 300, in resolve
    sub_match = pattern.resolve(new_path)
  File "/Library/Frameworks/Python.framework/Versions/2.7/lib/python2.7/site-packages/django/core/urlresolvers.py", line 209, in resolve
    return ResolverMatch(self.callback, args, kwargs, self.name)
  File "/Library/Frameworks/Python.framework/Versions/2.7/lib/python2.7/site-packages/django/core/urlresolvers.py", line 216, in callback
    self._callback = get_callable(self._callback_str)
  File "/Library/Frameworks/Python.framework/Versions/2.7/lib/python2.7/site-packages/django/utils/functional.py", line 27, in wrapper
    result = func(*args)
  File "/Library/Frameworks/Python.framework/Versions/2.7/lib/python2.7/site-packages/django/core/urlresolvers.py", line 92, in get_callable
    lookup_view = getattr(import_module(mod_name), func_name)
  File "/Library/Frameworks/Python.framework/Versions/2.7/lib/python2.7/site-packages/django/utils/importlib.py", line 35, in import_module
    __import__(name)
  File "/Users/joshblum/Desktop/Dropbox/code/comm.prod/commProd/views.py", line 266
    return render_to_response('hero_msg_template.html',
                                                      ^
IndentationError: unindent does not match any outer indentation level
Internal Server Error: /
Traceback (most recent call last):
  File "/Library/Frameworks/Python.framework/Versions/2.7/lib/python2.7/site-packages/django/core/handlers/base.py", line 101, in get_response
    request.path_info)
  File "/Library/Frameworks/Python.framework/Versions/2.7/lib/python2.7/site-packages/django/core/urlresolvers.py", line 300, in resolve
    sub_match = pattern.resolve(new_path)
  File "/Library/Frameworks/Python.framework/Versions/2.7/lib/python2.7/site-packages/django/core/urlresolvers.py", line 300, in resolve
    sub_match = pattern.resolve(new_path)
  File "/Library/Frameworks/Python.framework/Versions/2.7/lib/python2.7/site-packages/django/core/urlresolvers.py", line 209, in resolve
    return ResolverMatch(self.callback, args, kwargs, self.name)
  File "/Library/Frameworks/Python.framework/Versions/2.7/lib/python2.7/site-packages/django/core/urlresolvers.py", line 216, in callback
    self._callback = get_callable(self._callback_str)
  File "/Library/Frameworks/Python.framework/Versions/2.7/lib/python2.7/site-packages/django/utils/functional.py", line 27, in wrapper
    result = func(*args)
  File "/Library/Frameworks/Python.framework/Versions/2.7/lib/python2.7/site-packages/django/core/urlresolvers.py", line 92, in get_callable
    lookup_view = getattr(import_module(mod_name), func_name)
  File "/Library/Frameworks/Python.framework/Versions/2.7/lib/python2.7/site-packages/django/utils/importlib.py", line 35, in import_module
    __import__(name)
  File "/Users/joshblum/Desktop/Dropbox/code/comm.prod/commProd/views.py", line 265
    return render_to_response('hero_msg_template.html',
                                                      ^
IndentationError: unindent does not match any outer indentation level
Internal Server Error: /
Traceback (most recent call last):
  File "/Library/Frameworks/Python.framework/Versions/2.7/lib/python2.7/site-packages/django/core/handlers/base.py", line 101, in get_response
    request.path_info)
  File "/Library/Frameworks/Python.framework/Versions/2.7/lib/python2.7/site-packages/django/core/urlresolvers.py", line 300, in resolve
    sub_match = pattern.resolve(new_path)
  File "/Library/Frameworks/Python.framework/Versions/2.7/lib/python2.7/site-packages/django/core/urlresolvers.py", line 300, in resolve
    sub_match = pattern.resolve(new_path)
  File "/Library/Frameworks/Python.framework/Versions/2.7/lib/python2.7/site-packages/django/core/urlresolvers.py", line 209, in resolve
    return ResolverMatch(self.callback, args, kwargs, self.name)
  File "/Library/Frameworks/Python.framework/Versions/2.7/lib/python2.7/site-packages/django/core/urlresolvers.py", line 216, in callback
    self._callback = get_callable(self._callback_str)
  File "/Library/Frameworks/Python.framework/Versions/2.7/lib/python2.7/site-packages/django/utils/functional.py", line 27, in wrapper
    result = func(*args)
  File "/Library/Frameworks/Python.framework/Versions/2.7/lib/python2.7/site-packages/django/core/urlresolvers.py", line 92, in get_callable
    lookup_view = getattr(import_module(mod_name), func_name)
  File "/Library/Frameworks/Python.framework/Versions/2.7/lib/python2.7/site-packages/django/utils/importlib.py", line 35, in import_module
    __import__(name)
  File "/Users/joshblum/Desktop/Dropbox/code/comm.prod/commProd/views.py", line 265
    return render_to_response('hero_msg_template.html',
                                                      ^
IndentationError: unindent does not match any outer indentation level
Internal Server Error: /register/f3c784cc6f1b7101c69195eac98bfcee61477ccf/
Traceback (most recent call last):
  File "/Library/Frameworks/Python.framework/Versions/2.7/lib/python2.7/site-packages/django/core/handlers/base.py", line 111, in get_response
    response = callback(request, *callback_args, **callback_kwargs)
  File "/Library/Frameworks/Python.framework/Versions/2.7/lib/python2.7/site-packages/django/views/decorators/csrf.py", line 77, in wrapped_view
    return view_func(*args, **kwargs)
  File "/Users/joshblum/Desktop/Dropbox/code/comm.prod/commProd/views.py", line 35, in register
    return renderErrorMessage(page_title, hero_title, paragraphlist)
  File "/Users/joshblum/Desktop/Dropbox/code/comm.prod/commProd/views.py", line 265, in renderErrorMessage
    return render_to_response('hero_msg_template.html', template_values, context_instance=RequestContext(request))
NameError: global name 'request' is not defined
Internal Server Error: /register/f3c784cc6f1b7101c69195eac98bfcee61477ccf/
Traceback (most recent call last):
  File "/Library/Frameworks/Python.framework/Versions/2.7/lib/python2.7/site-packages/django/core/handlers/base.py", line 111, in get_response
    response = callback(request, *callback_args, **callback_kwargs)
  File "/Library/Frameworks/Python.framework/Versions/2.7/lib/python2.7/site-packages/django/views/decorators/csrf.py", line 77, in wrapped_view
    return view_func(*args, **kwargs)
  File "/Users/joshblum/Desktop/Dropbox/code/comm.prod/commProd/views.py", line 31, in register
    return renderErrorMessage(request, page_title, hero_title)
  File "/Users/joshblum/Desktop/Dropbox/code/comm.prod/commProd/views.py", line 247, in renderErrorMessage
    template_values, context_instance=RequestContext(request))
  File "/Library/Frameworks/Python.framework/Versions/2.7/lib/python2.7/site-packages/django/shortcuts/__init__.py", line 20, in render_to_response
    return HttpResponse(loader.render_to_string(*args, **kwargs), **httpresponse_kwargs)
  File "/Library/Frameworks/Python.framework/Versions/2.7/lib/python2.7/site-packages/django/template/loader.py", line 176, in render_to_string
    return t.render(context_instance)
  File "/Library/Frameworks/Python.framework/Versions/2.7/lib/python2.7/site-packages/django/template/base.py", line 140, in render
    return self._render(context)
  File "/Library/Frameworks/Python.framework/Versions/2.7/lib/python2.7/site-packages/django/template/base.py", line 134, in _render
    return self.nodelist.render(context)
  File "/Library/Frameworks/Python.framework/Versions/2.7/lib/python2.7/site-packages/django/template/base.py", line 823, in render
    bit = self.render_node(node, context)
  File "/Library/Frameworks/Python.framework/Versions/2.7/lib/python2.7/site-packages/django/template/debug.py", line 74, in render_node
    return node.render(context)
  File "/Library/Frameworks/Python.framework/Versions/2.7/lib/python2.7/site-packages/django/template/loader_tags.py", line 123, in render
    return compiled_parent._render(context)
  File "/Library/Frameworks/Python.framework/Versions/2.7/lib/python2.7/site-packages/django/template/base.py", line 134, in _render
    return self.nodelist.render(context)
  File "/Library/Frameworks/Python.framework/Versions/2.7/lib/python2.7/site-packages/django/template/base.py", line 823, in render
    bit = self.render_node(node, context)
  File "/Library/Frameworks/Python.framework/Versions/2.7/lib/python2.7/site-packages/django/template/debug.py", line 74, in render_node
    return node.render(context)
  File "/Library/Frameworks/Python.framework/Versions/2.7/lib/python2.7/site-packages/django/template/defaulttags.py", line 281, in render
    return nodelist.render(context)
  File "/Library/Frameworks/Python.framework/Versions/2.7/lib/python2.7/site-packages/django/template/base.py", line 823, in render
    bit = self.render_node(node, context)
  File "/Library/Frameworks/Python.framework/Versions/2.7/lib/python2.7/site-packages/django/template/debug.py", line 74, in render_node
    return node.render(context)
  File "/Library/Frameworks/Python.framework/Versions/2.7/lib/python2.7/site-packages/django/template/defaulttags.py", line 411, in render
    url = reverse(view_name, args=args, kwargs=kwargs, current_app=context.current_app)
  File "/Library/Frameworks/Python.framework/Versions/2.7/lib/python2.7/site-packages/django/core/urlresolvers.py", line 476, in reverse
    return iri_to_uri(resolver._reverse_with_prefix(view, prefix, *args, **kwargs))
  File "/Library/Frameworks/Python.framework/Versions/2.7/lib/python2.7/site-packages/django/core/urlresolvers.py", line 363, in _reverse_with_prefix
    possibilities = self.reverse_dict.getlist(lookup_view)
  File "/Library/Frameworks/Python.framework/Versions/2.7/lib/python2.7/site-packages/django/core/urlresolvers.py", line 276, in reverse_dict
    self._populate()
  File "/Library/Frameworks/Python.framework/Versions/2.7/lib/python2.7/site-packages/django/core/urlresolvers.py", line 253, in _populate
    for name in pattern.reverse_dict:
  File "/Library/Frameworks/Python.framework/Versions/2.7/lib/python2.7/site-packages/django/core/urlresolvers.py", line 276, in reverse_dict
    self._populate()
  File "/Library/Frameworks/Python.framework/Versions/2.7/lib/python2.7/site-packages/django/core/urlresolvers.py", line 265, in _populate
    lookups.appendlist(pattern.callback, (bits, p_pattern, pattern.default_args))
  File "/Library/Frameworks/Python.framework/Versions/2.7/lib/python2.7/site-packages/django/core/urlresolvers.py", line 216, in callback
    self._callback = get_callable(self._callback_str)
  File "/Library/Frameworks/Python.framework/Versions/2.7/lib/python2.7/site-packages/django/utils/functional.py", line 27, in wrapper
    result = func(*args)
  File "/Library/Frameworks/Python.framework/Versions/2.7/lib/python2.7/site-packages/django/core/urlresolvers.py", line 101, in get_callable
    (lookup_view, mod_name))
ViewDoesNotExist: Could not import commProd.views.invalid_reg. View does not exist in module commProd.views.
Internal Server Error: /register/f3c784cc6f1b7101c69195eac98bfcee61477ccf/
Traceback (most recent call last):
  File "/Library/Frameworks/Python.framework/Versions/2.7/lib/python2.7/site-packages/django/core/handlers/base.py", line 111, in get_response
    response = callback(request, *callback_args, **callback_kwargs)
  File "/Library/Frameworks/Python.framework/Versions/2.7/lib/python2.7/site-packages/django/views/decorators/csrf.py", line 77, in wrapped_view
    return view_func(*args, **kwargs)
  File "/Users/joshblum/Desktop/Dropbox/code/comm.prod/commProd/views.py", line 31, in register
    return renderErrorMessage(request, page_title, hero_title)
  File "/Users/joshblum/Desktop/Dropbox/code/comm.prod/commProd/views.py", line 247, in renderErrorMessage
    template_values, context_instance=RequestContext(request))
  File "/Library/Frameworks/Python.framework/Versions/2.7/lib/python2.7/site-packages/django/shortcuts/__init__.py", line 20, in render_to_response
    return HttpResponse(loader.render_to_string(*args, **kwargs), **httpresponse_kwargs)
  File "/Library/Frameworks/Python.framework/Versions/2.7/lib/python2.7/site-packages/django/template/loader.py", line 176, in render_to_string
    return t.render(context_instance)
  File "/Library/Frameworks/Python.framework/Versions/2.7/lib/python2.7/site-packages/django/template/base.py", line 140, in render
    return self._render(context)
  File "/Library/Frameworks/Python.framework/Versions/2.7/lib/python2.7/site-packages/django/template/base.py", line 134, in _render
    return self.nodelist.render(context)
  File "/Library/Frameworks/Python.framework/Versions/2.7/lib/python2.7/site-packages/django/template/base.py", line 823, in render
    bit = self.render_node(node, context)
  File "/Library/Frameworks/Python.framework/Versions/2.7/lib/python2.7/site-packages/django/template/debug.py", line 74, in render_node
    return node.render(context)
  File "/Library/Frameworks/Python.framework/Versions/2.7/lib/python2.7/site-packages/django/template/loader_tags.py", line 123, in render
    return compiled_parent._render(context)
  File "/Library/Frameworks/Python.framework/Versions/2.7/lib/python2.7/site-packages/django/template/base.py", line 134, in _render
    return self.nodelist.render(context)
  File "/Library/Frameworks/Python.framework/Versions/2.7/lib/python2.7/site-packages/django/template/base.py", line 823, in render
    bit = self.render_node(node, context)
  File "/Library/Frameworks/Python.framework/Versions/2.7/lib/python2.7/site-packages/django/template/debug.py", line 74, in render_node
    return node.render(context)
  File "/Library/Frameworks/Python.framework/Versions/2.7/lib/python2.7/site-packages/django/template/defaulttags.py", line 281, in render
    return nodelist.render(context)
  File "/Library/Frameworks/Python.framework/Versions/2.7/lib/python2.7/site-packages/django/template/base.py", line 823, in render
    bit = self.render_node(node, context)
  File "/Library/Frameworks/Python.framework/Versions/2.7/lib/python2.7/site-packages/django/template/debug.py", line 74, in render_node
    return node.render(context)
  File "/Library/Frameworks/Python.framework/Versions/2.7/lib/python2.7/site-packages/django/template/defaulttags.py", line 411, in render
    url = reverse(view_name, args=args, kwargs=kwargs, current_app=context.current_app)
  File "/Library/Frameworks/Python.framework/Versions/2.7/lib/python2.7/site-packages/django/core/urlresolvers.py", line 476, in reverse
    return iri_to_uri(resolver._reverse_with_prefix(view, prefix, *args, **kwargs))
  File "/Library/Frameworks/Python.framework/Versions/2.7/lib/python2.7/site-packages/django/core/urlresolvers.py", line 363, in _reverse_with_prefix
    possibilities = self.reverse_dict.getlist(lookup_view)
  File "/Library/Frameworks/Python.framework/Versions/2.7/lib/python2.7/site-packages/django/core/urlresolvers.py", line 276, in reverse_dict
    self._populate()
  File "/Library/Frameworks/Python.framework/Versions/2.7/lib/python2.7/site-packages/django/core/urlresolvers.py", line 253, in _populate
    for name in pattern.reverse_dict:
  File "/Library/Frameworks/Python.framework/Versions/2.7/lib/python2.7/site-packages/django/core/urlresolvers.py", line 276, in reverse_dict
    self._populate()
  File "/Library/Frameworks/Python.framework/Versions/2.7/lib/python2.7/site-packages/django/core/urlresolvers.py", line 265, in _populate
    lookups.appendlist(pattern.callback, (bits, p_pattern, pattern.default_args))
  File "/Library/Frameworks/Python.framework/Versions/2.7/lib/python2.7/site-packages/django/core/urlresolvers.py", line 216, in callback
    self._callback = get_callable(self._callback_str)
  File "/Library/Frameworks/Python.framework/Versions/2.7/lib/python2.7/site-packages/django/utils/functional.py", line 27, in wrapper
    result = func(*args)
  File "/Library/Frameworks/Python.framework/Versions/2.7/lib/python2.7/site-packages/django/core/urlresolvers.py", line 101, in get_callable
    (lookup_view, mod_name))
ViewDoesNotExist: Could not import commProd.views.invalid_reg. View does not exist in module commProd.views.
Internal Server Error: /register/f3c784cc6f1b7101c69195eac98bfcee61477ccf/
Traceback (most recent call last):
  File "/Library/Frameworks/Python.framework/Versions/2.7/lib/python2.7/site-packages/django/core/handlers/base.py", line 111, in get_response
    response = callback(request, *callback_args, **callback_kwargs)
  File "/Library/Frameworks/Python.framework/Versions/2.7/lib/python2.7/site-packages/django/views/decorators/csrf.py", line 77, in wrapped_view
    return view_func(*args, **kwargs)
  File "/Users/joshblum/Desktop/Dropbox/code/comm.prod/commProd/views.py", line 28, in register
    if request.user.is_authenticated:
  File "/Library/Frameworks/Python.framework/Versions/2.7/lib/python2.7/site-packages/django/utils/functional.py", line 184, in inner
    self._setup()
  File "/Library/Frameworks/Python.framework/Versions/2.7/lib/python2.7/site-packages/django/utils/functional.py", line 248, in _setup
    self._wrapped = self._setupfunc()
  File "/Library/Frameworks/Python.framework/Versions/2.7/lib/python2.7/site-packages/django/contrib/auth/middleware.py", line 16, in <lambda>
    request.user = SimpleLazyObject(lambda: get_user(request))
  File "/Library/Frameworks/Python.framework/Versions/2.7/lib/python2.7/site-packages/django/contrib/auth/middleware.py", line 8, in get_user
    request._cached_user = auth.get_user(request)
  File "/Library/Frameworks/Python.framework/Versions/2.7/lib/python2.7/site-packages/django/contrib/auth/__init__.py", line 98, in get_user
    user_id = request.session[SESSION_KEY]
  File "/Library/Frameworks/Python.framework/Versions/2.7/lib/python2.7/site-packages/django/contrib/sessions/backends/base.py", line 39, in __getitem__
    return self._session[key]
  File "/Library/Frameworks/Python.framework/Versions/2.7/lib/python2.7/site-packages/django/contrib/sessions/backends/base.py", line 165, in _get_session
    self._session_cache = self.load()
  File "/Library/Frameworks/Python.framework/Versions/2.7/lib/python2.7/site-packages/django/contrib/sessions/backends/db.py", line 19, in load
    expire_date__gt=timezone.now()
  File "/Library/Frameworks/Python.framework/Versions/2.7/lib/python2.7/site-packages/django/db/models/manager.py", line 131, in get
    return self.get_query_set().get(*args, **kwargs)
  File "/Library/Frameworks/Python.framework/Versions/2.7/lib/python2.7/site-packages/django/db/models/query.py", line 361, in get
    num = len(clone)
  File "/Library/Frameworks/Python.framework/Versions/2.7/lib/python2.7/site-packages/django/db/models/query.py", line 85, in __len__
    self._result_cache = list(self.iterator())
  File "/Library/Frameworks/Python.framework/Versions/2.7/lib/python2.7/site-packages/django/db/models/query.py", line 291, in iterator
    for row in compiler.results_iter():
  File "/Library/Frameworks/Python.framework/Versions/2.7/lib/python2.7/site-packages/django/db/models/sql/compiler.py", line 763, in results_iter
    for rows in self.execute_sql(MULTI):
  File "/Library/Frameworks/Python.framework/Versions/2.7/lib/python2.7/site-packages/django/db/models/sql/compiler.py", line 817, in execute_sql
    cursor = self.connection.cursor()
  File "/Library/Frameworks/Python.framework/Versions/2.7/lib/python2.7/site-packages/django/db/backends/__init__.py", line 306, in cursor
    cursor = self.make_debug_cursor(self._cursor())
  File "/Library/Frameworks/Python.framework/Versions/2.7/lib/python2.7/site-packages/django/db/backends/mysql/base.py", line 387, in _cursor
    self.connection = Database.connect(**kwargs)
  File "/Users/joshblum/Library/Python/2.7/lib/python/site-packages/MySQLdb/__init__.py", line 81, in Connect
    return Connection(*args, **kwargs)
  File "/Users/joshblum/Library/Python/2.7/lib/python/site-packages/MySQLdb/connections.py", line 187, in __init__
    super(Connection, self).__init__(*args, **kwargs2)
OperationalError: (2003, "Can't connect to MySQL server on 'sql.mit.edu' (60)")
Internal Server Error: /register/f3c784cc6f1b7101c69195eac98bfcee61477ccf/
Traceback (most recent call last):
  File "/Library/Frameworks/Python.framework/Versions/2.7/lib/python2.7/site-packages/django/core/handlers/base.py", line 111, in get_response
    response = callback(request, *callback_args, **callback_kwargs)
  File "/Library/Frameworks/Python.framework/Versions/2.7/lib/python2.7/site-packages/django/views/decorators/csrf.py", line 77, in wrapped_view
    return view_func(*args, **kwargs)
  File "/Users/joshblum/Desktop/Dropbox/code/comm.prod/commProd/views.py", line 31, in register
    return renderErrorMessage(request, page_title, hero_title)
  File "/Users/joshblum/Desktop/Dropbox/code/comm.prod/commProd/views.py", line 247, in renderErrorMessage
    template_values, context_instance=RequestContext(request))
  File "/Library/Frameworks/Python.framework/Versions/2.7/lib/python2.7/site-packages/django/shortcuts/__init__.py", line 20, in render_to_response
    return HttpResponse(loader.render_to_string(*args, **kwargs), **httpresponse_kwargs)
  File "/Library/Frameworks/Python.framework/Versions/2.7/lib/python2.7/site-packages/django/template/loader.py", line 176, in render_to_string
    return t.render(context_instance)
  File "/Library/Frameworks/Python.framework/Versions/2.7/lib/python2.7/site-packages/django/template/base.py", line 140, in render
    return self._render(context)
  File "/Library/Frameworks/Python.framework/Versions/2.7/lib/python2.7/site-packages/django/template/base.py", line 134, in _render
    return self.nodelist.render(context)
  File "/Library/Frameworks/Python.framework/Versions/2.7/lib/python2.7/site-packages/django/template/base.py", line 823, in render
    bit = self.render_node(node, context)
  File "/Library/Frameworks/Python.framework/Versions/2.7/lib/python2.7/site-packages/django/template/debug.py", line 74, in render_node
    return node.render(context)
  File "/Library/Frameworks/Python.framework/Versions/2.7/lib/python2.7/site-packages/django/template/loader_tags.py", line 123, in render
    return compiled_parent._render(context)
  File "/Library/Frameworks/Python.framework/Versions/2.7/lib/python2.7/site-packages/django/template/base.py", line 134, in _render
    return self.nodelist.render(context)
  File "/Library/Frameworks/Python.framework/Versions/2.7/lib/python2.7/site-packages/django/template/base.py", line 823, in render
    bit = self.render_node(node, context)
  File "/Library/Frameworks/Python.framework/Versions/2.7/lib/python2.7/site-packages/django/template/debug.py", line 74, in render_node
    return node.render(context)
  File "/Library/Frameworks/Python.framework/Versions/2.7/lib/python2.7/site-packages/django/template/defaulttags.py", line 281, in render
    return nodelist.render(context)
  File "/Library/Frameworks/Python.framework/Versions/2.7/lib/python2.7/site-packages/django/template/base.py", line 823, in render
    bit = self.render_node(node, context)
  File "/Library/Frameworks/Python.framework/Versions/2.7/lib/python2.7/site-packages/django/template/debug.py", line 74, in render_node
    return node.render(context)
  File "/Library/Frameworks/Python.framework/Versions/2.7/lib/python2.7/site-packages/django/template/defaulttags.py", line 411, in render
    url = reverse(view_name, args=args, kwargs=kwargs, current_app=context.current_app)
  File "/Library/Frameworks/Python.framework/Versions/2.7/lib/python2.7/site-packages/django/core/urlresolvers.py", line 476, in reverse
    return iri_to_uri(resolver._reverse_with_prefix(view, prefix, *args, **kwargs))
  File "/Library/Frameworks/Python.framework/Versions/2.7/lib/python2.7/site-packages/django/core/urlresolvers.py", line 363, in _reverse_with_prefix
    possibilities = self.reverse_dict.getlist(lookup_view)
  File "/Library/Frameworks/Python.framework/Versions/2.7/lib/python2.7/site-packages/django/core/urlresolvers.py", line 276, in reverse_dict
    self._populate()
  File "/Library/Frameworks/Python.framework/Versions/2.7/lib/python2.7/site-packages/django/core/urlresolvers.py", line 253, in _populate
    for name in pattern.reverse_dict:
  File "/Library/Frameworks/Python.framework/Versions/2.7/lib/python2.7/site-packages/django/core/urlresolvers.py", line 276, in reverse_dict
    self._populate()
  File "/Library/Frameworks/Python.framework/Versions/2.7/lib/python2.7/site-packages/django/core/urlresolvers.py", line 265, in _populate
    lookups.appendlist(pattern.callback, (bits, p_pattern, pattern.default_args))
  File "/Library/Frameworks/Python.framework/Versions/2.7/lib/python2.7/site-packages/django/core/urlresolvers.py", line 216, in callback
    self._callback = get_callable(self._callback_str)
  File "/Library/Frameworks/Python.framework/Versions/2.7/lib/python2.7/site-packages/django/utils/functional.py", line 27, in wrapper
    result = func(*args)
  File "/Library/Frameworks/Python.framework/Versions/2.7/lib/python2.7/site-packages/django/core/urlresolvers.py", line 101, in get_callable
    (lookup_view, mod_name))
ViewDoesNotExist: Could not import commProd.views.invalid_reg. View does not exist in module commProd.views.
Internal Server Error: /register/f3c784cc6f1b7101c69195eac98bfcee61477ccf/
Traceback (most recent call last):
  File "/Library/Frameworks/Python.framework/Versions/2.7/lib/python2.7/site-packages/django/core/handlers/base.py", line 111, in get_response
    response = callback(request, *callback_args, **callback_kwargs)
  File "/Library/Frameworks/Python.framework/Versions/2.7/lib/python2.7/site-packages/django/views/decorators/csrf.py", line 77, in wrapped_view
    return view_func(*args, **kwargs)
  File "/Users/joshblum/Desktop/Dropbox/code/comm.prod/commProd/views.py", line 28, in register
    if request.user.is_authenticated:
  File "/Library/Frameworks/Python.framework/Versions/2.7/lib/python2.7/site-packages/django/utils/functional.py", line 184, in inner
    self._setup()
  File "/Library/Frameworks/Python.framework/Versions/2.7/lib/python2.7/site-packages/django/utils/functional.py", line 248, in _setup
    self._wrapped = self._setupfunc()
  File "/Library/Frameworks/Python.framework/Versions/2.7/lib/python2.7/site-packages/django/contrib/auth/middleware.py", line 16, in <lambda>
    request.user = SimpleLazyObject(lambda: get_user(request))
  File "/Library/Frameworks/Python.framework/Versions/2.7/lib/python2.7/site-packages/django/contrib/auth/middleware.py", line 8, in get_user
    request._cached_user = auth.get_user(request)
  File "/Library/Frameworks/Python.framework/Versions/2.7/lib/python2.7/site-packages/django/contrib/auth/__init__.py", line 98, in get_user
    user_id = request.session[SESSION_KEY]
  File "/Library/Frameworks/Python.framework/Versions/2.7/lib/python2.7/site-packages/django/contrib/sessions/backends/base.py", line 39, in __getitem__
    return self._session[key]
  File "/Library/Frameworks/Python.framework/Versions/2.7/lib/python2.7/site-packages/django/contrib/sessions/backends/base.py", line 165, in _get_session
    self._session_cache = self.load()
  File "/Library/Frameworks/Python.framework/Versions/2.7/lib/python2.7/site-packages/django/contrib/sessions/backends/db.py", line 19, in load
    expire_date__gt=timezone.now()
  File "/Library/Frameworks/Python.framework/Versions/2.7/lib/python2.7/site-packages/django/db/models/manager.py", line 131, in get
    return self.get_query_set().get(*args, **kwargs)
  File "/Library/Frameworks/Python.framework/Versions/2.7/lib/python2.7/site-packages/django/db/models/query.py", line 361, in get
    num = len(clone)
  File "/Library/Frameworks/Python.framework/Versions/2.7/lib/python2.7/site-packages/django/db/models/query.py", line 85, in __len__
    self._result_cache = list(self.iterator())
  File "/Library/Frameworks/Python.framework/Versions/2.7/lib/python2.7/site-packages/django/db/models/query.py", line 291, in iterator
    for row in compiler.results_iter():
  File "/Library/Frameworks/Python.framework/Versions/2.7/lib/python2.7/site-packages/django/db/models/sql/compiler.py", line 763, in results_iter
    for rows in self.execute_sql(MULTI):
  File "/Library/Frameworks/Python.framework/Versions/2.7/lib/python2.7/site-packages/django/db/models/sql/compiler.py", line 817, in execute_sql
    cursor = self.connection.cursor()
  File "/Library/Frameworks/Python.framework/Versions/2.7/lib/python2.7/site-packages/django/db/backends/__init__.py", line 306, in cursor
    cursor = self.make_debug_cursor(self._cursor())
  File "/Library/Frameworks/Python.framework/Versions/2.7/lib/python2.7/site-packages/django/db/backends/mysql/base.py", line 387, in _cursor
    self.connection = Database.connect(**kwargs)
  File "/Users/joshblum/Library/Python/2.7/lib/python/site-packages/MySQLdb/__init__.py", line 81, in Connect
    return Connection(*args, **kwargs)
  File "/Users/joshblum/Library/Python/2.7/lib/python/site-packages/MySQLdb/connections.py", line 187, in __init__
    super(Connection, self).__init__(*args, **kwargs2)
OperationalError: (2003, "Can't connect to MySQL server on 'sql.mit.edu' (60)")
Internal Server Error: /register/f3c784cc6f1b7101c69195eac98bfcee61477ccf/
Traceback (most recent call last):
  File "/Library/Frameworks/Python.framework/Versions/2.7/lib/python2.7/site-packages/django/core/handlers/base.py", line 111, in get_response
    response = callback(request, *callback_args, **callback_kwargs)
  File "/Library/Frameworks/Python.framework/Versions/2.7/lib/python2.7/site-packages/django/views/decorators/csrf.py", line 77, in wrapped_view
    return view_func(*args, **kwargs)
  File "/Users/joshblum/Desktop/Dropbox/code/comm.prod/commProd/views.py", line 28, in register
    if request.user.is_authenticated:
  File "/Library/Frameworks/Python.framework/Versions/2.7/lib/python2.7/site-packages/django/utils/functional.py", line 184, in inner
    self._setup()
  File "/Library/Frameworks/Python.framework/Versions/2.7/lib/python2.7/site-packages/django/utils/functional.py", line 248, in _setup
    self._wrapped = self._setupfunc()
  File "/Library/Frameworks/Python.framework/Versions/2.7/lib/python2.7/site-packages/django/contrib/auth/middleware.py", line 16, in <lambda>
    request.user = SimpleLazyObject(lambda: get_user(request))
  File "/Library/Frameworks/Python.framework/Versions/2.7/lib/python2.7/site-packages/django/contrib/auth/middleware.py", line 8, in get_user
    request._cached_user = auth.get_user(request)
  File "/Library/Frameworks/Python.framework/Versions/2.7/lib/python2.7/site-packages/django/contrib/auth/__init__.py", line 98, in get_user
    user_id = request.session[SESSION_KEY]
  File "/Library/Frameworks/Python.framework/Versions/2.7/lib/python2.7/site-packages/django/contrib/sessions/backends/base.py", line 39, in __getitem__
    return self._session[key]
  File "/Library/Frameworks/Python.framework/Versions/2.7/lib/python2.7/site-packages/django/contrib/sessions/backends/base.py", line 165, in _get_session
    self._session_cache = self.load()
  File "/Library/Frameworks/Python.framework/Versions/2.7/lib/python2.7/site-packages/django/contrib/sessions/backends/db.py", line 19, in load
    expire_date__gt=timezone.now()
  File "/Library/Frameworks/Python.framework/Versions/2.7/lib/python2.7/site-packages/django/db/models/manager.py", line 131, in get
    return self.get_query_set().get(*args, **kwargs)
  File "/Library/Frameworks/Python.framework/Versions/2.7/lib/python2.7/site-packages/django/db/models/query.py", line 361, in get
    num = len(clone)
  File "/Library/Frameworks/Python.framework/Versions/2.7/lib/python2.7/site-packages/django/db/models/query.py", line 85, in __len__
    self._result_cache = list(self.iterator())
  File "/Library/Frameworks/Python.framework/Versions/2.7/lib/python2.7/site-packages/django/db/models/query.py", line 291, in iterator
    for row in compiler.results_iter():
  File "/Library/Frameworks/Python.framework/Versions/2.7/lib/python2.7/site-packages/django/db/models/sql/compiler.py", line 763, in results_iter
    for rows in self.execute_sql(MULTI):
  File "/Library/Frameworks/Python.framework/Versions/2.7/lib/python2.7/site-packages/django/db/models/sql/compiler.py", line 817, in execute_sql
    cursor = self.connection.cursor()
  File "/Library/Frameworks/Python.framework/Versions/2.7/lib/python2.7/site-packages/django/db/backends/__init__.py", line 306, in cursor
    cursor = self.make_debug_cursor(self._cursor())
  File "/Library/Frameworks/Python.framework/Versions/2.7/lib/python2.7/site-packages/django/db/backends/mysql/base.py", line 387, in _cursor
    self.connection = Database.connect(**kwargs)
  File "/Users/joshblum/Library/Python/2.7/lib/python/site-packages/MySQLdb/__init__.py", line 81, in Connect
    return Connection(*args, **kwargs)
  File "/Users/joshblum/Library/Python/2.7/lib/python/site-packages/MySQLdb/connections.py", line 187, in __init__
    super(Connection, self).__init__(*args, **kwargs2)
OperationalError: (2003, "Can't connect to MySQL server on 'sql.mit.edu' (60)")
Internal Server Error: /register/f3c784cc6f1b7101c69195eac98bfcee61477ccf/
Traceback (most recent call last):
  File "/Library/Frameworks/Python.framework/Versions/2.7/lib/python2.7/site-packages/django/core/handlers/base.py", line 111, in get_response
    response = callback(request, *callback_args, **callback_kwargs)
  File "/Library/Frameworks/Python.framework/Versions/2.7/lib/python2.7/site-packages/django/views/decorators/csrf.py", line 77, in wrapped_view
    return view_func(*args, **kwargs)
  File "/Users/joshblum/Desktop/Dropbox/code/comm.prod/commProd/views.py", line 37, in register
    page_title = "Oops"
  File "/Library/Frameworks/Python.framework/Versions/2.7/lib/python2.7/site-packages/django/db/models/query.py", line 562, in exists
    return self.query.has_results(using=self.db)
  File "/Library/Frameworks/Python.framework/Versions/2.7/lib/python2.7/site-packages/django/db/models/sql/query.py", line 441, in has_results
    return bool(compiler.execute_sql(SINGLE))
  File "/Library/Frameworks/Python.framework/Versions/2.7/lib/python2.7/site-packages/django/db/models/sql/compiler.py", line 817, in execute_sql
    cursor = self.connection.cursor()
  File "/Library/Frameworks/Python.framework/Versions/2.7/lib/python2.7/site-packages/django/db/backends/__init__.py", line 306, in cursor
    cursor = self.make_debug_cursor(self._cursor())
  File "/Library/Frameworks/Python.framework/Versions/2.7/lib/python2.7/site-packages/django/db/backends/mysql/base.py", line 387, in _cursor
    self.connection = Database.connect(**kwargs)
  File "/Users/joshblum/Library/Python/2.7/lib/python/site-packages/MySQLdb/__init__.py", line 81, in Connect
    return Connection(*args, **kwargs)
  File "/Users/joshblum/Library/Python/2.7/lib/python/site-packages/MySQLdb/connections.py", line 187, in __init__
    super(Connection, self).__init__(*args, **kwargs2)
OperationalError: (2003, "Can't connect to MySQL server on 'sql.mit.edu' (60)")
<<<<<<< HEAD
>>>>>>> 49c8002f0bb07fe25116cba4727d3d00027408a8
=======
Internal Server Error: /register/f3c784cc6f1b7101c69195eac98bfcee61477ccf/
Traceback (most recent call last):
  File "/Library/Frameworks/Python.framework/Versions/2.7/lib/python2.7/site-packages/django/core/handlers/base.py", line 101, in get_response
    request.path_info)
  File "/Library/Frameworks/Python.framework/Versions/2.7/lib/python2.7/site-packages/django/core/urlresolvers.py", line 300, in resolve
    sub_match = pattern.resolve(new_path)
  File "/Library/Frameworks/Python.framework/Versions/2.7/lib/python2.7/site-packages/django/core/urlresolvers.py", line 300, in resolve
    sub_match = pattern.resolve(new_path)
  File "/Library/Frameworks/Python.framework/Versions/2.7/lib/python2.7/site-packages/django/core/urlresolvers.py", line 209, in resolve
    return ResolverMatch(self.callback, args, kwargs, self.name)
  File "/Library/Frameworks/Python.framework/Versions/2.7/lib/python2.7/site-packages/django/core/urlresolvers.py", line 216, in callback
    self._callback = get_callable(self._callback_str)
  File "/Library/Frameworks/Python.framework/Versions/2.7/lib/python2.7/site-packages/django/utils/functional.py", line 27, in wrapper
    result = func(*args)
  File "/Library/Frameworks/Python.framework/Versions/2.7/lib/python2.7/site-packages/django/core/urlresolvers.py", line 92, in get_callable
    lookup_view = getattr(import_module(mod_name), func_name)
  File "/Library/Frameworks/Python.framework/Versions/2.7/lib/python2.7/site-packages/django/utils/importlib.py", line 35, in import_module
    __import__(name)
  File "/Users/joshblum/Desktop/Dropbox/code/comm.prod/commProd/views.py", line 201
    return random.choice(potentials)-=
                                     ^
SyntaxError: invalid syntax
>>>>>>> 80b9c324808fefff584f6119b73f3e02f5c5f0d2
Internal Server Error: /login
Traceback (most recent call last):
  File "/Library/Frameworks/Python.framework/Versions/2.7/lib/python2.7/site-packages/django/core/handlers/base.py", line 111, in get_response
    response = callback(request, *callback_args, **callback_kwargs)
  File "/Library/Frameworks/Python.framework/Versions/2.7/lib/python2.7/site-packages/django/views/decorators/debug.py", line 69, in wrapper
    return view(request, *args, **kwargs)
  File "/Library/Frameworks/Python.framework/Versions/2.7/lib/python2.7/site-packages/django/utils/decorators.py", line 91, in _wrapped_view
    response = view_func(request, *args, **kwargs)
  File "/Library/Frameworks/Python.framework/Versions/2.7/lib/python2.7/site-packages/django/views/decorators/cache.py", line 89, in _wrapped_view_func
    response = view_func(request, *args, **kwargs)
  File "/Library/Frameworks/Python.framework/Versions/2.7/lib/python2.7/site-packages/django/contrib/auth/views.py", line 60, in login
    current_site = get_current_site(request)
  File "/Library/Frameworks/Python.framework/Versions/2.7/lib/python2.7/site-packages/django/contrib/sites/models.py", line 92, in get_current_site
    current_site = Site.objects.get_current()
  File "/Library/Frameworks/Python.framework/Versions/2.7/lib/python2.7/site-packages/django/contrib/sites/models.py", line 25, in get_current
    current_site = self.get(pk=sid)
  File "/Library/Frameworks/Python.framework/Versions/2.7/lib/python2.7/site-packages/django/db/models/manager.py", line 131, in get
    return self.get_query_set().get(*args, **kwargs)
  File "/Library/Frameworks/Python.framework/Versions/2.7/lib/python2.7/site-packages/django/db/models/query.py", line 366, in get
    % self.model._meta.object_name)
DoesNotExist: Site matching query does not exist.
Internal Server Error: /login
Traceback (most recent call last):
  File "/Library/Frameworks/Python.framework/Versions/2.7/lib/python2.7/site-packages/django/core/handlers/base.py", line 111, in get_response
    response = callback(request, *callback_args, **callback_kwargs)
  File "/Library/Frameworks/Python.framework/Versions/2.7/lib/python2.7/site-packages/django/views/decorators/debug.py", line 69, in wrapper
    return view(request, *args, **kwargs)
  File "/Library/Frameworks/Python.framework/Versions/2.7/lib/python2.7/site-packages/django/utils/decorators.py", line 91, in _wrapped_view
    response = view_func(request, *args, **kwargs)
  File "/Library/Frameworks/Python.framework/Versions/2.7/lib/python2.7/site-packages/django/views/decorators/cache.py", line 89, in _wrapped_view_func
    response = view_func(request, *args, **kwargs)
  File "/Library/Frameworks/Python.framework/Versions/2.7/lib/python2.7/site-packages/django/contrib/auth/views.py", line 60, in login
    current_site = get_current_site(request)
  File "/Library/Frameworks/Python.framework/Versions/2.7/lib/python2.7/site-packages/django/contrib/sites/models.py", line 92, in get_current_site
    current_site = Site.objects.get_current()
  File "/Library/Frameworks/Python.framework/Versions/2.7/lib/python2.7/site-packages/django/contrib/sites/models.py", line 25, in get_current
    current_site = self.get(pk=sid)
  File "/Library/Frameworks/Python.framework/Versions/2.7/lib/python2.7/site-packages/django/db/models/manager.py", line 131, in get
    return self.get_query_set().get(*args, **kwargs)
  File "/Library/Frameworks/Python.framework/Versions/2.7/lib/python2.7/site-packages/django/db/models/query.py", line 366, in get
    % self.model._meta.object_name)
DoesNotExist: Site matching query does not exist.
Internal Server Error: /login
Traceback (most recent call last):
  File "/Library/Frameworks/Python.framework/Versions/2.7/lib/python2.7/site-packages/django/core/handlers/base.py", line 111, in get_response
    response = callback(request, *callback_args, **callback_kwargs)
  File "/Library/Frameworks/Python.framework/Versions/2.7/lib/python2.7/site-packages/django/views/decorators/debug.py", line 69, in wrapper
    return view(request, *args, **kwargs)
  File "/Library/Frameworks/Python.framework/Versions/2.7/lib/python2.7/site-packages/django/utils/decorators.py", line 91, in _wrapped_view
    response = view_func(request, *args, **kwargs)
  File "/Library/Frameworks/Python.framework/Versions/2.7/lib/python2.7/site-packages/django/views/decorators/cache.py", line 89, in _wrapped_view_func
    response = view_func(request, *args, **kwargs)
  File "/Library/Frameworks/Python.framework/Versions/2.7/lib/python2.7/site-packages/django/contrib/auth/views.py", line 60, in login
    current_site = get_current_site(request)
  File "/Library/Frameworks/Python.framework/Versions/2.7/lib/python2.7/site-packages/django/contrib/sites/models.py", line 92, in get_current_site
    current_site = Site.objects.get_current()
  File "/Library/Frameworks/Python.framework/Versions/2.7/lib/python2.7/site-packages/django/contrib/sites/models.py", line 25, in get_current
    current_site = self.get(pk=sid)
  File "/Library/Frameworks/Python.framework/Versions/2.7/lib/python2.7/site-packages/django/db/models/manager.py", line 131, in get
    return self.get_query_set().get(*args, **kwargs)
  File "/Library/Frameworks/Python.framework/Versions/2.7/lib/python2.7/site-packages/django/db/models/query.py", line 366, in get
    % self.model._meta.object_name)
DoesNotExist: Site matching query does not exist.
Internal Server Error: /login
Traceback (most recent call last):
  File "/Library/Frameworks/Python.framework/Versions/2.7/lib/python2.7/site-packages/django/core/handlers/base.py", line 111, in get_response
    response = callback(request, *callback_args, **callback_kwargs)
  File "/Library/Frameworks/Python.framework/Versions/2.7/lib/python2.7/site-packages/django/views/decorators/debug.py", line 69, in wrapper
    return view(request, *args, **kwargs)
  File "/Library/Frameworks/Python.framework/Versions/2.7/lib/python2.7/site-packages/django/utils/decorators.py", line 91, in _wrapped_view
    response = view_func(request, *args, **kwargs)
  File "/Library/Frameworks/Python.framework/Versions/2.7/lib/python2.7/site-packages/django/views/decorators/cache.py", line 89, in _wrapped_view_func
    response = view_func(request, *args, **kwargs)
  File "/Library/Frameworks/Python.framework/Versions/2.7/lib/python2.7/site-packages/django/contrib/auth/views.py", line 60, in login
    current_site = get_current_site(request)
  File "/Library/Frameworks/Python.framework/Versions/2.7/lib/python2.7/site-packages/django/contrib/sites/models.py", line 92, in get_current_site
    current_site = Site.objects.get_current()
  File "/Library/Frameworks/Python.framework/Versions/2.7/lib/python2.7/site-packages/django/contrib/sites/models.py", line 25, in get_current
    current_site = self.get(pk=sid)
  File "/Library/Frameworks/Python.framework/Versions/2.7/lib/python2.7/site-packages/django/db/models/manager.py", line 131, in get
    return self.get_query_set().get(*args, **kwargs)
  File "/Library/Frameworks/Python.framework/Versions/2.7/lib/python2.7/site-packages/django/db/models/query.py", line 366, in get
    % self.model._meta.object_name)
DoesNotExist: Site matching query does not exist.
Internal Server Error: /login
Traceback (most recent call last):
  File "/Library/Frameworks/Python.framework/Versions/2.7/lib/python2.7/site-packages/django/core/handlers/base.py", line 111, in get_response
    response = callback(request, *callback_args, **callback_kwargs)
  File "/Library/Frameworks/Python.framework/Versions/2.7/lib/python2.7/site-packages/django/views/decorators/debug.py", line 69, in wrapper
    return view(request, *args, **kwargs)
  File "/Library/Frameworks/Python.framework/Versions/2.7/lib/python2.7/site-packages/django/utils/decorators.py", line 91, in _wrapped_view
    response = view_func(request, *args, **kwargs)
  File "/Library/Frameworks/Python.framework/Versions/2.7/lib/python2.7/site-packages/django/views/decorators/cache.py", line 89, in _wrapped_view_func
    response = view_func(request, *args, **kwargs)
  File "/Library/Frameworks/Python.framework/Versions/2.7/lib/python2.7/site-packages/django/contrib/auth/views.py", line 60, in login
    current_site = get_current_site(request)
  File "/Library/Frameworks/Python.framework/Versions/2.7/lib/python2.7/site-packages/django/contrib/sites/models.py", line 92, in get_current_site
    current_site = Site.objects.get_current()
  File "/Library/Frameworks/Python.framework/Versions/2.7/lib/python2.7/site-packages/django/contrib/sites/models.py", line 25, in get_current
    current_site = self.get(pk=sid)
  File "/Library/Frameworks/Python.framework/Versions/2.7/lib/python2.7/site-packages/django/db/models/manager.py", line 131, in get
    return self.get_query_set().get(*args, **kwargs)
  File "/Library/Frameworks/Python.framework/Versions/2.7/lib/python2.7/site-packages/django/db/models/query.py", line 366, in get
    % self.model._meta.object_name)
DoesNotExist: Site matching query does not exist.
Internal Server Error: /login
Traceback (most recent call last):
  File "/Library/Frameworks/Python.framework/Versions/2.7/lib/python2.7/site-packages/django/core/handlers/base.py", line 111, in get_response
    response = callback(request, *callback_args, **callback_kwargs)
  File "/Library/Frameworks/Python.framework/Versions/2.7/lib/python2.7/site-packages/django/views/decorators/debug.py", line 69, in wrapper
    return view(request, *args, **kwargs)
  File "/Library/Frameworks/Python.framework/Versions/2.7/lib/python2.7/site-packages/django/utils/decorators.py", line 91, in _wrapped_view
    response = view_func(request, *args, **kwargs)
  File "/Library/Frameworks/Python.framework/Versions/2.7/lib/python2.7/site-packages/django/views/decorators/cache.py", line 89, in _wrapped_view_func
    response = view_func(request, *args, **kwargs)
  File "/Library/Frameworks/Python.framework/Versions/2.7/lib/python2.7/site-packages/django/contrib/auth/views.py", line 36, in login
    if form.is_valid():
  File "/Library/Frameworks/Python.framework/Versions/2.7/lib/python2.7/site-packages/django/forms/forms.py", line 124, in is_valid
    return self.is_bound and not bool(self.errors)
  File "/Library/Frameworks/Python.framework/Versions/2.7/lib/python2.7/site-packages/django/forms/forms.py", line 115, in _get_errors
    self.full_clean()
  File "/Library/Frameworks/Python.framework/Versions/2.7/lib/python2.7/site-packages/django/forms/forms.py", line 271, in full_clean
    self._clean_form()
  File "/Library/Frameworks/Python.framework/Versions/2.7/lib/python2.7/site-packages/django/forms/forms.py", line 299, in _clean_form
    self.cleaned_data = self.clean()
  File "/Library/Frameworks/Python.framework/Versions/2.7/lib/python2.7/site-packages/django/contrib/auth/forms.py", line 167, in clean
    password=password)
  File "/Library/Frameworks/Python.framework/Versions/2.7/lib/python2.7/site-packages/django/contrib/auth/__init__.py", line 45, in authenticate
    user = backend.authenticate(**credentials)
  File "/Library/Frameworks/Python.framework/Versions/2.7/lib/python2.7/site-packages/django/contrib/auth/backends.py", line 15, in authenticate
    if user.check_password(password):
  File "/Library/Frameworks/Python.framework/Versions/2.7/lib/python2.7/site-packages/django/contrib/auth/models.py", line 304, in check_password
    return check_password(raw_password, self.password, setter)
  File "/Library/Frameworks/Python.framework/Versions/2.7/lib/python2.7/site-packages/django/contrib/auth/hashers.py", line 42, in check_password
    hasher = get_hasher(algorithm)
  File "/Library/Frameworks/Python.framework/Versions/2.7/lib/python2.7/site-packages/django/contrib/auth/hashers.py", line 115, in get_hasher
    "setting?" % algorithm)
ValueError: Unknown password hashing algorithm ''. Did you specify it in the PASSWORD_HASHERS setting?
Internal Server Error: /login
Traceback (most recent call last):
  File "/Library/Frameworks/Python.framework/Versions/2.7/lib/python2.7/site-packages/django/core/handlers/base.py", line 111, in get_response
    response = callback(request, *callback_args, **callback_kwargs)
  File "/Library/Frameworks/Python.framework/Versions/2.7/lib/python2.7/site-packages/django/views/decorators/debug.py", line 69, in wrapper
    return view(request, *args, **kwargs)
  File "/Library/Frameworks/Python.framework/Versions/2.7/lib/python2.7/site-packages/django/utils/decorators.py", line 91, in _wrapped_view
    response = view_func(request, *args, **kwargs)
  File "/Library/Frameworks/Python.framework/Versions/2.7/lib/python2.7/site-packages/django/views/decorators/cache.py", line 89, in _wrapped_view_func
    response = view_func(request, *args, **kwargs)
  File "/Library/Frameworks/Python.framework/Versions/2.7/lib/python2.7/site-packages/django/contrib/auth/views.py", line 36, in login
    if form.is_valid():
  File "/Library/Frameworks/Python.framework/Versions/2.7/lib/python2.7/site-packages/django/forms/forms.py", line 124, in is_valid
    return self.is_bound and not bool(self.errors)
  File "/Library/Frameworks/Python.framework/Versions/2.7/lib/python2.7/site-packages/django/forms/forms.py", line 115, in _get_errors
    self.full_clean()
  File "/Library/Frameworks/Python.framework/Versions/2.7/lib/python2.7/site-packages/django/forms/forms.py", line 271, in full_clean
    self._clean_form()
  File "/Library/Frameworks/Python.framework/Versions/2.7/lib/python2.7/site-packages/django/forms/forms.py", line 299, in _clean_form
    self.cleaned_data = self.clean()
  File "/Library/Frameworks/Python.framework/Versions/2.7/lib/python2.7/site-packages/django/contrib/auth/forms.py", line 167, in clean
    password=password)
  File "/Library/Frameworks/Python.framework/Versions/2.7/lib/python2.7/site-packages/django/contrib/auth/__init__.py", line 45, in authenticate
    user = backend.authenticate(**credentials)
  File "/Library/Frameworks/Python.framework/Versions/2.7/lib/python2.7/site-packages/django/contrib/auth/backends.py", line 15, in authenticate
    if user.check_password(password):
  File "/Library/Frameworks/Python.framework/Versions/2.7/lib/python2.7/site-packages/django/contrib/auth/models.py", line 304, in check_password
    return check_password(raw_password, self.password, setter)
  File "/Library/Frameworks/Python.framework/Versions/2.7/lib/python2.7/site-packages/django/contrib/auth/hashers.py", line 42, in check_password
    hasher = get_hasher(algorithm)
  File "/Library/Frameworks/Python.framework/Versions/2.7/lib/python2.7/site-packages/django/contrib/auth/hashers.py", line 115, in get_hasher
    "setting?" % algorithm)
ValueError: Unknown password hashing algorithm ''. Did you specify it in the PASSWORD_HASHERS setting?
Internal Server Error: /login
Traceback (most recent call last):
  File "/Library/Frameworks/Python.framework/Versions/2.7/lib/python2.7/site-packages/django/core/handlers/base.py", line 111, in get_response
    response = callback(request, *callback_args, **callback_kwargs)
  File "/Library/Frameworks/Python.framework/Versions/2.7/lib/python2.7/site-packages/django/views/decorators/debug.py", line 69, in wrapper
    return view(request, *args, **kwargs)
  File "/Library/Frameworks/Python.framework/Versions/2.7/lib/python2.7/site-packages/django/utils/decorators.py", line 91, in _wrapped_view
    response = view_func(request, *args, **kwargs)
  File "/Library/Frameworks/Python.framework/Versions/2.7/lib/python2.7/site-packages/django/views/decorators/cache.py", line 89, in _wrapped_view_func
    response = view_func(request, *args, **kwargs)
  File "/Library/Frameworks/Python.framework/Versions/2.7/lib/python2.7/site-packages/django/contrib/auth/views.py", line 36, in login
    if form.is_valid():
  File "/Library/Frameworks/Python.framework/Versions/2.7/lib/python2.7/site-packages/django/forms/forms.py", line 124, in is_valid
    return self.is_bound and not bool(self.errors)
  File "/Library/Frameworks/Python.framework/Versions/2.7/lib/python2.7/site-packages/django/forms/forms.py", line 115, in _get_errors
    self.full_clean()
  File "/Library/Frameworks/Python.framework/Versions/2.7/lib/python2.7/site-packages/django/forms/forms.py", line 271, in full_clean
    self._clean_form()
  File "/Library/Frameworks/Python.framework/Versions/2.7/lib/python2.7/site-packages/django/forms/forms.py", line 299, in _clean_form
    self.cleaned_data = self.clean()
  File "/Library/Frameworks/Python.framework/Versions/2.7/lib/python2.7/site-packages/django/contrib/auth/forms.py", line 167, in clean
    password=password)
  File "/Library/Frameworks/Python.framework/Versions/2.7/lib/python2.7/site-packages/django/contrib/auth/__init__.py", line 45, in authenticate
    user = backend.authenticate(**credentials)
  File "/Library/Frameworks/Python.framework/Versions/2.7/lib/python2.7/site-packages/django/contrib/auth/backends.py", line 15, in authenticate
    if user.check_password(password):
  File "/Library/Frameworks/Python.framework/Versions/2.7/lib/python2.7/site-packages/django/contrib/auth/models.py", line 304, in check_password
    return check_password(raw_password, self.password, setter)
  File "/Library/Frameworks/Python.framework/Versions/2.7/lib/python2.7/site-packages/django/contrib/auth/hashers.py", line 42, in check_password
    hasher = get_hasher(algorithm)
  File "/Library/Frameworks/Python.framework/Versions/2.7/lib/python2.7/site-packages/django/contrib/auth/hashers.py", line 115, in get_hasher
    "setting?" % algorithm)
ValueError: Unknown password hashing algorithm ''. Did you specify it in the PASSWORD_HASHERS setting?
